File: Alu_Halter_tief.ras
*RAS_DATA_START
*RAS_HEADER_START
*CORR_POS_DB_NAME "AngleCorr_NIST640d_DteX_2022.02.28"
*CORR_POS_GONIO_RADIUS ""
*CORR_POS_NODE_INDEX01 ""
*CORR_POS_NODE_INDEX02 ""
*CORR_POS_NODE_INDEX03 ""
*CORR_POS_NODE_INDEX04 ""
*CORR_POS_NODE_INDEX05 ""
*CORR_POS_NODE_INDEX06 ""
*CORR_POS_NODE_INDEX07 ""
*CORR_POS_NODE_INDEX08 ""
*CORR_POS_NODE_INDEX09 ""
*CORR_POS_NODE_INDEX10 ""
*CORR_POS_NODE_INDEX11 ""
*CORR_POS_NODE_LABEL01 "Si(111)"
*CORR_POS_NODE_LABEL02 "Si(220)"
*CORR_POS_NODE_LABEL03 "Si(311)"
*CORR_POS_NODE_LABEL04 "Si(400)"
*CORR_POS_NODE_LABEL05 "Si(331)"
*CORR_POS_NODE_LABEL06 "Si(422)"
*CORR_POS_NODE_LABEL07 "Si(511)"
*CORR_POS_NODE_LABEL08 "Si(440)"
*CORR_POS_NODE_LABEL09 "Si(531)"
*CORR_POS_NODE_LABEL10 "Si(620)"
*CORR_POS_NODE_LABEL11 "Si(533)"
*CORR_POS_NODE_POS_CALC01 "28.4137"
*CORR_POS_NODE_POS_CALC02 "47.2707"
*CORR_POS_NODE_POS_CALC03 "56.0883"
*CORR_POS_NODE_POS_CALC04 "69.0934"
*CORR_POS_NODE_POS_CALC05 "76.3385"
*CORR_POS_NODE_POS_CALC06 "87.9915"
*CORR_POS_NODE_POS_CALC07 "94.9137"
*CORR_POS_NODE_POS_CALC08 "106.67"
*CORR_POS_NODE_POS_CALC09 "114.054"
*CORR_POS_NODE_POS_CALC10 "127.508"
*CORR_POS_NODE_POS_CALC11 "136.858"
*CORR_POS_NODE_POS_MEAS01 "28.3905"
*CORR_POS_NODE_POS_MEAS02 "47.2504"
*CORR_POS_NODE_POS_MEAS03 "56.0712"
*CORR_POS_NODE_POS_MEAS04 "69.0788"
*CORR_POS_NODE_POS_MEAS05 "76.3323"
*CORR_POS_NODE_POS_MEAS06 "87.9869"
*CORR_POS_NODE_POS_MEAS07 "94.9135"
*CORR_POS_NODE_POS_MEAS08 "106.672"
*CORR_POS_NODE_POS_MEAS09 "114.061"
*CORR_POS_NODE_POS_MEAS10 "127.517"
*CORR_POS_NODE_POS_MEAS11 "136.874"
*CORR_POS_OPT_ATTR "集中法"
*CORR_POS_PARAM_MU ""
*CORR_POS_PARAM_PL ""
*CORR_POS_SEMODEL_TYPE "0"
*CORR_POS_STANDARD_TYPE ""
*CORR_POS_VALUE_ANALYZER "None"
*CORR_POS_VALUE_CMONO "None"
*CORR_POS_VALUE_IMONO "None"
*CORR_POS_VALUE_IS "0.625deg"
*CORR_POS_VALUE_ISL "10.0mm"
*CORR_POS_VALUE_ISOLLER "2.5deg"
*CORR_POS_VALUE_RS1 "13.0mm"
*CORR_POS_VALUE_RS2 "13.0mm"
*CORR_POS_VALUE_RSOLLER "2.5deg"
*CORR_POS_XG_FOCUS_L ""
*CORR_POS_XG_WAVE_TYPE ""
*CORR_POS_XG_WAVE_VALUE ""
*DISP_FMT_X "%.2f"
*DISP_FMT_Y "%.0f"
*DISP_FULLSCALE "79444.0000000000"
*DISP_LINE_COLOR "255.0000000000"
*DISP_LINE_STYLE "0.0000000000"
*DISP_LINE_WIDTH "0.2500000000"
*DISP_NOTE "Collected Data-2"
*DISP_OFFSET_Y "0.0000000000"
*DISP_PEAKSEARCH_UNIT_Y "cps"
*DISP_RANGE_BOTTOM "0.0000000000"
*DISP_RANGE_LEFT "2.0000000000"
*DISP_RANGE_LOGCUTOFF "0.0100000000"
*DISP_RANGE_RIGHT "140.0000000000"
*DISP_RANGE_TOP "79444.0000000000"
*DISP_SCALE_MODE_Y "0.0000000000"
*DISP_TAB_NAME "Theta/2-Theta"
*DISP_TITLE_Y "Intensity"
*DISP_UNIT_Y "cps"
*DISP_WINDOW_NAME "MSG_MACROENGINE"
*FILE_COMMENT " "
*FILE_MD5 ""
*FILE_MEMO " "
*FILE_OPERATOR "Administrator"
*FILE_SAMPLE "Alu_Halter_tief"
*FILE_TYPE "RAS_RAW"
*FILE_USERGROUP "System Manager"
*FILE_VERSION "1.0000000000"
*HW_ATTACHMENT_ID "ATT1031"
*HW_ATTACHMENT_NAME "6サンプルチェンジャ|ASC-6"
*HW_COUNTER_ID-0 "CUT0025"
*HW_COUNTER_ID-1 "CUT0020"
*HW_COUNTER_ID-2 "CUT0020"
*HW_COUNTER_ID-3 "CMC0021"
*HW_COUNTER_NAME-0 "D/teX Ultra|D/teX Ultra"
*HW_COUNTER_NAME-1 "None|None"
*HW_COUNTER_NAME-2 "None|None"
*HW_COUNTER_NAME-3 "検出器モノクロメータ|Detector monochromator"
*HW_COUNTER_SELECT_NAME "D/teX Ultra|D/teX Ultra"
*HW_GONIOMETER_ID "GON0070"
*HW_GONIOMETER_NAME "MiniFlex 300/600|MiniFlex 300/600"
*HW_GONIOMETER_RADIUS-0 "79.0"
*HW_GONIOMETER_RADIUS-1 "91.5"
*HW_GONIOMETER_RADIUS-2 "150.0"
*HW_GONIOMETER_RADIUS-3 "0"
*HW_GONIOMETER_RADIUS-4 "103.4"
*HW_GONIOMETER_RADIUS-5 "150.0"
*HW_GONIOMETER_RADIUS-6 "46.6"
*HW_GONIOMETER_RADIUS-7 "160.0"
*HW_I_OPT_ID-0 "ISL0021"
*HW_I_OPT_ID-1 "ISO0021"
*HW_I_OPT_NAME-0 "発散スリット|Divergence slit"
*HW_I_OPT_NAME-1 "入射平行スリット|Incident parallel slit"
*HW_R_ATTENUATER_AUTOMODE "0"
*HW_R_OPT_ID-0 "RSS0021"
*HW_R_OPT_ID-1 "RSO0021"
*HW_R_OPT_ID-2 "RRS0021"
*HW_R_OPT_NAME-0 "散乱スリット|Scattering slit"
*HW_R_OPT_NAME-1 "受光平行スリット|Receiving soller slit"
*HW_R_OPT_NAME-2 "受光スリット|Receiving slit"
*HW_SAMPLE_HOLDER_ID "SMP0000"
*HW_SAMPLE_HOLDER_NAME "無し|None"
*HW_XG_CURRENT_MAX "15"
*HW_XG_CURRENT_MIN "2"
*HW_XG_CURRENT_RESOLUTION "1"
*HW_XG_CURRENT_UNIT "mA"
*HW_XG_FOCUS "1mm x 10mm"
*HW_XG_FOCUS_TYPE "Normal"
*HW_XG_ID ""
*HW_XG_NAME "300W/600W 封入管-B|300W/600W Sealed tube-B"
*HW_XG_TARGET_ATOMIC_NUMBER "29.0000000000"
*HW_XG_TARGET_NAME "Cu"
*HW_XG_TYPE "Hermetic"
*HW_XG_VOLTAGE_MAX "40"
*HW_XG_VOLTAGE_MIN "20"
*HW_XG_VOLTAGE_RESOLUTION "1"
*HW_XG_VOLTAGE_UNIT "kV"
*HW_XG_WATT_MAX "1"
*HW_XG_WATT_UNIT "kW"
*HW_XG_WAVE_LENGTH_ALPHA1 "1.540593"
*HW_XG_WAVE_LENGTH_ALPHA2 "1.544414"
*HW_XG_WAVE_LENGTH_BETA "1.392250"
*MEAS_COND_AXIS_NAME-0 "Theta/2-Theta"
*MEAS_COND_AXIS_NAME-1 "Spin"
*MEAS_COND_AXIS_NAME-2 "Change"
*MEAS_COND_AXIS_NAME-3 "Soller(inc.)"
*MEAS_COND_AXIS_NAME-4 "IHS"
*MEAS_COND_AXIS_NAME-5 "DS"
*MEAS_COND_AXIS_NAME-6 "SS"
*MEAS_COND_AXIS_NAME-7 "Soller(rec.)"
*MEAS_COND_AXIS_NAME-8 "RS"
*MEAS_COND_AXIS_NAME-9 "Filter"
*MEAS_COND_AXIS_NAME-10 "Monochromator"
*MEAS_COND_AXIS_NAME-11 "PHA"
*MEAS_COND_AXIS_NAME_INTERNAL-0 "TwoThetaTheta"
*MEAS_COND_AXIS_NAME_INTERNAL-1 "Spin"
*MEAS_COND_AXIS_NAME_INTERNAL-2 "Change"
*MEAS_COND_AXIS_NAME_INTERNAL-3 "IncidentSollerSlit"
*MEAS_COND_AXIS_NAME_INTERNAL-4 "IncidentAxdSlit"
*MEAS_COND_AXIS_NAME_INTERNAL-5 "IncidentSlitBox"
*MEAS_COND_AXIS_NAME_INTERNAL-6 "ReceivingSlitBox1"
*MEAS_COND_AXIS_NAME_INTERNAL-7 "ReceivingSollerSlit"
*MEAS_COND_AXIS_NAME_INTERNAL-8 "ReceivingSlitBox2"
*MEAS_COND_AXIS_NAME_INTERNAL-9 "Filter"
*MEAS_COND_AXIS_NAME_INTERNAL-10 "CounterMonochromator"
*MEAS_COND_AXIS_NAME_INTERNAL-11 "PHA"
*MEAS_COND_AXIS_NAME_MAGICNO-0 "268632064.0000000000"
*MEAS_COND_AXIS_NAME_MAGICNO-1 "16842752.0000000000"
*MEAS_COND_AXIS_NAME_MAGICNO-2 "16842752.0000000000"
*MEAS_COND_AXIS_NAME_MAGICNO-3 "20971521.0000000000"
*MEAS_COND_AXIS_NAME_MAGICNO-4 "22020097.0000000000"
*MEAS_COND_AXIS_NAME_MAGICNO-5 "22020097.0000000000"
*MEAS_COND_AXIS_NAME_MAGICNO-6 "23068673.0000000000"
*MEAS_COND_AXIS_NAME_MAGICNO-7 "20971521.0000000000"
*MEAS_COND_AXIS_NAME_MAGICNO-8 "23068673.0000000000"
*MEAS_COND_AXIS_NAME_MAGICNO-9 "20971521.0000000000"
*MEAS_COND_AXIS_NAME_MAGICNO-10 "20971521.0000000000"
*MEAS_COND_AXIS_NAME_MAGICNO-11 "0.0000000000"
*MEAS_COND_AXIS_OFFSET-0 "0.0000000000"
*MEAS_COND_AXIS_OFFSET-1 "-"
*MEAS_COND_AXIS_OFFSET-2 "-"
*MEAS_COND_AXIS_OFFSET-3 "-"
*MEAS_COND_AXIS_OFFSET-4 "-"
*MEAS_COND_AXIS_OFFSET-5 "-"
*MEAS_COND_AXIS_OFFSET-6 "-"
*MEAS_COND_AXIS_OFFSET-7 "-"
*MEAS_COND_AXIS_OFFSET-8 "-"
*MEAS_COND_AXIS_OFFSET-9 "-"
*MEAS_COND_AXIS_OFFSET-10 "-"
*MEAS_COND_AXIS_OFFSET-11 "-"
*MEAS_COND_AXIS_POSITION-0 "142.5900000000"
*MEAS_COND_AXIS_POSITION-1 "0.0000000000"
*MEAS_COND_AXIS_POSITION-2 "2.0000000000"
*MEAS_COND_AXIS_POSITION-3 "2.5deg"
*MEAS_COND_AXIS_POSITION-4 "10.0mm"
*MEAS_COND_AXIS_POSITION-5 "0.625deg"
*MEAS_COND_AXIS_POSITION-6 "8.0mm"
*MEAS_COND_AXIS_POSITION-7 "2.5deg"
*MEAS_COND_AXIS_POSITION-8 "13.0mm"
*MEAS_COND_AXIS_POSITION-9 "K-beta(x2)"
*MEAS_COND_AXIS_POSITION-10 "None"
*MEAS_COND_AXIS_POSITION-11 "49.0000000000"
*MEAS_COND_AXIS_UNIT-0 "deg"
*MEAS_COND_AXIS_UNIT-1 ""
*MEAS_COND_AXIS_UNIT-2 ""
*MEAS_COND_AXIS_UNIT-3 ""
*MEAS_COND_AXIS_UNIT-4 ""
*MEAS_COND_AXIS_UNIT-5 ""
*MEAS_COND_AXIS_UNIT-6 ""
*MEAS_COND_AXIS_UNIT-7 ""
*MEAS_COND_AXIS_UNIT-8 ""
*MEAS_COND_AXIS_UNIT-9 ""
*MEAS_COND_AXIS_UNIT-10 ""
*MEAS_COND_AXIS_UNIT-11 "div"
*MEAS_COND_CORRECTION_SLIT_COUNTERMONO "None"
*MEAS_COND_CORRECTION_SLIT_DS "0.625deg"
*MEAS_COND_CORRECTION_SLIT_FILTER "None"
*MEAS_COND_CORRECTION_SLIT_IHS "10.0mm"
*MEAS_COND_CORRECTION_SLIT_RS "13.0mm"
*MEAS_COND_CORRECTION_SLIT_SOLLER_INC "2.5deg"
*MEAS_COND_CORRECTION_SLIT_SOLLER_REC "2.5deg"
*MEAS_COND_CORRECTION_SLIT_SS "8.0mm"
*MEAS_COND_COUNTER_CNTLOSS_CORR "0.0000000000"
*MEAS_COND_COUNTER_PHABASE "49.0000000000"
*MEAS_COND_COUNTER_PHAWINDOW "8.0000000000"
*MEAS_COND_COUNTER_PHA_UNIT "div"
*MEAS_COND_COUNTER_TAUDIFF "0.2500000000"
*MEAS_COND_COUNTER_TAUINT "0.7500000000"
*MEAS_COND_IRRADIATION_MODE "OFF"
*MEAS_COND_IRRADIATION_WIDTH ""
*MEAS_COND_OPT_ATTR " "
*MEAS_COND_OPT_NAME ""
*MEAS_COND_UNSYMMETRIC_MODE "OFF"
*MEAS_COND_XG_CURRENT "15.0000000000"
*MEAS_COND_XG_VOLTAGE "40.0000000000"
*MEAS_COND_XG_WAVE_TYPE "Ka"
*MEAS_DATA_COUNT "13801.0000000000"
*MEAS_SCAN_AXIS_X "Theta/2-Theta"
*MEAS_SCAN_AXIS_X_INTERNAL "TwoThetaTheta"
*MEAS_SCAN_END_TIME "06/22/22 17:23:33"
*MEAS_SCAN_MODE "CONTINUOUS"
*MEAS_SCAN_MONITOR "0"
*MEAS_SCAN_RESOLUTION_X "0.005"
*MEAS_SCAN_SPEED "1.000"
*MEAS_SCAN_SPEED_UNIT "deg/min"
*MEAS_SCAN_START "2.0000000000"
*MEAS_SCAN_START_TIME "06/22/22 15:00:05"
*MEAS_SCAN_STEP "0.0100000000"
*MEAS_SCAN_STOP "140.0000000000"
*MEAS_SCAN_UNIT_X "deg"
*MEAS_SCAN_UNIT_Y "counts"
*SLIT_SYSTEM "0"
*RAS_HEADER_END
*RAS_INT_START
2.000 1143.000 1.000
2.100 1040.000 1.000
2.200 989.000 1.000
2.300 1043.000 1.000
2.400 965.000 1.000
2.500 930.000 1.000
2.600 872.000 1.000
2.700 864.000 1.000
2.800 887.000 1.000
2.900 824.000 1.000
3.000 912.000 1.000
3.100 762.000 1.000
3.200 817.000 1.000
3.300 721.000 1.000
3.400 706.000 1.000
3.500 709.000 1.000
3.600 726.000 1.000
3.700 676.000 1.000
3.800 720.000 1.000
3.900 706.000 1.000
4.000 632.000 1.000
4.100 622.000 1.000
4.200 605.000 1.000
4.300 634.000 1.000
4.400 598.000 1.000
4.500 629.000 1.000
4.600 597.000 1.000
4.700 632.000 1.000
4.800 599.000 1.000
4.900 579.000 1.000
5.000 568.000 1.000
5.100 604.000 1.000
5.200 569.000 1.000
5.300 583.000 1.000
5.400 536.000 1.000
5.500 531.000 1.000
5.600 555.000 1.000
5.700 552.000 1.000
5.800 554.000 1.000
5.900 525.000 1.000
6.000 515.000 1.000
6.100 557.000 1.000
6.200 539.000 1.000
6.300 513.000 1.000
6.400 535.000 1.000
6.500 547.000 1.000
6.600 543.000 1.000
6.700 532.000 1.000
6.800 518.000 1.000
6.900 551.000 1.000
7.000 526.000 1.000
7.100 529.000 1.000
7.200 550.000 1.000
7.300 530.000 1.000
7.400 562.000 1.000
7.500 509.000 1.000
7.600 543.000 1.000
7.700 523.000 1.000
7.800 584.000 1.000
7.900 542.000 1.000
8.000 537.000 1.000
8.100 537.000 1.000
8.200 560.000 1.000
8.300 559.000 1.000
8.400 549.000 1.000
8.500 556.000 1.000
8.600 569.000 1.000
8.700 554.000 1.000
8.800 566.000 1.000
8.900 556.000 1.000
9.000 539.000 1.000
9.100 563.000 1.000
9.200 568.000 1.000
9.300 586.000 1.000
9.400 579.000 1.000
9.500 576.000 1.000
9.600 570.000 1.000
9.700 579.000 1.000
9.800 586.000 1.000
9.900 581.000 1.000
10.000 593.000 1.000
10.100 592.000 1.000
10.200 590.000 1.000
10.300 588.000 1.000
10.400 590.000 1.000
10.500 619.000 1.000
10.600 595.000 1.000
10.700 578.000 1.000
10.800 598.000 1.000
10.900 568.000 1.000
11.000 609.000 1.000
11.100 596.000 1.000
11.200 575.000 1.000
11.300 583.000 1.000
11.400 565.000 1.000
11.500 582.000 1.000
11.600 568.000 1.000
11.700 583.000 1.000
11.800 541.000 1.000
11.900 590.000 1.000
12.000 563.000 1.000
12.100 574.000 1.000
12.200 563.000 1.000
12.300 557.000 1.000
12.400 548.000 1.000
12.500 555.000 1.000
12.600 544.000 1.000
12.700 519.000 1.000
12.800 562.000 1.000
12.900 525.000 1.000
13.000 528.000 1.000
13.100 504.000 1.000
13.200 501.000 1.000
13.300 539.000 1.000
13.400 487.000 1.000
13.500 508.000 1.000
13.600 474.000 1.000
13.700 455.000 1.000
13.800 479.000 1.000
13.900 464.000 1.000
14.000 450.000 1.000
14.100 452.000 1.000
14.200 454.000 1.000
14.300 476.000 1.000
14.400 464.000 1.000
14.500 401.000 1.000
14.600 451.000 1.000
14.700 417.000 1.000
14.800 423.000 1.000
14.900 410.000 1.000
15.000 411.000 1.000
15.100 397.000 1.000
15.200 414.000 1.000
15.300 399.000 1.000
15.400 395.000 1.000
15.500 376.000 1.000
15.600 381.000 1.000
15.700 360.000 1.000
15.800 387.000 1.000
15.900 332.000 1.000
16.000 345.000 1.000
16.100 350.000 1.000
16.200 337.000 1.000
16.300 367.000 1.000
16.400 351.000 1.000
16.500 330.000 1.000
16.600 322.000 1.000
16.700 336.000 1.000
16.800 320.000 1.000
16.900 330.000 1.000
17.000 340.000 1.000
17.100 308.000 1.000
17.200 353.000 1.000
17.300 314.000 1.000
17.400 314.000 1.000
17.500 327.000 1.000
17.600 300.000 1.000
17.700 309.000 1.000
17.800 278.000 1.000
17.900 291.000 1.000
18.000 306.000 1.000
18.100 303.000 1.000
18.200 287.000 1.000
18.300 318.000 1.000
18.400 280.000 1.000
18.500 283.000 1.000
18.600 267.000 1.000
18.700 298.000 1.000
18.800 268.000 1.000
18.900 256.000 1.000
19.000 260.000 1.000
19.100 258.000 1.000
19.200 256.000 1.000
19.300 242.000 1.000
19.400 262.000 1.000
19.500 257.000 1.000
19.600 273.000 1.000
19.700 254.000 1.000
19.800 249.000 1.000
19.900 246.000 1.000
20.000 234.000 1.000
20.100 250.000 1.000
20.200 231.000 1.000
20.300 245.000 1.000
20.400 226.000 1.000
20.500 238.000 1.000
20.600 235.000 1.000
20.700 244.000 1.000
20.800 228.000 1.000
20.900 229.000 1.000
21.000 240.000 1.000
21.100 231.000 1.000
21.200 222.000 1.000
21.300 226.000 1.000
21.400 225.000 1.000
21.500 224.000 1.000
21.600 229.000 1.000
21.700 245.000 1.000
21.800 220.000 1.000
21.900 231.000 1.000
22.000 218.000 1.000
22.100 216.000 1.000
22.200 211.000 1.000
22.300 207.000 1.000
22.400 217.000 1.000
22.500 223.000 1.000
22.600 213.000 1.000
22.700 218.000 1.000
22.800 195.000 1.000
22.900 210.000 1.000
23.000 205.000 1.000
23.100 178.000 1.000
23.200 203.000 1.000
23.300 200.000 1.000
23.400 186.000 1.000
23.500 187.000 1.000
23.600 189.000 1.000
23.700 188.000 1.000
23.800 189.000 1.000
23.900 188.000 1.000
24.000 193.000 1.000
24.100 185.000 1.000
24.200 199.000 1.000
24.300 188.000 1.000
24.400 181.000 1.000
24.500 178.000 1.000
24.600 169.000 1.000
24.700 181.000 1.000
24.800 177.000 1.000
24.900 178.000 1.000
25.000 171.000 1.000
25.100 176.000 1.000
25.200 171.000 1.000
25.300 171.000 1.000
25.400 183.000 1.000
25.500 176.000 1.000
25.600 169.000 1.000
25.700 173.000 1.000
25.800 163.000 1.000
25.900 154.000 1.000
26.000 160.000 1.000
26.100 156.000 1.000
26.200 162.000 1.000
26.300 171.000 1.000
26.400 164.000 1.000
26.500 144.000 1.000
26.600 161.000 1.000
26.700 146.000 1.000
26.800 159.000 1.000
26.900 128.000 1.000
27.000 154.000 1.000
27.100 148.000 1.000
27.200 167.000 1.000
27.300 157.000 1.000
27.400 157.000 1.000
27.500 152.000 1.000
27.600 137.000 1.000
27.700 135.000 1.000
27.800 151.000 1.000
27.900 142.000 1.000
28.000 133.000 1.000
28.100 139.000 1.000
28.200 137.000 1.000
28.300 147.000 1.000
28.400 142.000 1.000
28.500 151.000 1.000
28.600 139.000 1.000
28.700 152.000 1.000
28.800 138.000 1.000
28.900 133.000 1.000
29.000 135.000 1.000
29.100 126.000 1.000
29.200 136.000 1.000
29.300 123.000 1.000
29.400 125.000 1.000
29.500 142.000 1.000
29.600 137.000 1.000
29.700 128.000 1.000
29.800 114.000 1.000
29.900 128.000 1.000
30.000 152.000 1.000
30.100 130.000 1.000
30.200 122.000 1.000
30.300 141.000 1.000
30.400 134.000 1.000
30.500 131.000 1.000
30.600 141.000 1.000
30.700 126.000 1.000
30.800 123.000 1.000
30.900 146.000 1.000
31.000 134.000 1.000
31.100 136.000 1.000
31.200 129.000 1.000
31.300 130.000 1.000
31.400 111.000 1.000
31.500 127.000 1.000
31.600 132.000 1.000
31.700 124.000 1.000
31.800 126.000 1.000
31.900 135.000 1.000
32.000 129.000 1.000
32.100 148.000 1.000
32.200 116.000 1.000
32.300 127.000 1.000
32.400 127.000 1.000
32.500 116.000 1.000
32.600 133.000 1.000
32.700 122.000 1.000
32.800 136.000 1.000
32.900 123.000 1.000
33.000 144.000 1.000
33.100 131.000 1.000
33.200 140.000 1.000
33.300 131.000 1.000
33.400 139.000 1.000
33.500 141.000 1.000
33.600 144.000 1.000
33.700 145.000 1.000
33.800 137.000 1.000
33.900 139.000 1.000
34.000 137.000 1.000
34.100 140.000 1.000
34.200 140.000 1.000
34.300 137.000 1.000
34.400 146.000 1.000
34.500 155.000 1.000
34.600 144.000 1.000
34.700 151.000 1.000
34.800 150.000 1.000
34.900 156.000 1.000
35.000 156.000 1.000
35.100 158.000 1.000
35.200 155.000 1.000
35.300 197.000 1.000
35.400 283.000 1.000
35.500 313.000 1.000
35.600 345.000 1.000
35.700 353.000 1.000
35.800 345.000 1.000
35.900 326.000 1.000
36.000 358.000 1.000
36.100 460.000 1.000
36.200 759.000 1.000
36.300 1132.000 1.000
36.400 1279.000 1.000
36.500 1922.000 1.000
36.600 8910.000 1.000
36.700 31970.000 1.000
36.800 34409.000 1.000
36.900 12331.000 1.000
37.000 1641.000 1.000
37.100 733.000 1.000
37.200 533.000 1.000
37.300 446.000 1.000
37.400 375.000 1.000
37.500 338.000 1.000
37.600 313.000 1.000
37.700 281.000 1.000
37.800 291.000 1.000
37.900 275.000 1.000
38.000 269.000 1.000
38.100 275.000 1.000
38.200 252.000 1.000
38.300 245.000 1.000
38.400 253.000 1.000
38.500 259.000 1.000
38.600 265.000 1.000
38.700 262.000 1.000
38.800 249.000 1.000
38.900 227.000 1.000
39.000 238.000 1.000
39.100 217.000 1.000
39.200 215.000 1.000
39.300 227.000 1.000
39.400 217.000 1.000
39.500 220.000 1.000
39.600 197.000 1.000
39.700 196.000 1.000
39.800 196.000 1.000
39.900 204.000 1.000
40.000 192.000 1.000
40.100 203.000 1.000
40.200 210.000 1.000
40.300 178.000 1.000
40.400 202.000 1.000
40.500 200.000 1.000
40.600 179.000 1.000
40.700 195.000 1.000
40.800 192.000 1.000
40.900 195.000 1.000
41.000 182.000 1.000
41.100 206.000 1.000
41.200 212.000 1.000
41.300 217.000 1.000
41.400 252.000 1.000
41.500 284.000 1.000
41.600 265.000 1.000
41.700 289.000 1.000
41.800 284.000 1.000
41.900 291.000 1.000
42.000 286.000 1.000
42.100 309.000 1.000
42.200 306.000 1.000
42.300 322.000 1.000
42.400 407.000 1.000
42.500 582.000 1.000
42.600 745.000 1.000
42.700 1186.000 1.000
42.800 3714.000 1.000
42.900 13193.000 1.000
43.000 19408.000 1.000
43.100 10007.000 1.000
43.200 2432.000 1.000
43.300 979.000 1.000
43.400 668.000 1.000
43.500 495.000 1.000
43.600 369.000 1.000
43.700 317.000 1.000
43.800 287.000 1.000
43.900 269.000 1.000
44.000 255.000 1.000
44.100 241.000 1.000
44.200 212.000 1.000
44.300 230.000 1.000
44.400 217.000 1.000
44.500 214.000 1.000
44.600 214.000 1.000
44.700 214.000 1.000
44.800 188.000 1.000
44.900 206.000 1.000
45.000 200.000 1.000
45.100 198.000 1.000
45.200 198.000 1.000
45.300 186.000 1.000
45.400 180.000 1.000
45.500 183.000 1.000
45.600 178.000 1.000
45.700 186.000 1.000
45.800 177.000 1.000
45.900 171.000 1.000
46.000 180.000 1.000
46.100 172.000 1.000
46.200 174.000 1.000
46.300 153.000 1.000
46.400 185.000 1.000
46.500 175.000 1.000
46.600 168.000 1.000
46.700 155.000 1.000
46.800 163.000 1.000
46.900 147.000 1.000
47.000 155.000 1.000
47.100 164.000 1.000
47.200 150.000 1.000
47.300 124.000 1.000
47.400 168.000 1.000
47.500 155.000 1.000
47.600 144.000 1.000
47.700 164.000 1.000
47.800 146.000 1.000
47.900 154.000 1.000
48.000 143.000 1.000
48.100 150.000 1.000
48.200 141.000 1.000
48.300 159.000 1.000
48.400 145.000 1.000
48.500 153.000 1.000
48.600 150.000 1.000
48.700 136.000 1.000
48.800 131.000 1.000
48.900 129.000 1.000
49.000 138.000 1.000
49.100 130.000 1.000
49.200 160.000 1.000
49.300 143.000 1.000
49.400 149.000 1.000
49.500 129.000 1.000
49.600 144.000 1.000
49.700 140.000 1.000
49.800 121.000 1.000
49.900 130.000 1.000
50.000 131.000 1.000
50.100 127.000 1.000
50.200 121.000 1.000
50.300 126.000 1.000
50.400 115.000 1.000
50.500 131.000 1.000
50.600 134.000 1.000
50.700 125.000 1.000
50.800 110.000 1.000
50.900 122.000 1.000
51.000 128.000 1.000
51.100 116.000 1.000
51.200 115.000 1.000
51.300 127.000 1.000
51.400 131.000 1.000
51.500 120.000 1.000
51.600 132.000 1.000
51.700 121.000 1.000
51.800 130.000 1.000
51.900 126.000 1.000
52.000 114.000 1.000
52.100 129.000 1.000
52.200 115.000 1.000
52.300 114.000 1.000
52.400 117.000 1.000
52.500 121.000 1.000
52.600 124.000 1.000
52.700 117.000 1.000
52.800 122.000 1.000
52.900 127.000 1.000
53.000 109.000 1.000
53.100 122.000 1.000
53.200 117.000 1.000
53.300 106.000 1.000
53.400 116.000 1.000
53.500 119.000 1.000
53.600 112.000 1.000
53.700 114.000 1.000
53.800 130.000 1.000
53.900 115.000 1.000
54.000 126.000 1.000
54.100 107.000 1.000
54.200 110.000 1.000
54.300 122.000 1.000
54.400 114.000 1.000
54.500 114.000 1.000
54.600 110.000 1.000
54.700 125.000 1.000
54.800 114.000 1.000
54.900 105.000 1.000
55.000 116.000 1.000
55.100 108.000 1.000
55.200 108.000 1.000
55.300 93.000 1.000
55.400 107.000 1.000
55.500 120.000 1.000
55.600 113.000 1.000
55.700 107.000 1.000
55.800 116.000 1.000
55.900 109.000 1.000
56.000 107.000 1.000
56.100 130.000 1.000
56.200 120.000 1.000
56.300 119.000 1.000
56.400 113.000 1.000
56.500 115.000 1.000
56.600 133.000 1.000
56.700 127.000 1.000
56.800 125.000 1.000
56.900 125.000 1.000
57.000 124.000 1.000
57.100 109.000 1.000
57.200 117.000 1.000
57.300 119.000 1.000
57.400 101.000 1.000
57.500 108.000 1.000
57.600 106.000 1.000
57.700 108.000 1.000
57.800 114.000 1.000
57.900 114.000 1.000
58.000 111.000 1.000
58.100 110.000 1.000
58.200 113.000 1.000
58.300 113.000 1.000
58.400 108.000 1.000
58.500 108.000 1.000
58.600 113.000 1.000
58.700 100.000 1.000
58.800 122.000 1.000
58.900 121.000 1.000
59.000 117.000 1.000
59.100 105.000 1.000
59.200 110.000 1.000
59.300 113.000 1.000
59.400 108.000 1.000
59.500 109.000 1.000
59.600 119.000 1.000
59.700 123.000 1.000
59.800 117.000 1.000
59.900 119.000 1.000
60.000 126.000 1.000
60.100 114.000 1.000
60.200 110.000 1.000
60.300 109.000 1.000
60.400 122.000 1.000
60.500 131.000 1.000
60.600 121.000 1.000
60.700 123.000 1.000
60.800 107.000 1.000
60.900 127.000 1.000
61.000 127.000 1.000
61.100 132.000 1.000
61.200 138.000 1.000
61.300 131.000 1.000
61.400 121.000 1.000
61.500 130.000 1.000
61.600 137.000 1.000
61.700 126.000 1.000
61.800 116.000 1.000
61.900 125.000 1.000
62.000 149.000 1.000
62.100 143.000 1.000
62.200 129.000 1.000
62.300 122.000 1.000
62.400 138.000 1.000
62.500 140.000 1.000
62.600 148.000 1.000
62.700 160.000 1.000
62.800 190.000 1.000
62.900 221.000 1.000
63.000 271.000 1.000
63.100 356.000 1.000
63.200 1000.000 1.000
63.300 4138.000 1.000
63.400 2427.000 1.000
63.500 2568.000 1.000
63.600 872.000 1.000
63.700 352.000 1.000
63.800 231.000 1.000
63.900 180.000 1.000
64.000 172.000 1.000
64.100 145.000 1.000
64.200 148.000 1.000
64.300 137.000 1.000
64.400 134.000 1.000
64.500 136.000 1.000
64.600 132.000 1.000
64.700 136.000 1.000
64.800 133.000 1.000
64.900 126.000 1.000
65.000 128.000 1.000
65.100 120.000 1.000
65.200 129.000 1.000
65.300 130.000 1.000
65.400 133.000 1.000
65.500 126.000 1.000
65.600 131.000 1.000
65.700 122.000 1.000
65.800 128.000 1.000
65.900 122.000 1.000
66.000 121.000 1.000
66.100 119.000 1.000
66.200 117.000 1.000
66.300 123.000 1.000
66.400 119.000 1.000
66.500 116.000 1.000
66.600 114.000 1.000
66.700 119.000 1.000
66.800 115.000 1.000
66.900 120.000 1.000
67.000 122.000 1.000
67.100 119.000 1.000
67.200 106.000 1.000
67.300 101.000 1.000
67.400 128.000 1.000
67.500 120.000 1.000
67.600 114.000 1.000
67.700 126.000 1.000
67.800 120.000 1.000
67.900 110.000 1.000
68.000 130.000 1.000
68.100 120.000 1.000
68.200 106.000 1.000
68.300 120.000 1.000
68.400 123.000 1.000
68.500 127.000 1.000
68.600 122.000 1.000
68.700 113.000 1.000
68.800 108.000 1.000
68.900 119.000 1.000
69.000 124.000 1.000
69.100 119.000 1.000
69.200 124.000 1.000
69.300 124.000 1.000
69.400 114.000 1.000
69.500 119.000 1.000
69.600 118.000 1.000
69.700 118.000 1.000
69.800 128.000 1.000
69.900 132.000 1.000
70.000 114.000 1.000
70.100 120.000 1.000
70.200 115.000 1.000
70.300 106.000 1.000
70.400 116.000 1.000
70.500 121.000 1.000
70.600 115.000 1.000
70.700 124.000 1.000
70.800 115.000 1.000
70.900 113.000 1.000
71.000 112.000 1.000
71.100 127.000 1.000
71.200 134.000 1.000
71.300 125.000 1.000
71.400 122.000 1.000
71.500 119.000 1.000
71.600 137.000 1.000
71.700 125.000 1.000
71.800 136.000 1.000
71.900 126.000 1.000
72.000 144.000 1.000
72.100 125.000 1.000
72.200 129.000 1.000
72.300 128.000 1.000
72.400 120.000 1.000
72.500 128.000 1.000
72.600 129.000 1.000
72.700 131.000 1.000
72.800 125.000 1.000
72.900 130.000 1.000
73.000 129.000 1.000
73.100 130.000 1.000
73.200 128.000 1.000
73.300 132.000 1.000
73.400 149.000 1.000
73.500 138.000 1.000
73.600 143.000 1.000
73.700 159.000 1.000
73.800 140.000 1.000
73.900 162.000 1.000
74.000 153.000 1.000
74.100 162.000 1.000
74.200 160.000 1.000
74.300 154.000 1.000
74.400 168.000 1.000
74.500 156.000 1.000
74.600 164.000 1.000
74.700 172.000 1.000
74.800 160.000 1.000
74.900 169.000 1.000
75.000 179.000 1.000
75.100 171.000 1.000
75.200 174.000 1.000
75.300 179.000 1.000
75.400 178.000 1.000
75.500 188.000 1.000
75.600 187.000 1.000
75.700 206.000 1.000
75.800 224.000 1.000
75.900 282.000 1.000
76.000 393.000 1.000
76.100 468.000 1.000
76.200 725.000 1.000
76.300 1676.000 1.000
76.400 7267.000 1.000
76.500 6191.000 1.000
76.600 3451.000 1.000
76.700 4559.000 1.000
76.800 1253.000 1.000
76.900 572.000 1.000
77.000 366.000 1.000
77.100 289.000 1.000
77.200 234.000 1.000
77.300 224.000 1.000
77.400 205.000 1.000
77.500 202.000 1.000
77.600 189.000 1.000
77.700 202.000 1.000
77.800 192.000 1.000
77.900 199.000 1.000
78.000 187.000 1.000
78.100 166.000 1.000
78.200 168.000 1.000
78.300 177.000 1.000
78.400 185.000 1.000
78.500 174.000 1.000
78.600 164.000 1.000
78.700 159.000 1.000
78.800 174.000 1.000
78.900 172.000 1.000
79.000 180.000 1.000
79.100 168.000 1.000
79.200 176.000 1.000
79.300 162.000 1.000
79.400 159.000 1.000
79.500 177.000 1.000
79.600 175.000 1.000
79.700 188.000 1.000
79.800 168.000 1.000
79.900 181.000 1.000
80.000 211.000 1.000
80.100 253.000 1.000
80.200 326.000 1.000
80.300 335.000 1.000
80.400 485.000 1.000
80.500 1043.000 1.000
80.600 4585.000 1.000
80.700 4873.000 1.000
80.800 1823.000 1.000
80.900 3596.000 1.000
81.000 1234.000 1.000
81.100 453.000 1.000
81.200 298.000 1.000
81.300 228.000 1.000
81.400 207.000 1.000
81.500 184.000 1.000
81.600 174.000 1.000
81.700 159.000 1.000
81.800 172.000 1.000
81.900 161.000 1.000
82.000 144.000 1.000
82.100 147.000 1.000
82.200 142.000 1.000
82.300 139.000 1.000
82.400 150.000 1.000
82.500 136.000 1.000
82.600 149.000 1.000
82.700 124.000 1.000
82.800 128.000 1.000
82.900 123.000 1.000
83.000 140.000 1.000
83.100 125.000 1.000
83.200 144.000 1.000
83.300 133.000 1.000
83.400 123.000 1.000
83.500 121.000 1.000
83.600 133.000 1.000
83.700 117.000 1.000
83.800 127.000 1.000
83.900 116.000 1.000
84.000 123.000 1.000
84.100 131.000 1.000
84.200 114.000 1.000
84.300 109.000 1.000
84.400 116.000 1.000
84.500 111.000 1.000
84.600 125.000 1.000
84.700 118.000 1.000
84.800 108.000 1.000
84.900 106.000 1.000
85.000 118.000 1.000
85.100 118.000 1.000
85.200 109.000 1.000
85.300 114.000 1.000
85.400 109.000 1.000
85.500 108.000 1.000
85.600 117.000 1.000
85.700 111.000 1.000
85.800 123.000 1.000
85.900 103.000 1.000
86.000 103.000 1.000
86.100 108.000 1.000
86.200 109.000 1.000
86.300 101.000 1.000
86.400 106.000 1.000
86.500 102.000 1.000
86.600 101.000 1.000
86.700 109.000 1.000
86.800 99.000 1.000
86.900 106.000 1.000
87.000 98.000 1.000
87.100 102.000 1.000
87.200 94.000 1.000
87.300 98.000 1.000
87.400 104.000 1.000
87.500 96.000 1.000
87.600 104.000 1.000
87.700 103.000 1.000
87.800 94.000 1.000
87.900 108.000 1.000
88.000 102.000 1.000
88.100 93.000 1.000
88.200 108.000 1.000
88.300 95.000 1.000
88.400 100.000 1.000
88.500 91.000 1.000
88.600 101.000 1.000
88.700 97.000 1.000
88.800 93.000 1.000
88.900 98.000 1.000
89.000 91.000 1.000
89.100 95.000 1.000
89.200 97.000 1.000
89.300 102.000 1.000
89.400 102.000 1.000
89.500 99.000 1.000
89.600 102.000 1.000
89.700 95.000 1.000
89.800 89.000 1.000
89.900 101.000 1.000
90.000 92.000 1.000
90.100 90.000 1.000
90.200 101.000 1.000
90.300 95.000 1.000
90.400 98.000 1.000
90.500 106.000 1.000
90.600 79.000 1.000
90.700 86.000 1.000
90.800 92.000 1.000
90.900 89.000 1.000
91.000 89.000 1.000
91.100 93.000 1.000
91.200 93.000 1.000
91.300 89.000 1.000
91.400 94.000 1.000
91.500 93.000 1.000
91.600 88.000 1.000
91.700 85.000 1.000
91.800 98.000 1.000
91.900 97.000 1.000
92.000 85.000 1.000
92.100 89.000 1.000
92.200 80.000 1.000
92.300 104.000 1.000
92.400 89.000 1.000
92.500 103.000 1.000
92.600 93.000 1.000
92.700 104.000 1.000
92.800 84.000 1.000
92.900 98.000 1.000
93.000 105.000 1.000
93.100 93.000 1.000
93.200 92.000 1.000
93.300 95.000 1.000
93.400 97.000 1.000
93.500 96.000 1.000
93.600 98.000 1.000
93.700 82.000 1.000
93.800 96.000 1.000
93.900 107.000 1.000
94.000 91.000 1.000
94.100 94.000 1.000
94.200 104.000 1.000
94.300 104.000 1.000
94.400 103.000 1.000
94.500 93.000 1.000
94.600 80.000 1.000
94.700 91.000 1.000
94.800 96.000 1.000
94.900 102.000 1.000
95.000 94.000 1.000
95.100 108.000 1.000
95.200 95.000 1.000
95.300 100.000 1.000
95.400 92.000 1.000
95.500 104.000 1.000
95.600 95.000 1.000
95.700 97.000 1.000
95.800 97.000 1.000
95.900 100.000 1.000
96.000 98.000 1.000
96.100 98.000 1.000
96.200 91.000 1.000
96.300 101.000 1.000
96.400 114.000 1.000
96.500 93.000 1.000
96.600 107.000 1.000
96.700 126.000 1.000
96.800 144.000 1.000
96.900 167.000 1.000
97.000 212.000 1.000
97.100 345.000 1.000
97.200 930.000 1.000
97.300 1136.000 1.000
97.400 435.000 1.000
97.500 479.000 1.000
97.600 712.000 1.000
97.700 310.000 1.000
97.800 168.000 1.000
97.900 140.000 1.000
98.000 131.000 1.000
98.100 120.000 1.000
98.200 99.000 1.000
98.300 97.000 1.000
98.400 108.000 1.000
98.500 110.000 1.000
98.600 99.000 1.000
98.700 100.000 1.000
98.800 115.000 1.000
98.900 95.000 1.000
99.000 101.000 1.000
99.100 95.000 1.000
99.200 89.000 1.000
99.300 107.000 1.000
99.400 86.000 1.000
99.500 86.000 1.000
99.600 72.000 1.000
99.700 97.000 1.000
99.800 87.000 1.000
99.900 98.000 1.000
100.000 86.000 1.000
100.100 99.000 1.000
100.200 92.000 1.000
100.300 84.000 1.000
100.400 99.000 1.000
100.500 95.000 1.000
100.600 87.000 1.000
100.700 100.000 1.000
100.800 91.000 1.000
100.900 93.000 1.000
101.000 83.000 1.000
101.100 89.000 1.000
101.200 88.000 1.000
101.300 91.000 1.000
101.400 106.000 1.000
101.500 85.000 1.000
101.600 87.000 1.000
101.700 78.000 1.000
101.800 90.000 1.000
101.900 90.000 1.000
102.000 92.000 1.000
102.100 93.000 1.000
102.200 98.000 1.000
102.300 98.000 1.000
102.400 102.000 1.000
102.500 91.000 1.000
102.600 96.000 1.000
102.700 92.000 1.000
102.800 101.000 1.000
102.900 71.000 1.000
103.000 103.000 1.000
103.100 94.000 1.000
103.200 99.000 1.000
103.300 92.000 1.000
103.400 97.000 1.000
103.500 98.000 1.000
103.600 91.000 1.000
103.700 98.000 1.000
103.800 88.000 1.000
103.900 91.000 1.000
104.000 94.000 1.000
104.100 87.000 1.000
104.200 89.000 1.000
104.300 87.000 1.000
104.400 93.000 1.000
104.500 89.000 1.000
104.600 91.000 1.000
104.700 109.000 1.000
104.800 107.000 1.000
104.900 95.000 1.000
105.000 114.000 1.000
105.100 99.000 1.000
105.200 89.000 1.000
105.300 107.000 1.000
105.400 97.000 1.000
105.500 103.000 1.000
105.600 108.000 1.000
105.700 104.000 1.000
105.800 103.000 1.000
105.900 105.000 1.000
106.000 108.000 1.000
106.100 115.000 1.000
106.200 101.000 1.000
106.300 106.000 1.000
106.400 111.000 1.000
106.500 101.000 1.000
106.600 106.000 1.000
106.700 107.000 1.000
106.800 105.000 1.000
106.900 111.000 1.000
107.000 119.000 1.000
107.100 94.000 1.000
107.200 109.000 1.000
107.300 104.000 1.000
107.400 101.000 1.000
107.500 109.000 1.000
107.600 113.000 1.000
107.700 110.000 1.000
107.800 95.000 1.000
107.900 98.000 1.000
108.000 109.000 1.000
108.100 116.000 1.000
108.200 120.000 1.000
108.300 117.000 1.000
108.400 112.000 1.000
108.500 122.000 1.000
108.600 113.000 1.000
108.700 120.000 1.000
108.800 112.000 1.000
108.900 129.000 1.000
109.000 117.000 1.000
109.100 125.000 1.000
109.200 130.000 1.000
109.300 159.000 1.000
109.400 171.000 1.000
109.500 165.000 1.000
109.600 171.000 1.000
109.700 205.000 1.000
109.800 242.000 1.000
109.900 398.000 1.000
110.000 839.000 1.000
110.100 2310.000 1.000
110.200 2109.000 1.000
110.300 786.000 1.000
110.400 622.000 1.000
110.500 1083.000 1.000
110.600 1288.000 1.000
110.700 555.000 1.000
110.800 305.000 1.000
110.900 220.000 1.000
111.000 201.000 1.000
111.100 179.000 1.000
111.200 146.000 1.000
111.300 146.000 1.000
111.400 134.000 1.000
111.500 147.000 1.000
111.600 145.000 1.000
111.700 133.000 1.000
111.800 146.000 1.000
111.900 133.000 1.000
112.000 130.000 1.000
112.100 123.000 1.000
112.200 131.000 1.000
112.300 129.000 1.000
112.400 129.000 1.000
112.500 123.000 1.000
112.600 140.000 1.000
112.700 131.000 1.000
112.800 127.000 1.000
112.900 134.000 1.000
113.000 133.000 1.000
113.100 136.000 1.000
113.200 136.000 1.000
113.300 134.000 1.000
113.400 122.000 1.000
113.500 129.000 1.000
113.600 127.000 1.000
113.700 149.000 1.000
113.800 153.000 1.000
113.900 159.000 1.000
114.000 155.000 1.000
114.100 168.000 1.000
114.200 219.000 1.000
114.300 264.000 1.000
114.400 322.000 1.000
114.500 611.000 1.000
114.600 1404.000 1.000
114.700 1554.000 1.000
114.800 677.000 1.000
114.900 480.000 1.000
115.000 563.000 1.000
115.100 960.000 1.000
115.200 660.000 1.000
115.300 330.000 1.000
115.400 213.000 1.000
115.500 195.000 1.000
115.600 161.000 1.000
115.700 156.000 1.000
115.800 155.000 1.000
115.900 158.000 1.000
116.000 144.000 1.000
116.100 131.000 1.000
116.200 122.000 1.000
116.300 127.000 1.000
116.400 134.000 1.000
116.500 125.000 1.000
116.600 128.000 1.000
116.700 136.000 1.000
116.800 117.000 1.000
116.900 129.000 1.000
117.000 125.000 1.000
117.100 126.000 1.000
117.200 122.000 1.000
117.300 122.000 1.000
117.400 120.000 1.000
117.500 116.000 1.000
117.600 109.000 1.000
117.700 112.000 1.000
117.800 126.000 1.000
117.900 105.000 1.000
118.000 125.000 1.000
118.100 122.000 1.000
118.200 113.000 1.000
118.300 123.000 1.000
118.400 115.000 1.000
118.500 116.000 1.000
118.600 107.000 1.000
118.700 128.000 1.000
118.800 114.000 1.000
118.900 121.000 1.000
119.000 128.000 1.000
119.100 117.000 1.000
119.200 138.000 1.000
119.300 109.000 1.000
119.400 120.000 1.000
119.500 126.000 1.000
119.600 114.000 1.000
119.700 136.000 1.000
119.800 134.000 1.000
119.900 105.000 1.000
120.000 126.000 1.000
120.100 120.000 1.000
120.200 118.000 1.000
120.300 114.000 1.000
120.400 121.000 1.000
120.500 122.000 1.000
120.600 124.000 1.000
120.700 119.000 1.000
120.800 112.000 1.000
120.900 123.000 1.000
121.000 117.000 1.000
121.100 125.000 1.000
121.200 129.000 1.000
121.300 119.000 1.000
121.400 115.000 1.000
121.500 108.000 1.000
121.600 122.000 1.000
121.700 116.000 1.000
121.800 118.000 1.000
121.900 127.000 1.000
122.000 113.000 1.000
122.100 132.000 1.000
122.200 107.000 1.000
122.300 114.000 1.000
122.400 130.000 1.000
122.500 123.000 1.000
122.600 117.000 1.000
122.700 117.000 1.000
122.800 118.000 1.000
122.900 125.000 1.000
123.000 125.000 1.000
123.100 117.000 1.000
123.200 119.000 1.000
123.300 125.000 1.000
123.400 113.000 1.000
123.500 115.000 1.000
123.600 128.000 1.000
123.700 118.000 1.000
123.800 125.000 1.000
123.900 127.000 1.000
124.000 123.000 1.000
124.100 125.000 1.000
124.200 130.000 1.000
124.300 124.000 1.000
124.400 123.000 1.000
124.500 121.000 1.000
124.600 129.000 1.000
124.700 112.000 1.000
124.800 119.000 1.000
124.900 117.000 1.000
125.000 113.000 1.000
125.100 132.000 1.000
125.200 147.000 1.000
125.300 131.000 1.000
125.400 124.000 1.000
125.500 120.000 1.000
125.600 113.000 1.000
125.700 115.000 1.000
125.800 122.000 1.000
125.900 129.000 1.000
126.000 115.000 1.000
126.100 128.000 1.000
126.200 117.000 1.000
126.300 118.000 1.000
126.400 120.000 1.000
126.500 127.000 1.000
126.600 136.000 1.000
126.700 130.000 1.000
126.800 128.000 1.000
126.900 131.000 1.000
127.000 135.000 1.000
127.100 141.000 1.000
127.200 127.000 1.000
127.300 143.000 1.000
127.400 138.000 1.000
127.500 140.000 1.000
127.600 126.000 1.000
127.700 127.000 1.000
127.800 142.000 1.000
127.900 122.000 1.000
128.000 129.000 1.000
128.100 129.000 1.000
128.200 123.000 1.000
128.300 124.000 1.000
128.400 132.000 1.000
128.500 137.000 1.000
128.600 126.000 1.000
128.700 137.000 1.000
128.800 122.000 1.000
128.900 138.000 1.000
129.000 128.000 1.000
129.100 140.000 1.000
129.200 149.000 1.000
129.300 146.000 1.000
129.400 145.000 1.000
129.500 139.000 1.000
129.600 135.000 1.000
129.700 132.000 1.000
129.800 139.000 1.000
129.900 141.000 1.000
130.000 140.000 1.000
130.100 142.000 1.000
130.200 145.000 1.000
130.300 134.000 1.000
130.400 133.000 1.000
130.500 132.000 1.000
130.600 141.000 1.000
130.700 128.000 1.000
130.800 140.000 1.000
130.900 136.000 1.000
131.000 141.000 1.000
131.100 141.000 1.000
131.200 134.000 1.000
131.300 144.000 1.000
131.400 151.000 1.000
131.500 140.000 1.000
131.600 147.000 1.000
131.700 135.000 1.000
131.800 123.000 1.000
131.900 144.000 1.000
132.000 142.000 1.000
132.100 145.000 1.000
132.200 152.000 1.000
132.300 152.000 1.000
132.400 156.000 1.000
132.500 152.000 1.000
132.600 144.000 1.000
132.700 167.000 1.000
132.800 142.000 1.000
132.900 162.000 1.000
133.000 155.000 1.000
133.100 158.000 1.000
133.200 146.000 1.000
133.300 169.000 1.000
133.400 166.000 1.000
133.500 156.000 1.000
133.600 181.000 1.000
133.700 178.000 1.000
133.800 168.000 1.000
133.900 178.000 1.000
134.000 195.000 1.000
134.100 193.000 1.000
134.200 202.000 1.000
134.300 210.000 1.000
134.400 227.000 1.000
134.500 266.000 1.000
134.600 302.000 1.000
134.700 352.000 1.000
134.800 477.000 1.000
134.900 681.000 1.000
135.000 1158.000 1.000
135.100 1954.000 1.000
135.200 2740.000 1.000
135.300 1896.000 1.000
135.400 1046.000 1.000
135.500 648.000 1.000
135.600 607.000 1.000
135.700 736.000 1.000
135.800 1081.000 1.000
135.900 1432.000 1.000
136.000 1121.000 1.000
136.100 659.000 1.000
136.200 414.000 1.000
136.300 318.000 1.000
136.400 265.000 1.000
136.500 241.000 1.000
136.600 215.000 1.000
136.700 202.000 1.000
136.800 197.000 1.000
136.900 170.000 1.000
137.000 172.000 1.000
137.100 190.000 1.000
137.200 166.000 1.000
137.300 175.000 1.000
137.400 152.000 1.000
137.500 169.000 1.000
137.600 180.000 1.000
137.700 160.000 1.000
137.800 152.000 1.000
137.900 166.000 1.000
138.000 151.000 1.000
138.100 155.000 1.000
138.200 160.000 1.000
138.300 162.000 1.000
138.400 159.000 1.000
138.500 162.000 1.000
138.600 157.000 1.000
138.700 158.000 1.000
138.800 165.000 1.000
138.900 156.000 1.000
139.000 155.000 1.000
139.100 165.000 1.000
139.200 155.000 1.000
139.300 150.000 1.000
139.400 151.000 1.000
139.500 164.000 1.000
139.600 166.000 1.000
139.700 154.000 1.000
139.800 147.000 1.000
139.900 156.000 1.000
140.000 163.000 1.000
*RAS_INT_END
*RAS_DATA_END