File: Alu_Halter_flach.ras
*RAS_DATA_START
*RAS_HEADER_START
*CORR_POS_DB_NAME "AngleCorr_NIST640d_DteX_2022.02.28"
*CORR_POS_GONIO_RADIUS ""
*CORR_POS_NODE_INDEX01 ""
*CORR_POS_NODE_INDEX02 ""
*CORR_POS_NODE_INDEX03 ""
*CORR_POS_NODE_INDEX04 ""
*CORR_POS_NODE_INDEX05 ""
*CORR_POS_NODE_INDEX06 ""
*CORR_POS_NODE_INDEX07 ""
*CORR_POS_NODE_INDEX08 ""
*CORR_POS_NODE_INDEX09 ""
*CORR_POS_NODE_INDEX10 ""
*CORR_POS_NODE_INDEX11 ""
*CORR_POS_NODE_LABEL01 "Si(111)"
*CORR_POS_NODE_LABEL02 "Si(220)"
*CORR_POS_NODE_LABEL03 "Si(311)"
*CORR_POS_NODE_LABEL04 "Si(400)"
*CORR_POS_NODE_LABEL05 "Si(331)"
*CORR_POS_NODE_LABEL06 "Si(422)"
*CORR_POS_NODE_LABEL07 "Si(511)"
*CORR_POS_NODE_LABEL08 "Si(440)"
*CORR_POS_NODE_LABEL09 "Si(531)"
*CORR_POS_NODE_LABEL10 "Si(620)"
*CORR_POS_NODE_LABEL11 "Si(533)"
*CORR_POS_NODE_POS_CALC01 "28.4137"
*CORR_POS_NODE_POS_CALC02 "47.2707"
*CORR_POS_NODE_POS_CALC03 "56.0883"
*CORR_POS_NODE_POS_CALC04 "69.0934"
*CORR_POS_NODE_POS_CALC05 "76.3385"
*CORR_POS_NODE_POS_CALC06 "87.9915"
*CORR_POS_NODE_POS_CALC07 "94.9137"
*CORR_POS_NODE_POS_CALC08 "106.67"
*CORR_POS_NODE_POS_CALC09 "114.054"
*CORR_POS_NODE_POS_CALC10 "127.508"
*CORR_POS_NODE_POS_CALC11 "136.858"
*CORR_POS_NODE_POS_MEAS01 "28.3905"
*CORR_POS_NODE_POS_MEAS02 "47.2504"
*CORR_POS_NODE_POS_MEAS03 "56.0712"
*CORR_POS_NODE_POS_MEAS04 "69.0788"
*CORR_POS_NODE_POS_MEAS05 "76.3323"
*CORR_POS_NODE_POS_MEAS06 "87.9869"
*CORR_POS_NODE_POS_MEAS07 "94.9135"
*CORR_POS_NODE_POS_MEAS08 "106.672"
*CORR_POS_NODE_POS_MEAS09 "114.061"
*CORR_POS_NODE_POS_MEAS10 "127.517"
*CORR_POS_NODE_POS_MEAS11 "136.874"
*CORR_POS_OPT_ATTR "集中法"
*CORR_POS_PARAM_MU ""
*CORR_POS_PARAM_PL ""
*CORR_POS_SEMODEL_TYPE "0"
*CORR_POS_STANDARD_TYPE ""
*CORR_POS_VALUE_ANALYZER "None"
*CORR_POS_VALUE_CMONO "None"
*CORR_POS_VALUE_IMONO "None"
*CORR_POS_VALUE_IS "0.625deg"
*CORR_POS_VALUE_ISL "10.0mm"
*CORR_POS_VALUE_ISOLLER "2.5deg"
*CORR_POS_VALUE_RS1 "13.0mm"
*CORR_POS_VALUE_RS2 "13.0mm"
*CORR_POS_VALUE_RSOLLER "2.5deg"
*CORR_POS_XG_FOCUS_L ""
*CORR_POS_XG_WAVE_TYPE ""
*CORR_POS_XG_WAVE_VALUE ""
*DISP_FMT_X "%.2f"
*DISP_FMT_Y "%.0f"
*DISP_FULLSCALE "275736.0000000000"
*DISP_LINE_COLOR "255.0000000000"
*DISP_LINE_STYLE "0.0000000000"
*DISP_LINE_WIDTH "0.2500000000"
*DISP_NOTE "Collected Data-1"
*DISP_OFFSET_Y "0.0000000000"
*DISP_PEAKSEARCH_UNIT_Y "cps"
*DISP_RANGE_BOTTOM "0.0000000000"
*DISP_RANGE_LEFT "2.0000000000"
*DISP_RANGE_LOGCUTOFF "0.0100000000"
*DISP_RANGE_RIGHT "140.0000000000"
*DISP_RANGE_TOP "275736.0000000000"
*DISP_SCALE_MODE_Y "0.0000000000"
*DISP_TAB_NAME "Theta/2-Theta"
*DISP_TITLE_Y "Intensity"
*DISP_UNIT_Y "cps"
*DISP_WINDOW_NAME "MSG_MACROENGINE"
*FILE_COMMENT " "
*FILE_MD5 ""
*FILE_MEMO " "
*FILE_OPERATOR "Administrator"
*FILE_SAMPLE "Alu_Halter_flach"
*FILE_TYPE "RAS_RAW"
*FILE_USERGROUP "System Manager"
*FILE_VERSION "1.0000000000"
*HW_ATTACHMENT_ID "ATT1031"
*HW_ATTACHMENT_NAME "6サンプルチェンジャ|ASC-6"
*HW_COUNTER_ID-0 "CUT0025"
*HW_COUNTER_ID-1 "CUT0020"
*HW_COUNTER_ID-2 "CUT0020"
*HW_COUNTER_ID-3 "CMC0021"
*HW_COUNTER_NAME-0 "D/teX Ultra|D/teX Ultra"
*HW_COUNTER_NAME-1 "None|None"
*HW_COUNTER_NAME-2 "None|None"
*HW_COUNTER_NAME-3 "検出器モノクロメータ|Detector monochromator"
*HW_COUNTER_SELECT_NAME "D/teX Ultra|D/teX Ultra"
*HW_GONIOMETER_ID "GON0070"
*HW_GONIOMETER_NAME "MiniFlex 300/600|MiniFlex 300/600"
*HW_GONIOMETER_RADIUS-0 "79.0"
*HW_GONIOMETER_RADIUS-1 "91.5"
*HW_GONIOMETER_RADIUS-2 "150.0"
*HW_GONIOMETER_RADIUS-3 "0"
*HW_GONIOMETER_RADIUS-4 "103.4"
*HW_GONIOMETER_RADIUS-5 "150.0"
*HW_GONIOMETER_RADIUS-6 "46.6"
*HW_GONIOMETER_RADIUS-7 "160.0"
*HW_I_OPT_ID-0 "ISL0021"
*HW_I_OPT_ID-1 "ISO0021"
*HW_I_OPT_NAME-0 "発散スリット|Divergence slit"
*HW_I_OPT_NAME-1 "入射平行スリット|Incident parallel slit"
*HW_R_ATTENUATER_AUTOMODE "0"
*HW_R_OPT_ID-0 "RSS0021"
*HW_R_OPT_ID-1 "RSO0021"
*HW_R_OPT_ID-2 "RRS0021"
*HW_R_OPT_NAME-0 "散乱スリット|Scattering slit"
*HW_R_OPT_NAME-1 "受光平行スリット|Receiving soller slit"
*HW_R_OPT_NAME-2 "受光スリット|Receiving slit"
*HW_SAMPLE_HOLDER_ID "SMP0000"
*HW_SAMPLE_HOLDER_NAME "無し|None"
*HW_XG_CURRENT_MAX "15"
*HW_XG_CURRENT_MIN "2"
*HW_XG_CURRENT_RESOLUTION "1"
*HW_XG_CURRENT_UNIT "mA"
*HW_XG_FOCUS "1mm x 10mm"
*HW_XG_FOCUS_TYPE "Normal"
*HW_XG_ID ""
*HW_XG_NAME "300W/600W 封入管-B|300W/600W Sealed tube-B"
*HW_XG_TARGET_ATOMIC_NUMBER "29.0000000000"
*HW_XG_TARGET_NAME "Cu"
*HW_XG_TYPE "Hermetic"
*HW_XG_VOLTAGE_MAX "40"
*HW_XG_VOLTAGE_MIN "20"
*HW_XG_VOLTAGE_RESOLUTION "1"
*HW_XG_VOLTAGE_UNIT "kV"
*HW_XG_WATT_MAX "1"
*HW_XG_WATT_UNIT "kW"
*HW_XG_WAVE_LENGTH_ALPHA1 "1.540593"
*HW_XG_WAVE_LENGTH_ALPHA2 "1.544414"
*HW_XG_WAVE_LENGTH_BETA "1.392250"
*MEAS_COND_AXIS_NAME-0 "Theta/2-Theta"
*MEAS_COND_AXIS_NAME-1 "Spin"
*MEAS_COND_AXIS_NAME-2 "Change"
*MEAS_COND_AXIS_NAME-3 "Soller(inc.)"
*MEAS_COND_AXIS_NAME-4 "IHS"
*MEAS_COND_AXIS_NAME-5 "DS"
*MEAS_COND_AXIS_NAME-6 "SS"
*MEAS_COND_AXIS_NAME-7 "Soller(rec.)"
*MEAS_COND_AXIS_NAME-8 "RS"
*MEAS_COND_AXIS_NAME-9 "Filter"
*MEAS_COND_AXIS_NAME-10 "Monochromator"
*MEAS_COND_AXIS_NAME-11 "PHA"
*MEAS_COND_AXIS_NAME_INTERNAL-0 "TwoThetaTheta"
*MEAS_COND_AXIS_NAME_INTERNAL-1 "Spin"
*MEAS_COND_AXIS_NAME_INTERNAL-2 "Change"
*MEAS_COND_AXIS_NAME_INTERNAL-3 "IncidentSollerSlit"
*MEAS_COND_AXIS_NAME_INTERNAL-4 "IncidentAxdSlit"
*MEAS_COND_AXIS_NAME_INTERNAL-5 "IncidentSlitBox"
*MEAS_COND_AXIS_NAME_INTERNAL-6 "ReceivingSlitBox1"
*MEAS_COND_AXIS_NAME_INTERNAL-7 "ReceivingSollerSlit"
*MEAS_COND_AXIS_NAME_INTERNAL-8 "ReceivingSlitBox2"
*MEAS_COND_AXIS_NAME_INTERNAL-9 "Filter"
*MEAS_COND_AXIS_NAME_INTERNAL-10 "CounterMonochromator"
*MEAS_COND_AXIS_NAME_INTERNAL-11 "PHA"
*MEAS_COND_AXIS_NAME_MAGICNO-0 "268632064.0000000000"
*MEAS_COND_AXIS_NAME_MAGICNO-1 "16842752.0000000000"
*MEAS_COND_AXIS_NAME_MAGICNO-2 "16842752.0000000000"
*MEAS_COND_AXIS_NAME_MAGICNO-3 "20971521.0000000000"
*MEAS_COND_AXIS_NAME_MAGICNO-4 "22020097.0000000000"
*MEAS_COND_AXIS_NAME_MAGICNO-5 "22020097.0000000000"
*MEAS_COND_AXIS_NAME_MAGICNO-6 "23068673.0000000000"
*MEAS_COND_AXIS_NAME_MAGICNO-7 "20971521.0000000000"
*MEAS_COND_AXIS_NAME_MAGICNO-8 "23068673.0000000000"
*MEAS_COND_AXIS_NAME_MAGICNO-9 "20971521.0000000000"
*MEAS_COND_AXIS_NAME_MAGICNO-10 "20971521.0000000000"
*MEAS_COND_AXIS_NAME_MAGICNO-11 "0.0000000000"
*MEAS_COND_AXIS_OFFSET-0 "0.0000000000"
*MEAS_COND_AXIS_OFFSET-1 "-"
*MEAS_COND_AXIS_OFFSET-2 "-"
*MEAS_COND_AXIS_OFFSET-3 "-"
*MEAS_COND_AXIS_OFFSET-4 "-"
*MEAS_COND_AXIS_OFFSET-5 "-"
*MEAS_COND_AXIS_OFFSET-6 "-"
*MEAS_COND_AXIS_OFFSET-7 "-"
*MEAS_COND_AXIS_OFFSET-8 "-"
*MEAS_COND_AXIS_OFFSET-9 "-"
*MEAS_COND_AXIS_OFFSET-10 "-"
*MEAS_COND_AXIS_OFFSET-11 "-"
*MEAS_COND_AXIS_POSITION-0 "10.0000000000"
*MEAS_COND_AXIS_POSITION-1 "0.0000000000"
*MEAS_COND_AXIS_POSITION-2 "1.0000000000"
*MEAS_COND_AXIS_POSITION-3 "2.5deg"
*MEAS_COND_AXIS_POSITION-4 "10.0mm"
*MEAS_COND_AXIS_POSITION-5 "0.625deg"
*MEAS_COND_AXIS_POSITION-6 "8.0mm"
*MEAS_COND_AXIS_POSITION-7 "2.5deg"
*MEAS_COND_AXIS_POSITION-8 "13.0mm"
*MEAS_COND_AXIS_POSITION-9 "K-beta(x2)"
*MEAS_COND_AXIS_POSITION-10 "None"
*MEAS_COND_AXIS_POSITION-11 "49.0000000000"
*MEAS_COND_AXIS_UNIT-0 "deg"
*MEAS_COND_AXIS_UNIT-1 ""
*MEAS_COND_AXIS_UNIT-2 ""
*MEAS_COND_AXIS_UNIT-3 ""
*MEAS_COND_AXIS_UNIT-4 ""
*MEAS_COND_AXIS_UNIT-5 ""
*MEAS_COND_AXIS_UNIT-6 ""
*MEAS_COND_AXIS_UNIT-7 ""
*MEAS_COND_AXIS_UNIT-8 ""
*MEAS_COND_AXIS_UNIT-9 ""
*MEAS_COND_AXIS_UNIT-10 ""
*MEAS_COND_AXIS_UNIT-11 "div"
*MEAS_COND_CORRECTION_SLIT_COUNTERMONO "None"
*MEAS_COND_CORRECTION_SLIT_DS "0.625deg"
*MEAS_COND_CORRECTION_SLIT_FILTER "None"
*MEAS_COND_CORRECTION_SLIT_IHS "10.0mm"
*MEAS_COND_CORRECTION_SLIT_RS "13.0mm"
*MEAS_COND_CORRECTION_SLIT_SOLLER_INC "2.5deg"
*MEAS_COND_CORRECTION_SLIT_SOLLER_REC "2.5deg"
*MEAS_COND_CORRECTION_SLIT_SS "8.0mm"
*MEAS_COND_COUNTER_CNTLOSS_CORR "0.0000000000"
*MEAS_COND_COUNTER_PHABASE "49.0000000000"
*MEAS_COND_COUNTER_PHAWINDOW "8.0000000000"
*MEAS_COND_COUNTER_PHA_UNIT "div"
*MEAS_COND_COUNTER_TAUDIFF "0.2500000000"
*MEAS_COND_COUNTER_TAUINT "0.7500000000"
*MEAS_COND_IRRADIATION_MODE "OFF"
*MEAS_COND_IRRADIATION_WIDTH ""
*MEAS_COND_OPT_ATTR " "
*MEAS_COND_OPT_NAME ""
*MEAS_COND_UNSYMMETRIC_MODE "OFF"
*MEAS_COND_XG_CURRENT "15.0000000000"
*MEAS_COND_XG_VOLTAGE "40.0000000000"
*MEAS_COND_XG_WAVE_TYPE "Ka"
*MEAS_DATA_COUNT "13801.0000000000"
*MEAS_SCAN_AXIS_X "Theta/2-Theta"
*MEAS_SCAN_AXIS_X_INTERNAL "TwoThetaTheta"
*MEAS_SCAN_END_TIME "06/22/22 14:59:51"
*MEAS_SCAN_MODE "CONTINUOUS"
*MEAS_SCAN_MONITOR "0"
*MEAS_SCAN_RESOLUTION_X "0.005"
*MEAS_SCAN_SPEED "1.000"
*MEAS_SCAN_SPEED_UNIT "deg/min"
*MEAS_SCAN_START "2.0000000000"
*MEAS_SCAN_START_TIME "06/22/22 12:36:38"
*MEAS_SCAN_STEP "0.0100000000"
*MEAS_SCAN_STOP "140.0000000000"
*MEAS_SCAN_UNIT_X "deg"
*MEAS_SCAN_UNIT_Y "counts"
*SLIT_SYSTEM "0"
*RAS_HEADER_END
*RAS_INT_START
2.000 1139.000 1.000
2.100 1213.000 1.000
2.200 1243.000 1.000
2.300 1047.000 1.000
2.400 1073.000 1.000
2.500 1023.000 1.000
2.600 984.000 1.000
2.700 992.000 1.000
2.800 963.000 1.000
2.900 882.000 1.000
3.000 862.000 1.000
3.100 819.000 1.000
3.200 764.000 1.000
3.300 863.000 1.000
3.400 804.000 1.000
3.500 811.000 1.000
3.600 804.000 1.000
3.700 701.000 1.000
3.800 796.000 1.000
3.900 694.000 1.000
4.000 695.000 1.000
4.100 749.000 1.000
4.200 676.000 1.000
4.300 721.000 1.000
4.400 664.000 1.000
4.500 666.000 1.000
4.600 629.000 1.000
4.700 654.000 1.000
4.800 661.000 1.000
4.900 665.000 1.000
5.000 614.000 1.000
5.100 573.000 1.000
5.200 596.000 1.000
5.300 571.000 1.000
5.400 629.000 1.000
5.500 576.000 1.000
5.600 592.000 1.000
5.700 586.000 1.000
5.800 592.000 1.000
5.900 548.000 1.000
6.000 565.000 1.000
6.100 565.000 1.000
6.200 569.000 1.000
6.300 543.000 1.000
6.400 582.000 1.000
6.500 578.000 1.000
6.600 573.000 1.000
6.700 545.000 1.000
6.800 548.000 1.000
6.900 586.000 1.000
7.000 554.000 1.000
7.100 566.000 1.000
7.200 546.000 1.000
7.300 566.000 1.000
7.400 559.000 1.000
7.500 549.000 1.000
7.600 592.000 1.000
7.700 602.000 1.000
7.800 605.000 1.000
7.900 594.000 1.000
8.000 583.000 1.000
8.100 605.000 1.000
8.200 611.000 1.000
8.300 609.000 1.000
8.400 631.000 1.000
8.500 630.000 1.000
8.600 620.000 1.000
8.700 610.000 1.000
8.800 658.000 1.000
8.900 643.000 1.000
9.000 677.000 1.000
9.100 663.000 1.000
9.200 672.000 1.000
9.300 664.000 1.000
9.400 681.000 1.000
9.500 694.000 1.000
9.600 682.000 1.000
9.700 728.000 1.000
9.800 691.000 1.000
9.900 712.000 1.000
10.000 687.000 1.000
10.100 713.000 1.000
10.200 756.000 1.000
10.300 733.000 1.000
10.400 689.000 1.000
10.500 746.000 1.000
10.600 754.000 1.000
10.700 754.000 1.000
10.800 751.000 1.000
10.900 773.000 1.000
11.000 754.000 1.000
11.100 754.000 1.000
11.200 775.000 1.000
11.300 771.000 1.000
11.400 740.000 1.000
11.500 757.000 1.000
11.600 735.000 1.000
11.700 746.000 1.000
11.800 761.000 1.000
11.900 776.000 1.000
12.000 770.000 1.000
12.100 738.000 1.000
12.200 762.000 1.000
12.300 746.000 1.000
12.400 765.000 1.000
12.500 702.000 1.000
12.600 743.000 1.000
12.700 731.000 1.000
12.800 734.000 1.000
12.900 726.000 1.000
13.000 740.000 1.000
13.100 730.000 1.000
13.200 713.000 1.000
13.300 721.000 1.000
13.400 746.000 1.000
13.500 708.000 1.000
13.600 706.000 1.000
13.700 686.000 1.000
13.800 714.000 1.000
13.900 685.000 1.000
14.000 699.000 1.000
14.100 658.000 1.000
14.200 675.000 1.000
14.300 674.000 1.000
14.400 705.000 1.000
14.500 684.000 1.000
14.600 642.000 1.000
14.700 655.000 1.000
14.800 638.000 1.000
14.900 633.000 1.000
15.000 663.000 1.000
15.100 649.000 1.000
15.200 601.000 1.000
15.300 620.000 1.000
15.400 613.000 1.000
15.500 608.000 1.000
15.600 641.000 1.000
15.700 622.000 1.000
15.800 575.000 1.000
15.900 587.000 1.000
16.000 582.000 1.000
16.100 602.000 1.000
16.200 573.000 1.000
16.300 587.000 1.000
16.400 532.000 1.000
16.500 561.000 1.000
16.600 524.000 1.000
16.700 554.000 1.000
16.800 554.000 1.000
16.900 523.000 1.000
17.000 520.000 1.000
17.100 526.000 1.000
17.200 536.000 1.000
17.300 508.000 1.000
17.400 513.000 1.000
17.500 521.000 1.000
17.600 541.000 1.000
17.700 514.000 1.000
17.800 522.000 1.000
17.900 476.000 1.000
18.000 478.000 1.000
18.100 489.000 1.000
18.200 489.000 1.000
18.300 466.000 1.000
18.400 515.000 1.000
18.500 461.000 1.000
18.600 449.000 1.000
18.700 476.000 1.000
18.800 491.000 1.000
18.900 458.000 1.000
19.000 470.000 1.000
19.100 461.000 1.000
19.200 433.000 1.000
19.300 472.000 1.000
19.400 445.000 1.000
19.500 427.000 1.000
19.600 436.000 1.000
19.700 444.000 1.000
19.800 431.000 1.000
19.900 419.000 1.000
20.000 417.000 1.000
20.100 425.000 1.000
20.200 418.000 1.000
20.300 434.000 1.000
20.400 412.000 1.000
20.500 421.000 1.000
20.600 424.000 1.000
20.700 399.000 1.000
20.800 407.000 1.000
20.900 410.000 1.000
21.000 389.000 1.000
21.100 393.000 1.000
21.200 379.000 1.000
21.300 388.000 1.000
21.400 399.000 1.000
21.500 401.000 1.000
21.600 416.000 1.000
21.700 380.000 1.000
21.800 391.000 1.000
21.900 373.000 1.000
22.000 393.000 1.000
22.100 388.000 1.000
22.200 374.000 1.000
22.300 368.000 1.000
22.400 366.000 1.000
22.500 347.000 1.000
22.600 336.000 1.000
22.700 352.000 1.000
22.800 347.000 1.000
22.900 341.000 1.000
23.000 332.000 1.000
23.100 323.000 1.000
23.200 316.000 1.000
23.300 356.000 1.000
23.400 322.000 1.000
23.500 322.000 1.000
23.600 352.000 1.000
23.700 326.000 1.000
23.800 354.000 1.000
23.900 329.000 1.000
24.000 339.000 1.000
24.100 348.000 1.000
24.200 311.000 1.000
24.300 316.000 1.000
24.400 312.000 1.000
24.500 318.000 1.000
24.600 312.000 1.000
24.700 309.000 1.000
24.800 322.000 1.000
24.900 303.000 1.000
25.000 317.000 1.000
25.100 291.000 1.000
25.200 304.000 1.000
25.300 294.000 1.000
25.400 312.000 1.000
25.500 286.000 1.000
25.600 301.000 1.000
25.700 294.000 1.000
25.800 306.000 1.000
25.900 305.000 1.000
26.000 299.000 1.000
26.100 273.000 1.000
26.200 293.000 1.000
26.300 338.000 1.000
26.400 307.000 1.000
26.500 284.000 1.000
26.600 306.000 1.000
26.700 279.000 1.000
26.800 286.000 1.000
26.900 302.000 1.000
27.000 303.000 1.000
27.100 285.000 1.000
27.200 281.000 1.000
27.300 270.000 1.000
27.400 273.000 1.000
27.500 285.000 1.000
27.600 282.000 1.000
27.700 293.000 1.000
27.800 265.000 1.000
27.900 281.000 1.000
28.000 281.000 1.000
28.100 282.000 1.000
28.200 280.000 1.000
28.300 262.000 1.000
28.400 279.000 1.000
28.500 274.000 1.000
28.600 260.000 1.000
28.700 270.000 1.000
28.800 254.000 1.000
28.900 262.000 1.000
29.000 275.000 1.000
29.100 244.000 1.000
29.200 250.000 1.000
29.300 263.000 1.000
29.400 269.000 1.000
29.500 263.000 1.000
29.600 246.000 1.000
29.700 274.000 1.000
29.800 241.000 1.000
29.900 239.000 1.000
30.000 256.000 1.000
30.100 273.000 1.000
30.200 240.000 1.000
30.300 252.000 1.000
30.400 268.000 1.000
30.500 250.000 1.000
30.600 234.000 1.000
30.700 245.000 1.000
30.800 263.000 1.000
30.900 267.000 1.000
31.000 272.000 1.000
31.100 250.000 1.000
31.200 272.000 1.000
31.300 250.000 1.000
31.400 246.000 1.000
31.500 246.000 1.000
31.600 249.000 1.000
31.700 240.000 1.000
31.800 245.000 1.000
31.900 266.000 1.000
32.000 246.000 1.000
32.100 257.000 1.000
32.200 241.000 1.000
32.300 251.000 1.000
32.400 258.000 1.000
32.500 241.000 1.000
32.600 252.000 1.000
32.700 244.000 1.000
32.800 246.000 1.000
32.900 256.000 1.000
33.000 266.000 1.000
33.100 240.000 1.000
33.200 278.000 1.000
33.300 242.000 1.000
33.400 252.000 1.000
33.500 251.000 1.000
33.600 247.000 1.000
33.700 257.000 1.000
33.800 274.000 1.000
33.900 282.000 1.000
34.000 300.000 1.000
34.100 301.000 1.000
34.200 257.000 1.000
34.300 257.000 1.000
34.400 259.000 1.000
34.500 263.000 1.000
34.600 262.000 1.000
34.700 292.000 1.000
34.800 265.000 1.000
34.900 257.000 1.000
35.000 273.000 1.000
35.100 281.000 1.000
35.200 286.000 1.000
35.300 286.000 1.000
35.400 278.000 1.000
35.500 278.000 1.000
35.600 280.000 1.000
35.700 288.000 1.000
35.800 291.000 1.000
35.900 284.000 1.000
36.000 313.000 1.000
36.100 330.000 1.000
36.200 325.000 1.000
36.300 336.000 1.000
36.400 369.000 1.000
36.500 562.000 1.000
36.600 798.000 1.000
36.700 808.000 1.000
36.800 850.000 1.000
36.900 835.000 1.000
37.000 854.000 1.000
37.100 905.000 1.000
37.200 994.000 1.000
37.300 1307.000 1.000
37.400 1953.000 1.000
37.500 2412.000 1.000
37.600 3725.000 1.000
37.700 10720.000 1.000
37.800 63061.000 1.000
37.900 102253.000 1.000
38.000 41042.000 1.000
38.100 5642.000 1.000
38.200 2788.000 1.000
38.300 1621.000 1.000
38.400 1107.000 1.000
38.500 856.000 1.000
38.600 712.000 1.000
38.700 632.000 1.000
38.800 585.000 1.000
38.900 567.000 1.000
39.000 563.000 1.000
39.100 516.000 1.000
39.200 475.000 1.000
39.300 477.000 1.000
39.400 466.000 1.000
39.500 461.000 1.000
39.600 483.000 1.000
39.700 484.000 1.000
39.800 466.000 1.000
39.900 432.000 1.000
40.000 396.000 1.000
40.100 358.000 1.000
40.200 343.000 1.000
40.300 354.000 1.000
40.400 364.000 1.000
40.500 341.000 1.000
40.600 321.000 1.000
40.700 328.000 1.000
40.800 339.000 1.000
40.900 333.000 1.000
41.000 326.000 1.000
41.100 301.000 1.000
41.200 297.000 1.000
41.300 283.000 1.000
41.400 285.000 1.000
41.500 282.000 1.000
41.600 275.000 1.000
41.700 280.000 1.000
41.800 272.000 1.000
41.900 298.000 1.000
42.000 294.000 1.000
42.100 273.000 1.000
42.200 245.000 1.000
42.300 277.000 1.000
42.400 289.000 1.000
42.500 396.000 1.000
42.600 378.000 1.000
42.700 408.000 1.000
42.800 401.000 1.000
42.900 430.000 1.000
43.000 442.000 1.000
43.100 452.000 1.000
43.200 480.000 1.000
43.300 449.000 1.000
43.400 472.000 1.000
43.500 600.000 1.000
43.600 850.000 1.000
43.700 1096.000 1.000
43.800 1733.000 1.000
43.900 3805.000 1.000
44.000 19359.000 1.000
44.100 32662.000 1.000
44.200 19817.000 1.000
44.300 3064.000 1.000
44.400 1487.000 1.000
44.500 920.000 1.000
44.600 653.000 1.000
44.700 489.000 1.000
44.800 410.000 1.000
44.900 364.000 1.000
45.000 332.000 1.000
45.100 331.000 1.000
45.200 316.000 1.000
45.300 282.000 1.000
45.400 256.000 1.000
45.500 276.000 1.000
45.600 257.000 1.000
45.700 256.000 1.000
45.800 266.000 1.000
45.900 253.000 1.000
46.000 242.000 1.000
46.100 238.000 1.000
46.200 233.000 1.000
46.300 208.000 1.000
46.400 214.000 1.000
46.500 236.000 1.000
46.600 205.000 1.000
46.700 212.000 1.000
46.800 204.000 1.000
46.900 198.000 1.000
47.000 196.000 1.000
47.100 206.000 1.000
47.200 199.000 1.000
47.300 206.000 1.000
47.400 182.000 1.000
47.500 182.000 1.000
47.600 184.000 1.000
47.700 177.000 1.000
47.800 186.000 1.000
47.900 168.000 1.000
48.000 185.000 1.000
48.100 182.000 1.000
48.200 174.000 1.000
48.300 159.000 1.000
48.400 179.000 1.000
48.500 163.000 1.000
48.600 165.000 1.000
48.700 172.000 1.000
48.800 160.000 1.000
48.900 171.000 1.000
49.000 147.000 1.000
49.100 153.000 1.000
49.200 146.000 1.000
49.300 161.000 1.000
49.400 168.000 1.000
49.500 168.000 1.000
49.600 151.000 1.000
49.700 155.000 1.000
49.800 149.000 1.000
49.900 146.000 1.000
50.000 137.000 1.000
50.100 144.000 1.000
50.200 139.000 1.000
50.300 163.000 1.000
50.400 143.000 1.000
50.500 148.000 1.000
50.600 143.000 1.000
50.700 127.000 1.000
50.800 143.000 1.000
50.900 142.000 1.000
51.000 129.000 1.000
51.100 133.000 1.000
51.200 136.000 1.000
51.300 144.000 1.000
51.400 133.000 1.000
51.500 147.000 1.000
51.600 132.000 1.000
51.700 139.000 1.000
51.800 119.000 1.000
51.900 135.000 1.000
52.000 137.000 1.000
52.100 119.000 1.000
52.200 131.000 1.000
52.300 127.000 1.000
52.400 127.000 1.000
52.500 136.000 1.000
52.600 124.000 1.000
52.700 130.000 1.000
52.800 150.000 1.000
52.900 138.000 1.000
53.000 133.000 1.000
53.100 133.000 1.000
53.200 129.000 1.000
53.300 122.000 1.000
53.400 128.000 1.000
53.500 124.000 1.000
53.600 136.000 1.000
53.700 123.000 1.000
53.800 128.000 1.000
53.900 130.000 1.000
54.000 126.000 1.000
54.100 139.000 1.000
54.200 123.000 1.000
54.300 126.000 1.000
54.400 128.000 1.000
54.500 124.000 1.000
54.600 133.000 1.000
54.700 128.000 1.000
54.800 127.000 1.000
54.900 125.000 1.000
55.000 126.000 1.000
55.100 122.000 1.000
55.200 129.000 1.000
55.300 118.000 1.000
55.400 105.000 1.000
55.500 113.000 1.000
55.600 128.000 1.000
55.700 122.000 1.000
55.800 120.000 1.000
55.900 128.000 1.000
56.000 112.000 1.000
56.100 120.000 1.000
56.200 122.000 1.000
56.300 114.000 1.000
56.400 117.000 1.000
56.500 100.000 1.000
56.600 110.000 1.000
56.700 122.000 1.000
56.800 120.000 1.000
56.900 112.000 1.000
57.000 115.000 1.000
57.100 117.000 1.000
57.200 125.000 1.000
57.300 112.000 1.000
57.400 125.000 1.000
57.500 112.000 1.000
57.600 130.000 1.000
57.700 130.000 1.000
57.800 119.000 1.000
57.900 121.000 1.000
58.000 119.000 1.000
58.100 102.000 1.000
58.200 105.000 1.000
58.300 110.000 1.000
58.400 110.000 1.000
58.500 110.000 1.000
58.600 118.000 1.000
58.700 115.000 1.000
58.800 106.000 1.000
58.900 119.000 1.000
59.000 116.000 1.000
59.100 121.000 1.000
59.200 121.000 1.000
59.300 125.000 1.000
59.400 102.000 1.000
59.500 108.000 1.000
59.600 111.000 1.000
59.700 121.000 1.000
59.800 104.000 1.000
59.900 122.000 1.000
60.000 111.000 1.000
60.100 128.000 1.000
60.200 122.000 1.000
60.300 101.000 1.000
60.400 123.000 1.000
60.500 101.000 1.000
60.600 119.000 1.000
60.700 106.000 1.000
60.800 134.000 1.000
60.900 108.000 1.000
61.000 111.000 1.000
61.100 121.000 1.000
61.200 117.000 1.000
61.300 115.000 1.000
61.400 124.000 1.000
61.500 114.000 1.000
61.600 122.000 1.000
61.700 125.000 1.000
61.800 124.000 1.000
61.900 121.000 1.000
62.000 129.000 1.000
62.100 132.000 1.000
62.200 118.000 1.000
62.300 144.000 1.000
62.400 142.000 1.000
62.500 137.000 1.000
62.600 132.000 1.000
62.700 124.000 1.000
62.800 122.000 1.000
62.900 127.000 1.000
63.000 134.000 1.000
63.100 136.000 1.000
63.200 127.000 1.000
63.300 139.000 1.000
63.400 144.000 1.000
63.500 134.000 1.000
63.600 143.000 1.000
63.700 146.000 1.000
63.800 183.000 1.000
63.900 221.000 1.000
64.000 251.000 1.000
64.100 339.000 1.000
64.200 844.000 1.000
64.300 3882.000 1.000
64.400 1469.000 1.000
64.500 2154.000 1.000
64.600 534.000 1.000
64.700 260.000 1.000
64.800 187.000 1.000
64.900 158.000 1.000
65.000 150.000 1.000
65.100 149.000 1.000
65.200 139.000 1.000
65.300 130.000 1.000
65.400 142.000 1.000
65.500 119.000 1.000
65.600 126.000 1.000
65.700 118.000 1.000
65.800 130.000 1.000
65.900 131.000 1.000
66.000 120.000 1.000
66.100 120.000 1.000
66.200 118.000 1.000
66.300 117.000 1.000
66.400 124.000 1.000
66.500 133.000 1.000
66.600 123.000 1.000
66.700 128.000 1.000
66.800 125.000 1.000
66.900 124.000 1.000
67.000 127.000 1.000
67.100 142.000 1.000
67.200 123.000 1.000
67.300 117.000 1.000
67.400 128.000 1.000
67.500 121.000 1.000
67.600 118.000 1.000
67.700 108.000 1.000
67.800 118.000 1.000
67.900 130.000 1.000
68.000 123.000 1.000
68.100 107.000 1.000
68.200 107.000 1.000
68.300 134.000 1.000
68.400 109.000 1.000
68.500 131.000 1.000
68.600 127.000 1.000
68.700 131.000 1.000
68.800 119.000 1.000
68.900 119.000 1.000
69.000 121.000 1.000
69.100 128.000 1.000
69.200 124.000 1.000
69.300 124.000 1.000
69.400 114.000 1.000
69.500 124.000 1.000
69.600 140.000 1.000
69.700 124.000 1.000
69.800 128.000 1.000
69.900 114.000 1.000
70.000 116.000 1.000
70.100 126.000 1.000
70.200 129.000 1.000
70.300 126.000 1.000
70.400 132.000 1.000
70.500 133.000 1.000
70.600 124.000 1.000
70.700 118.000 1.000
70.800 115.000 1.000
70.900 125.000 1.000
71.000 132.000 1.000
71.100 127.000 1.000
71.200 122.000 1.000
71.300 142.000 1.000
71.400 128.000 1.000
71.500 129.000 1.000
71.600 140.000 1.000
71.700 138.000 1.000
71.800 133.000 1.000
71.900 113.000 1.000
72.000 138.000 1.000
72.100 125.000 1.000
72.200 140.000 1.000
72.300 149.000 1.000
72.400 126.000 1.000
72.500 136.000 1.000
72.600 126.000 1.000
72.700 141.000 1.000
72.800 118.000 1.000
72.900 137.000 1.000
73.000 153.000 1.000
73.100 121.000 1.000
73.200 119.000 1.000
73.300 124.000 1.000
73.400 133.000 1.000
73.500 126.000 1.000
73.600 149.000 1.000
73.700 144.000 1.000
73.800 135.000 1.000
73.900 148.000 1.000
74.000 144.000 1.000
74.100 148.000 1.000
74.200 149.000 1.000
74.300 156.000 1.000
74.400 183.000 1.000
74.500 179.000 1.000
74.600 180.000 1.000
74.700 171.000 1.000
74.800 179.000 1.000
74.900 184.000 1.000
75.000 185.000 1.000
75.100 178.000 1.000
75.200 164.000 1.000
75.300 191.000 1.000
75.400 161.000 1.000
75.500 188.000 1.000
75.600 177.000 1.000
75.700 195.000 1.000
75.800 186.000 1.000
75.900 188.000 1.000
76.000 193.000 1.000
76.100 205.000 1.000
76.200 187.000 1.000
76.300 219.000 1.000
76.400 209.000 1.000
76.500 210.000 1.000
76.600 235.000 1.000
76.700 285.000 1.000
76.800 343.000 1.000
76.900 483.000 1.000
77.000 661.000 1.000
77.100 999.000 1.000
77.200 2324.000 1.000
77.300 8551.000 1.000
77.400 8035.000 1.000
77.500 4000.000 1.000
77.600 5802.000 1.000
77.700 1358.000 1.000
77.800 618.000 1.000
77.900 414.000 1.000
78.000 320.000 1.000
78.100 278.000 1.000
78.200 254.000 1.000
78.300 241.000 1.000
78.400 230.000 1.000
78.500 219.000 1.000
78.600 199.000 1.000
78.700 209.000 1.000
78.800 218.000 1.000
78.900 196.000 1.000
79.000 216.000 1.000
79.100 204.000 1.000
79.200 215.000 1.000
79.300 171.000 1.000
79.400 194.000 1.000
79.500 191.000 1.000
79.600 195.000 1.000
79.700 202.000 1.000
79.800 176.000 1.000
79.900 182.000 1.000
80.000 188.000 1.000
80.100 188.000 1.000
80.200 180.000 1.000
80.300 192.000 1.000
80.400 186.000 1.000
80.500 192.000 1.000
80.600 194.000 1.000
80.700 196.000 1.000
80.800 215.000 1.000
80.900 231.000 1.000
81.000 302.000 1.000
81.100 361.000 1.000
81.200 455.000 1.000
81.300 766.000 1.000
81.400 1967.000 1.000
81.500 6609.000 1.000
81.600 3348.000 1.000
81.700 2392.000 1.000
81.800 3424.000 1.000
81.900 865.000 1.000
82.000 421.000 1.000
82.100 302.000 1.000
82.200 243.000 1.000
82.300 213.000 1.000
82.400 198.000 1.000
82.500 189.000 1.000
82.600 183.000 1.000
82.700 168.000 1.000
82.800 163.000 1.000
82.900 151.000 1.000
83.000 163.000 1.000
83.100 153.000 1.000
83.200 157.000 1.000
83.300 159.000 1.000
83.400 142.000 1.000
83.500 149.000 1.000
83.600 139.000 1.000
83.700 138.000 1.000
83.800 142.000 1.000
83.900 136.000 1.000
84.000 153.000 1.000
84.100 146.000 1.000
84.200 149.000 1.000
84.300 141.000 1.000
84.400 129.000 1.000
84.500 137.000 1.000
84.600 134.000 1.000
84.700 146.000 1.000
84.800 143.000 1.000
84.900 120.000 1.000
85.000 136.000 1.000
85.100 126.000 1.000
85.200 113.000 1.000
85.300 131.000 1.000
85.400 129.000 1.000
85.500 127.000 1.000
85.600 125.000 1.000
85.700 116.000 1.000
85.800 131.000 1.000
85.900 119.000 1.000
86.000 125.000 1.000
86.100 134.000 1.000
86.200 128.000 1.000
86.300 120.000 1.000
86.400 120.000 1.000
86.500 134.000 1.000
86.600 136.000 1.000
86.700 127.000 1.000
86.800 130.000 1.000
86.900 132.000 1.000
87.000 128.000 1.000
87.100 123.000 1.000
87.200 115.000 1.000
87.300 125.000 1.000
87.400 117.000 1.000
87.500 107.000 1.000
87.600 110.000 1.000
87.700 115.000 1.000
87.800 108.000 1.000
87.900 106.000 1.000
88.000 114.000 1.000
88.100 107.000 1.000
88.200 115.000 1.000
88.300 117.000 1.000
88.400 123.000 1.000
88.500 114.000 1.000
88.600 101.000 1.000
88.700 105.000 1.000
88.800 110.000 1.000
88.900 115.000 1.000
89.000 98.000 1.000
89.100 113.000 1.000
89.200 108.000 1.000
89.300 126.000 1.000
89.400 106.000 1.000
89.500 114.000 1.000
89.600 114.000 1.000
89.700 115.000 1.000
89.800 113.000 1.000
89.900 100.000 1.000
90.000 120.000 1.000
90.100 117.000 1.000
90.200 111.000 1.000
90.300 90.000 1.000
90.400 100.000 1.000
90.500 102.000 1.000
90.600 98.000 1.000
90.700 101.000 1.000
90.800 115.000 1.000
90.900 102.000 1.000
91.000 95.000 1.000
91.100 107.000 1.000
91.200 114.000 1.000
91.300 100.000 1.000
91.400 103.000 1.000
91.500 110.000 1.000
91.600 109.000 1.000
91.700 100.000 1.000
91.800 120.000 1.000
91.900 101.000 1.000
92.000 107.000 1.000
92.100 102.000 1.000
92.200 94.000 1.000
92.300 110.000 1.000
92.400 95.000 1.000
92.500 111.000 1.000
92.600 111.000 1.000
92.700 111.000 1.000
92.800 95.000 1.000
92.900 103.000 1.000
93.000 103.000 1.000
93.100 116.000 1.000
93.200 103.000 1.000
93.300 116.000 1.000
93.400 100.000 1.000
93.500 111.000 1.000
93.600 102.000 1.000
93.700 106.000 1.000
93.800 107.000 1.000
93.900 99.000 1.000
94.000 108.000 1.000
94.100 106.000 1.000
94.200 98.000 1.000
94.300 117.000 1.000
94.400 95.000 1.000
94.500 104.000 1.000
94.600 99.000 1.000
94.700 112.000 1.000
94.800 98.000 1.000
94.900 112.000 1.000
95.000 117.000 1.000
95.100 111.000 1.000
95.200 98.000 1.000
95.300 89.000 1.000
95.400 95.000 1.000
95.500 107.000 1.000
95.600 97.000 1.000
95.700 106.000 1.000
95.800 109.000 1.000
95.900 104.000 1.000
96.000 104.000 1.000
96.100 125.000 1.000
96.200 98.000 1.000
96.300 112.000 1.000
96.400 112.000 1.000
96.500 101.000 1.000
96.600 119.000 1.000
96.700 115.000 1.000
96.800 98.000 1.000
96.900 129.000 1.000
97.000 112.000 1.000
97.100 124.000 1.000
97.200 129.000 1.000
97.300 128.000 1.000
97.400 159.000 1.000
97.500 180.000 1.000
97.600 203.000 1.000
97.700 245.000 1.000
97.800 446.000 1.000
97.900 984.000 1.000
98.000 1934.000 1.000
98.100 790.000 1.000
98.200 516.000 1.000
98.300 904.000 1.000
98.400 645.000 1.000
98.500 226.000 1.000
98.600 171.000 1.000
98.700 151.000 1.000
98.800 126.000 1.000
98.900 116.000 1.000
99.000 118.000 1.000
99.100 115.000 1.000
99.200 114.000 1.000
99.300 105.000 1.000
99.400 122.000 1.000
99.500 104.000 1.000
99.600 107.000 1.000
99.700 119.000 1.000
99.800 118.000 1.000
99.900 108.000 1.000
100.000 100.000 1.000
100.100 108.000 1.000
100.200 104.000 1.000
100.300 98.000 1.000
100.400 91.000 1.000
100.500 90.000 1.000
100.600 109.000 1.000
100.700 113.000 1.000
100.800 102.000 1.000
100.900 106.000 1.000
101.000 113.000 1.000
101.100 102.000 1.000
101.200 119.000 1.000
101.300 100.000 1.000
101.400 101.000 1.000
101.500 106.000 1.000
101.600 101.000 1.000
101.700 100.000 1.000
101.800 107.000 1.000
101.900 104.000 1.000
102.000 99.000 1.000
102.100 105.000 1.000
102.200 111.000 1.000
102.300 87.000 1.000
102.400 109.000 1.000
102.500 102.000 1.000
102.600 95.000 1.000
102.700 95.000 1.000
102.800 110.000 1.000
102.900 111.000 1.000
103.000 105.000 1.000
103.100 99.000 1.000
103.200 104.000 1.000
103.300 95.000 1.000
103.400 97.000 1.000
103.500 96.000 1.000
103.600 93.000 1.000
103.700 117.000 1.000
103.800 110.000 1.000
103.900 106.000 1.000
104.000 121.000 1.000
104.100 92.000 1.000
104.200 98.000 1.000
104.300 112.000 1.000
104.400 107.000 1.000
104.500 110.000 1.000
104.600 97.000 1.000
104.700 110.000 1.000
104.800 99.000 1.000
104.900 106.000 1.000
105.000 109.000 1.000
105.100 101.000 1.000
105.200 109.000 1.000
105.300 103.000 1.000
105.400 100.000 1.000
105.500 116.000 1.000
105.600 112.000 1.000
105.700 104.000 1.000
105.800 103.000 1.000
105.900 105.000 1.000
106.000 114.000 1.000
106.100 116.000 1.000
106.200 109.000 1.000
106.300 115.000 1.000
106.400 118.000 1.000
106.500 109.000 1.000
106.600 117.000 1.000
106.700 105.000 1.000
106.800 98.000 1.000
106.900 103.000 1.000
107.000 109.000 1.000
107.100 114.000 1.000
107.200 114.000 1.000
107.300 102.000 1.000
107.400 113.000 1.000
107.500 116.000 1.000
107.600 111.000 1.000
107.700 122.000 1.000
107.800 108.000 1.000
107.900 113.000 1.000
108.000 112.000 1.000
108.100 108.000 1.000
108.200 113.000 1.000
108.300 96.000 1.000
108.400 128.000 1.000
108.500 111.000 1.000
108.600 125.000 1.000
108.700 121.000 1.000
108.800 126.000 1.000
108.900 121.000 1.000
109.000 130.000 1.000
109.100 114.000 1.000
109.200 125.000 1.000
109.300 127.000 1.000
109.400 121.000 1.000
109.500 145.000 1.000
109.600 137.000 1.000
109.700 138.000 1.000
109.800 140.000 1.000
109.900 150.000 1.000
110.000 154.000 1.000
110.100 166.000 1.000
110.200 179.000 1.000
110.300 207.000 1.000
110.400 272.000 1.000
110.500 389.000 1.000
110.600 689.000 1.000
110.700 1331.000 1.000
110.800 1664.000 1.000
110.900 701.000 1.000
111.000 518.000 1.000
111.100 723.000 1.000
111.200 917.000 1.000
111.300 453.000 1.000
111.400 242.000 1.000
111.500 175.000 1.000
111.600 172.000 1.000
111.700 158.000 1.000
111.800 138.000 1.000
111.900 157.000 1.000
112.000 153.000 1.000
112.100 152.000 1.000
112.200 132.000 1.000
112.300 132.000 1.000
112.400 125.000 1.000
112.500 128.000 1.000
112.600 149.000 1.000
112.700 136.000 1.000
112.800 143.000 1.000
112.900 137.000 1.000
113.000 135.000 1.000
113.100 129.000 1.000
113.200 134.000 1.000
113.300 136.000 1.000
113.400 127.000 1.000
113.500 149.000 1.000
113.600 117.000 1.000
113.700 128.000 1.000
113.800 128.000 1.000
113.900 142.000 1.000
114.000 153.000 1.000
114.100 142.000 1.000
114.200 152.000 1.000
114.300 140.000 1.000
114.400 154.000 1.000
114.500 159.000 1.000
114.600 170.000 1.000
114.700 189.000 1.000
114.800 228.000 1.000
114.900 282.000 1.000
115.000 421.000 1.000
115.100 735.000 1.000
115.200 1331.000 1.000
115.300 1284.000 1.000
115.400 577.000 1.000
115.500 449.000 1.000
115.600 610.000 1.000
115.700 847.000 1.000
115.800 495.000 1.000
115.900 261.000 1.000
116.000 215.000 1.000
116.100 179.000 1.000
116.200 154.000 1.000
116.300 157.000 1.000
116.400 143.000 1.000
116.500 151.000 1.000
116.600 142.000 1.000
116.700 131.000 1.000
116.800 141.000 1.000
116.900 134.000 1.000
117.000 133.000 1.000
117.100 130.000 1.000
117.200 137.000 1.000
117.300 141.000 1.000
117.400 140.000 1.000
117.500 119.000 1.000
117.600 131.000 1.000
117.700 135.000 1.000
117.800 126.000 1.000
117.900 132.000 1.000
118.000 129.000 1.000
118.100 132.000 1.000
118.200 131.000 1.000
118.300 145.000 1.000
118.400 137.000 1.000
118.500 129.000 1.000
118.600 131.000 1.000
118.700 130.000 1.000
118.800 126.000 1.000
118.900 127.000 1.000
119.000 123.000 1.000
119.100 126.000 1.000
119.200 131.000 1.000
119.300 130.000 1.000
119.400 130.000 1.000
119.500 122.000 1.000
119.600 142.000 1.000
119.700 126.000 1.000
119.800 122.000 1.000
119.900 132.000 1.000
120.000 131.000 1.000
120.100 138.000 1.000
120.200 139.000 1.000
120.300 125.000 1.000
120.400 137.000 1.000
120.500 140.000 1.000
120.600 127.000 1.000
120.700 137.000 1.000
120.800 133.000 1.000
120.900 141.000 1.000
121.000 130.000 1.000
121.100 131.000 1.000
121.200 133.000 1.000
121.300 134.000 1.000
121.400 135.000 1.000
121.500 135.000 1.000
121.600 135.000 1.000
121.700 140.000 1.000
121.800 139.000 1.000
121.900 136.000 1.000
122.000 138.000 1.000
122.100 131.000 1.000
122.200 132.000 1.000
122.300 134.000 1.000
122.400 133.000 1.000
122.500 142.000 1.000
122.600 112.000 1.000
122.700 138.000 1.000
122.800 132.000 1.000
122.900 128.000 1.000
123.000 139.000 1.000
123.100 126.000 1.000
123.200 131.000 1.000
123.300 141.000 1.000
123.400 139.000 1.000
123.500 136.000 1.000
123.600 132.000 1.000
123.700 136.000 1.000
123.800 145.000 1.000
123.900 129.000 1.000
124.000 138.000 1.000
124.100 118.000 1.000
124.200 120.000 1.000
124.300 127.000 1.000
124.400 123.000 1.000
124.500 125.000 1.000
124.600 132.000 1.000
124.700 135.000 1.000
124.800 123.000 1.000
124.900 149.000 1.000
125.000 145.000 1.000
125.100 120.000 1.000
125.200 135.000 1.000
125.300 135.000 1.000
125.400 135.000 1.000
125.500 140.000 1.000
125.600 130.000 1.000
125.700 139.000 1.000
125.800 136.000 1.000
125.900 133.000 1.000
126.000 145.000 1.000
126.100 118.000 1.000
126.200 132.000 1.000
126.300 124.000 1.000
126.400 141.000 1.000
126.500 135.000 1.000
126.600 131.000 1.000
126.700 132.000 1.000
126.800 143.000 1.000
126.900 150.000 1.000
127.000 150.000 1.000
127.100 136.000 1.000
127.200 137.000 1.000
127.300 145.000 1.000
127.400 145.000 1.000
127.500 148.000 1.000
127.600 146.000 1.000
127.700 153.000 1.000
127.800 144.000 1.000
127.900 152.000 1.000
128.000 143.000 1.000
128.100 133.000 1.000
128.200 143.000 1.000
128.300 147.000 1.000
128.400 152.000 1.000
128.500 155.000 1.000
128.600 130.000 1.000
128.700 147.000 1.000
128.800 135.000 1.000
128.900 161.000 1.000
129.000 157.000 1.000
129.100 144.000 1.000
129.200 155.000 1.000
129.300 152.000 1.000
129.400 150.000 1.000
129.500 154.000 1.000
129.600 164.000 1.000
129.700 147.000 1.000
129.800 159.000 1.000
129.900 151.000 1.000
130.000 164.000 1.000
130.100 151.000 1.000
130.200 152.000 1.000
130.300 161.000 1.000
130.400 164.000 1.000
130.500 170.000 1.000
130.600 153.000 1.000
130.700 153.000 1.000
130.800 158.000 1.000
130.900 156.000 1.000
131.000 158.000 1.000
131.100 145.000 1.000
131.200 154.000 1.000
131.300 168.000 1.000
131.400 175.000 1.000
131.500 165.000 1.000
131.600 154.000 1.000
131.700 148.000 1.000
131.800 163.000 1.000
131.900 184.000 1.000
132.000 163.000 1.000
132.100 165.000 1.000
132.200 158.000 1.000
132.300 171.000 1.000
132.400 173.000 1.000
132.500 156.000 1.000
132.600 164.000 1.000
132.700 167.000 1.000
132.800 180.000 1.000
132.900 170.000 1.000
133.000 156.000 1.000
133.100 180.000 1.000
133.200 175.000 1.000
133.300 177.000 1.000
133.400 168.000 1.000
133.500 185.000 1.000
133.600 173.000 1.000
133.700 191.000 1.000
133.800 186.000 1.000
133.900 204.000 1.000
134.000 196.000 1.000
134.100 228.000 1.000
134.200 216.000 1.000
134.300 236.000 1.000
134.400 236.000 1.000
134.500 245.000 1.000
134.600 247.000 1.000
134.700 269.000 1.000
134.800 313.000 1.000
134.900 351.000 1.000
135.000 451.000 1.000
135.100 593.000 1.000
135.200 844.000 1.000
135.300 1215.000 1.000
135.400 1849.000 1.000
135.500 2858.000 1.000
135.600 3485.000 1.000
135.700 1934.000 1.000
135.800 1046.000 1.000
135.900 859.000 1.000
136.000 866.000 1.000
136.100 1097.000 1.000
136.200 1424.000 1.000
136.300 1750.000 1.000
136.400 1145.000 1.000
136.500 628.000 1.000
136.600 445.000 1.000
136.700 327.000 1.000
136.800 280.000 1.000
136.900 258.000 1.000
137.000 216.000 1.000
137.100 214.000 1.000
137.200 232.000 1.000
137.300 212.000 1.000
137.400 209.000 1.000
137.500 193.000 1.000
137.600 216.000 1.000
137.700 190.000 1.000
137.800 190.000 1.000
137.900 191.000 1.000
138.000 188.000 1.000
138.100 196.000 1.000
138.200 188.000 1.000
138.300 185.000 1.000
138.400 190.000 1.000
138.500 181.000 1.000
138.600 181.000 1.000
138.700 178.000 1.000
138.800 184.000 1.000
138.900 195.000 1.000
139.000 183.000 1.000
139.100 176.000 1.000
139.200 208.000 1.000
139.300 185.000 1.000
139.400 178.000 1.000
139.500 172.000 1.000
139.600 176.000 1.000
139.700 176.000 1.000
139.800 181.000 1.000
139.900 184.000 1.000
140.000 172.000 1.000
*RAS_INT_END
*RAS_DATA_END