File: Parafilm_Si.ras
*RAS_DATA_START
*RAS_HEADER_START
*CORR_POS_DB_NAME "AngleCorr_NIST640d_DteX_2022.02.28"
*CORR_POS_GONIO_RADIUS ""
*CORR_POS_NODE_INDEX01 ""
*CORR_POS_NODE_INDEX02 ""
*CORR_POS_NODE_INDEX03 ""
*CORR_POS_NODE_INDEX04 ""
*CORR_POS_NODE_INDEX05 ""
*CORR_POS_NODE_INDEX06 ""
*CORR_POS_NODE_INDEX07 ""
*CORR_POS_NODE_INDEX08 ""
*CORR_POS_NODE_INDEX09 ""
*CORR_POS_NODE_INDEX10 ""
*CORR_POS_NODE_INDEX11 ""
*CORR_POS_NODE_LABEL01 "Si(111)"
*CORR_POS_NODE_LABEL02 "Si(220)"
*CORR_POS_NODE_LABEL03 "Si(311)"
*CORR_POS_NODE_LABEL04 "Si(400)"
*CORR_POS_NODE_LABEL05 "Si(331)"
*CORR_POS_NODE_LABEL06 "Si(422)"
*CORR_POS_NODE_LABEL07 "Si(511)"
*CORR_POS_NODE_LABEL08 "Si(440)"
*CORR_POS_NODE_LABEL09 "Si(531)"
*CORR_POS_NODE_LABEL10 "Si(620)"
*CORR_POS_NODE_LABEL11 "Si(533)"
*CORR_POS_NODE_POS_CALC01 "28.4137"
*CORR_POS_NODE_POS_CALC02 "47.2707"
*CORR_POS_NODE_POS_CALC03 "56.0883"
*CORR_POS_NODE_POS_CALC04 "69.0934"
*CORR_POS_NODE_POS_CALC05 "76.3385"
*CORR_POS_NODE_POS_CALC06 "87.9915"
*CORR_POS_NODE_POS_CALC07 "94.9137"
*CORR_POS_NODE_POS_CALC08 "106.67"
*CORR_POS_NODE_POS_CALC09 "114.054"
*CORR_POS_NODE_POS_CALC10 "127.508"
*CORR_POS_NODE_POS_CALC11 "136.858"
*CORR_POS_NODE_POS_MEAS01 "28.3905"
*CORR_POS_NODE_POS_MEAS02 "47.2504"
*CORR_POS_NODE_POS_MEAS03 "56.0712"
*CORR_POS_NODE_POS_MEAS04 "69.0788"
*CORR_POS_NODE_POS_MEAS05 "76.3323"
*CORR_POS_NODE_POS_MEAS06 "87.9869"
*CORR_POS_NODE_POS_MEAS07 "94.9135"
*CORR_POS_NODE_POS_MEAS08 "106.672"
*CORR_POS_NODE_POS_MEAS09 "114.061"
*CORR_POS_NODE_POS_MEAS10 "127.517"
*CORR_POS_NODE_POS_MEAS11 "136.874"
*CORR_POS_OPT_ATTR "集中法"
*CORR_POS_PARAM_MU ""
*CORR_POS_PARAM_PL ""
*CORR_POS_SEMODEL_TYPE "0"
*CORR_POS_STANDARD_TYPE ""
*CORR_POS_VALUE_ANALYZER "None"
*CORR_POS_VALUE_CMONO "None"
*CORR_POS_VALUE_IMONO "None"
*CORR_POS_VALUE_IS "0.625deg"
*CORR_POS_VALUE_ISL "10.0mm"
*CORR_POS_VALUE_ISOLLER "2.5deg"
*CORR_POS_VALUE_RS1 "13.0mm"
*CORR_POS_VALUE_RS2 "13.0mm"
*CORR_POS_VALUE_RSOLLER "2.5deg"
*CORR_POS_XG_FOCUS_L ""
*CORR_POS_XG_WAVE_TYPE ""
*CORR_POS_XG_WAVE_VALUE ""
*DISP_FMT_X "%.2f"
*DISP_FMT_Y "%.0f"
*DISP_FULLSCALE "563728.0000000000"
*DISP_LINE_COLOR "255.0000000000"
*DISP_LINE_STYLE "0.0000000000"
*DISP_LINE_WIDTH "0.2500000000"
*DISP_NOTE "Collected Data-6"
*DISP_OFFSET_Y "0.0000000000"
*DISP_PEAKSEARCH_UNIT_Y "cps"
*DISP_RANGE_BOTTOM "0.0000000000"
*DISP_RANGE_LEFT "2.0000000000"
*DISP_RANGE_LOGCUTOFF "0.0100000000"
*DISP_RANGE_RIGHT "140.0000000000"
*DISP_RANGE_TOP "563728.0000000000"
*DISP_SCALE_MODE_Y "0.0000000000"
*DISP_TAB_NAME "Theta/2-Theta"
*DISP_TITLE_Y "Intensity"
*DISP_UNIT_Y "cps"
*DISP_WINDOW_NAME "MSG_MACROENGINE"
*FILE_COMMENT " "
*FILE_MD5 ""
*FILE_MEMO " "
*FILE_OPERATOR "Administrator"
*FILE_SAMPLE "Parafilm_Si"
*FILE_TYPE "RAS_RAW"
*FILE_USERGROUP "System Manager"
*FILE_VERSION "1.0000000000"
*HW_ATTACHMENT_ID "ATT1031"
*HW_ATTACHMENT_NAME "6サンプルチェンジャ|ASC-6"
*HW_COUNTER_ID-0 "CUT0025"
*HW_COUNTER_ID-1 "CUT0020"
*HW_COUNTER_ID-2 "CUT0020"
*HW_COUNTER_ID-3 "CMC0021"
*HW_COUNTER_NAME-0 "D/teX Ultra|D/teX Ultra"
*HW_COUNTER_NAME-1 "None|None"
*HW_COUNTER_NAME-2 "None|None"
*HW_COUNTER_NAME-3 "検出器モノクロメータ|Detector monochromator"
*HW_COUNTER_SELECT_NAME "D/teX Ultra|D/teX Ultra"
*HW_GONIOMETER_ID "GON0070"
*HW_GONIOMETER_NAME "MiniFlex 300/600|MiniFlex 300/600"
*HW_GONIOMETER_RADIUS-0 "79.0"
*HW_GONIOMETER_RADIUS-1 "91.5"
*HW_GONIOMETER_RADIUS-2 "150.0"
*HW_GONIOMETER_RADIUS-3 "0"
*HW_GONIOMETER_RADIUS-4 "103.4"
*HW_GONIOMETER_RADIUS-5 "150.0"
*HW_GONIOMETER_RADIUS-6 "46.6"
*HW_GONIOMETER_RADIUS-7 "160.0"
*HW_I_OPT_ID-0 "ISL0021"
*HW_I_OPT_ID-1 "ISO0021"
*HW_I_OPT_NAME-0 "発散スリット|Divergence slit"
*HW_I_OPT_NAME-1 "入射平行スリット|Incident parallel slit"
*HW_R_ATTENUATER_AUTOMODE "0"
*HW_R_OPT_ID-0 "RSS0021"
*HW_R_OPT_ID-1 "RSO0021"
*HW_R_OPT_ID-2 "RRS0021"
*HW_R_OPT_NAME-0 "散乱スリット|Scattering slit"
*HW_R_OPT_NAME-1 "受光平行スリット|Receiving soller slit"
*HW_R_OPT_NAME-2 "受光スリット|Receiving slit"
*HW_SAMPLE_HOLDER_ID "SMP0000"
*HW_SAMPLE_HOLDER_NAME "無し|None"
*HW_XG_CURRENT_MAX "15"
*HW_XG_CURRENT_MIN "2"
*HW_XG_CURRENT_RESOLUTION "1"
*HW_XG_CURRENT_UNIT "mA"
*HW_XG_FOCUS "1mm x 10mm"
*HW_XG_FOCUS_TYPE "Normal"
*HW_XG_ID ""
*HW_XG_NAME "300W/600W 封入管-B|300W/600W Sealed tube-B"
*HW_XG_TARGET_ATOMIC_NUMBER "29.0000000000"
*HW_XG_TARGET_NAME "Cu"
*HW_XG_TYPE "Hermetic"
*HW_XG_VOLTAGE_MAX "40"
*HW_XG_VOLTAGE_MIN "20"
*HW_XG_VOLTAGE_RESOLUTION "1"
*HW_XG_VOLTAGE_UNIT "kV"
*HW_XG_WATT_MAX "1"
*HW_XG_WATT_UNIT "kW"
*HW_XG_WAVE_LENGTH_ALPHA1 "1.540593"
*HW_XG_WAVE_LENGTH_ALPHA2 "1.544414"
*HW_XG_WAVE_LENGTH_BETA "1.392250"
*MEAS_COND_AXIS_NAME-0 "Theta/2-Theta"
*MEAS_COND_AXIS_NAME-1 "Spin"
*MEAS_COND_AXIS_NAME-2 "Change"
*MEAS_COND_AXIS_NAME-3 "Soller(inc.)"
*MEAS_COND_AXIS_NAME-4 "IHS"
*MEAS_COND_AXIS_NAME-5 "DS"
*MEAS_COND_AXIS_NAME-6 "SS"
*MEAS_COND_AXIS_NAME-7 "Soller(rec.)"
*MEAS_COND_AXIS_NAME-8 "RS"
*MEAS_COND_AXIS_NAME-9 "Filter"
*MEAS_COND_AXIS_NAME-10 "Monochromator"
*MEAS_COND_AXIS_NAME-11 "PHA"
*MEAS_COND_AXIS_NAME_INTERNAL-0 "TwoThetaTheta"
*MEAS_COND_AXIS_NAME_INTERNAL-1 "Spin"
*MEAS_COND_AXIS_NAME_INTERNAL-2 "Change"
*MEAS_COND_AXIS_NAME_INTERNAL-3 "IncidentSollerSlit"
*MEAS_COND_AXIS_NAME_INTERNAL-4 "IncidentAxdSlit"
*MEAS_COND_AXIS_NAME_INTERNAL-5 "IncidentSlitBox"
*MEAS_COND_AXIS_NAME_INTERNAL-6 "ReceivingSlitBox1"
*MEAS_COND_AXIS_NAME_INTERNAL-7 "ReceivingSollerSlit"
*MEAS_COND_AXIS_NAME_INTERNAL-8 "ReceivingSlitBox2"
*MEAS_COND_AXIS_NAME_INTERNAL-9 "Filter"
*MEAS_COND_AXIS_NAME_INTERNAL-10 "CounterMonochromator"
*MEAS_COND_AXIS_NAME_INTERNAL-11 "PHA"
*MEAS_COND_AXIS_NAME_MAGICNO-0 "268632064.0000000000"
*MEAS_COND_AXIS_NAME_MAGICNO-1 "16842752.0000000000"
*MEAS_COND_AXIS_NAME_MAGICNO-2 "16842752.0000000000"
*MEAS_COND_AXIS_NAME_MAGICNO-3 "20971521.0000000000"
*MEAS_COND_AXIS_NAME_MAGICNO-4 "22020097.0000000000"
*MEAS_COND_AXIS_NAME_MAGICNO-5 "22020097.0000000000"
*MEAS_COND_AXIS_NAME_MAGICNO-6 "23068673.0000000000"
*MEAS_COND_AXIS_NAME_MAGICNO-7 "20971521.0000000000"
*MEAS_COND_AXIS_NAME_MAGICNO-8 "23068673.0000000000"
*MEAS_COND_AXIS_NAME_MAGICNO-9 "20971521.0000000000"
*MEAS_COND_AXIS_NAME_MAGICNO-10 "20971521.0000000000"
*MEAS_COND_AXIS_NAME_MAGICNO-11 "0.0000000000"
*MEAS_COND_AXIS_OFFSET-0 "0.0000000000"
*MEAS_COND_AXIS_OFFSET-1 "-"
*MEAS_COND_AXIS_OFFSET-2 "-"
*MEAS_COND_AXIS_OFFSET-3 "-"
*MEAS_COND_AXIS_OFFSET-4 "-"
*MEAS_COND_AXIS_OFFSET-5 "-"
*MEAS_COND_AXIS_OFFSET-6 "-"
*MEAS_COND_AXIS_OFFSET-7 "-"
*MEAS_COND_AXIS_OFFSET-8 "-"
*MEAS_COND_AXIS_OFFSET-9 "-"
*MEAS_COND_AXIS_OFFSET-10 "-"
*MEAS_COND_AXIS_OFFSET-11 "-"
*MEAS_COND_AXIS_POSITION-0 "142.5900000000"
*MEAS_COND_AXIS_POSITION-1 "0.0000000000"
*MEAS_COND_AXIS_POSITION-2 "6.0000000000"
*MEAS_COND_AXIS_POSITION-3 "2.5deg"
*MEAS_COND_AXIS_POSITION-4 "10.0mm"
*MEAS_COND_AXIS_POSITION-5 "0.625deg"
*MEAS_COND_AXIS_POSITION-6 "8.0mm"
*MEAS_COND_AXIS_POSITION-7 "2.5deg"
*MEAS_COND_AXIS_POSITION-8 "13.0mm"
*MEAS_COND_AXIS_POSITION-9 "K-beta(x2)"
*MEAS_COND_AXIS_POSITION-10 "None"
*MEAS_COND_AXIS_POSITION-11 "49.0000000000"
*MEAS_COND_AXIS_UNIT-0 "deg"
*MEAS_COND_AXIS_UNIT-1 ""
*MEAS_COND_AXIS_UNIT-2 ""
*MEAS_COND_AXIS_UNIT-3 ""
*MEAS_COND_AXIS_UNIT-4 ""
*MEAS_COND_AXIS_UNIT-5 ""
*MEAS_COND_AXIS_UNIT-6 ""
*MEAS_COND_AXIS_UNIT-7 ""
*MEAS_COND_AXIS_UNIT-8 ""
*MEAS_COND_AXIS_UNIT-9 ""
*MEAS_COND_AXIS_UNIT-10 ""
*MEAS_COND_AXIS_UNIT-11 "div"
*MEAS_COND_CORRECTION_SLIT_COUNTERMONO "None"
*MEAS_COND_CORRECTION_SLIT_DS "0.625deg"
*MEAS_COND_CORRECTION_SLIT_FILTER "None"
*MEAS_COND_CORRECTION_SLIT_IHS "10.0mm"
*MEAS_COND_CORRECTION_SLIT_RS "13.0mm"
*MEAS_COND_CORRECTION_SLIT_SOLLER_INC "2.5deg"
*MEAS_COND_CORRECTION_SLIT_SOLLER_REC "2.5deg"
*MEAS_COND_CORRECTION_SLIT_SS "8.0mm"
*MEAS_COND_COUNTER_CNTLOSS_CORR "0.0000000000"
*MEAS_COND_COUNTER_PHABASE "49.0000000000"
*MEAS_COND_COUNTER_PHAWINDOW "8.0000000000"
*MEAS_COND_COUNTER_PHA_UNIT "div"
*MEAS_COND_COUNTER_TAUDIFF "0.2500000000"
*MEAS_COND_COUNTER_TAUINT "0.7500000000"
*MEAS_COND_IRRADIATION_MODE "OFF"
*MEAS_COND_IRRADIATION_WIDTH ""
*MEAS_COND_OPT_ATTR " "
*MEAS_COND_OPT_NAME ""
*MEAS_COND_UNSYMMETRIC_MODE "OFF"
*MEAS_COND_XG_CURRENT "15.0000000000"
*MEAS_COND_XG_VOLTAGE "40.0000000000"
*MEAS_COND_XG_WAVE_TYPE "Ka"
*MEAS_DATA_COUNT "13801.0000000000"
*MEAS_SCAN_AXIS_X "Theta/2-Theta"
*MEAS_SCAN_AXIS_X_INTERNAL "TwoThetaTheta"
*MEAS_SCAN_END_TIME "06/23/22 02:58:24"
*MEAS_SCAN_MODE "CONTINUOUS"
*MEAS_SCAN_MONITOR "0"
*MEAS_SCAN_RESOLUTION_X "0.005"
*MEAS_SCAN_SPEED "1.000"
*MEAS_SCAN_SPEED_UNIT "deg/min"
*MEAS_SCAN_START "2.0000000000"
*MEAS_SCAN_START_TIME "06/23/22 00:34:56"
*MEAS_SCAN_STEP "0.0100000000"
*MEAS_SCAN_STOP "140.0000000000"
*MEAS_SCAN_UNIT_X "deg"
*MEAS_SCAN_UNIT_Y "counts"
*SLIT_SYSTEM "0"
*RAS_HEADER_END
*RAS_INT_START
2.000 50580.000 1.000
2.100 98810.000 1.000
2.200 252266.000 1.000
2.300 213748.000 1.000
2.400 64121.000 1.000
2.500 16245.000 1.000
2.600 7062.000 1.000
2.700 4187.000 1.000
2.800 2864.000 1.000
2.900 2272.000 1.000
3.000 1761.000 1.000
3.100 1587.000 1.000
3.200 1488.000 1.000
3.300 1414.000 1.000
3.400 1450.000 1.000
3.500 1406.000 1.000
3.600 1431.000 1.000
3.700 1700.000 1.000
3.800 1793.000 1.000
3.900 2097.000 1.000
4.000 2950.000 1.000
4.100 4861.000 1.000
4.200 10578.000 1.000
4.300 27933.000 1.000
4.400 48773.000 1.000
4.500 30756.000 1.000
4.600 12007.000 1.000
4.700 5304.000 1.000
4.800 3295.000 1.000
4.900 2479.000 1.000
5.000 2024.000 1.000
5.100 1723.000 1.000
5.200 1510.000 1.000
5.300 1385.000 1.000
5.400 1271.000 1.000
5.500 1166.000 1.000
5.600 1174.000 1.000
5.700 1147.000 1.000
5.800 1045.000 1.000
5.900 1075.000 1.000
6.000 1057.000 1.000
6.100 1085.000 1.000
6.200 1143.000 1.000
6.300 1399.000 1.000
6.400 2192.000 1.000
6.500 4204.000 1.000
6.600 5862.000 1.000
6.700 4268.000 1.000
6.800 2556.000 1.000
6.900 1883.000 1.000
7.000 1576.000 1.000
7.100 1388.000 1.000
7.200 1274.000 1.000
7.300 1194.000 1.000
7.400 1212.000 1.000
7.500 1171.000 1.000
7.600 1136.000 1.000
7.700 1076.000 1.000
7.800 1032.000 1.000
7.900 1063.000 1.000
8.000 1052.000 1.000
8.100 1056.000 1.000
8.200 1016.000 1.000
8.300 958.000 1.000
8.400 1024.000 1.000
8.500 1032.000 1.000
8.600 1067.000 1.000
8.700 1164.000 1.000
8.800 1220.000 1.000
8.900 1198.000 1.000
9.000 1202.000 1.000
9.100 1192.000 1.000
9.200 1178.000 1.000
9.300 1151.000 1.000
9.400 1210.000 1.000
9.500 1227.000 1.000
9.600 1196.000 1.000
9.700 1188.000 1.000
9.800 1212.000 1.000
9.900 1188.000 1.000
10.000 1215.000 1.000
10.100 1259.000 1.000
10.200 1271.000 1.000
10.300 1287.000 1.000
10.400 1292.000 1.000
10.500 1358.000 1.000
10.600 1402.000 1.000
10.700 1422.000 1.000
10.800 1406.000 1.000
10.900 1447.000 1.000
11.000 1472.000 1.000
11.100 1511.000 1.000
11.200 1598.000 1.000
11.300 1598.000 1.000
11.400 1652.000 1.000
11.500 1683.000 1.000
11.600 1732.000 1.000
11.700 1804.000 1.000
11.800 1818.000 1.000
11.900 1880.000 1.000
12.000 1942.000 1.000
12.100 2012.000 1.000
12.200 2058.000 1.000
12.300 2104.000 1.000
12.400 2116.000 1.000
12.500 2211.000 1.000
12.600 2206.000 1.000
12.700 2254.000 1.000
12.800 2352.000 1.000
12.900 2435.000 1.000
13.000 2492.000 1.000
13.100 2528.000 1.000
13.200 2535.000 1.000
13.300 2558.000 1.000
13.400 2696.000 1.000
13.500 2697.000 1.000
13.600 2767.000 1.000
13.700 2791.000 1.000
13.800 2828.000 1.000
13.900 2897.000 1.000
14.000 2902.000 1.000
14.100 3002.000 1.000
14.200 2982.000 1.000
14.300 3042.000 1.000
14.400 3012.000 1.000
14.500 3039.000 1.000
14.600 2978.000 1.000
14.700 3099.000 1.000
14.800 2977.000 1.000
14.900 2952.000 1.000
15.000 2919.000 1.000
15.100 2889.000 1.000
15.200 2836.000 1.000
15.300 2775.000 1.000
15.400 2819.000 1.000
15.500 2764.000 1.000
15.600 2757.000 1.000
15.700 2666.000 1.000
15.800 2618.000 1.000
15.900 2503.000 1.000
16.000 2488.000 1.000
16.100 2448.000 1.000
16.200 2383.000 1.000
16.300 2346.000 1.000
16.400 2313.000 1.000
16.500 2270.000 1.000
16.600 2210.000 1.000
16.700 2164.000 1.000
16.800 2110.000 1.000
16.900 2120.000 1.000
17.000 2005.000 1.000
17.100 1936.000 1.000
17.200 1905.000 1.000
17.300 1832.000 1.000
17.400 1892.000 1.000
17.500 1822.000 1.000
17.600 1765.000 1.000
17.700 1722.000 1.000
17.800 1712.000 1.000
17.900 1645.000 1.000
18.000 1622.000 1.000
18.100 1576.000 1.000
18.200 1602.000 1.000
18.300 1553.000 1.000
18.400 1484.000 1.000
18.500 1469.000 1.000
18.600 1425.000 1.000
18.700 1376.000 1.000
18.800 1439.000 1.000
18.900 1385.000 1.000
19.000 1320.000 1.000
19.100 1315.000 1.000
19.200 1328.000 1.000
19.300 1319.000 1.000
19.400 1266.000 1.000
19.500 1235.000 1.000
19.600 1218.000 1.000
19.700 1251.000 1.000
19.800 1225.000 1.000
19.900 1205.000 1.000
20.000 1144.000 1.000
20.100 1128.000 1.000
20.200 1173.000 1.000
20.300 1169.000 1.000
20.400 1149.000 1.000
20.500 1186.000 1.000
20.600 1172.000 1.000
20.700 1175.000 1.000
20.800 1200.000 1.000
20.900 1292.000 1.000
21.000 1375.000 1.000
21.100 1549.000 1.000
21.200 1964.000 1.000
21.300 3065.000 1.000
21.400 4729.000 1.000
21.500 4931.000 1.000
21.600 3126.000 1.000
21.700 1888.000 1.000
21.800 1384.000 1.000
21.900 1204.000 1.000
22.000 1064.000 1.000
22.100 1020.000 1.000
22.200 919.000 1.000
22.300 906.000 1.000
22.400 876.000 1.000
22.500 867.000 1.000
22.600 863.000 1.000
22.700 849.000 1.000
22.800 873.000 1.000
22.900 848.000 1.000
23.000 857.000 1.000
23.100 919.000 1.000
23.200 944.000 1.000
23.300 1013.000 1.000
23.400 1130.000 1.000
23.500 1413.000 1.000
23.600 1965.000 1.000
23.700 3095.000 1.000
23.800 3487.000 1.000
23.900 2694.000 1.000
24.000 1577.000 1.000
24.100 1103.000 1.000
24.200 860.000 1.000
24.300 755.000 1.000
24.400 671.000 1.000
24.500 635.000 1.000
24.600 621.000 1.000
24.700 594.000 1.000
24.800 561.000 1.000
24.900 575.000 1.000
25.000 530.000 1.000
25.100 560.000 1.000
25.200 500.000 1.000
25.300 486.000 1.000
25.400 505.000 1.000
25.500 493.000 1.000
25.600 503.000 1.000
25.700 487.000 1.000
25.800 463.000 1.000
25.900 458.000 1.000
26.000 466.000 1.000
26.100 465.000 1.000
26.200 456.000 1.000
26.300 443.000 1.000
26.400 439.000 1.000
26.500 435.000 1.000
26.600 442.000 1.000
26.700 423.000 1.000
26.800 440.000 1.000
26.900 424.000 1.000
27.000 405.000 1.000
27.100 413.000 1.000
27.200 424.000 1.000
27.300 381.000 1.000
27.400 432.000 1.000
27.500 404.000 1.000
27.600 407.000 1.000
27.700 414.000 1.000
27.800 381.000 1.000
27.900 382.000 1.000
28.000 377.000 1.000
28.100 381.000 1.000
28.200 370.000 1.000
28.300 377.000 1.000
28.400 387.000 1.000
28.500 384.000 1.000
28.600 388.000 1.000
28.700 377.000 1.000
28.800 364.000 1.000
28.900 391.000 1.000
29.000 351.000 1.000
29.100 371.000 1.000
29.200 362.000 1.000
29.300 350.000 1.000
29.400 368.000 1.000
29.500 371.000 1.000
29.600 360.000 1.000
29.700 372.000 1.000
29.800 411.000 1.000
29.900 394.000 1.000
30.000 399.000 1.000
30.100 391.000 1.000
30.200 348.000 1.000
30.300 342.000 1.000
30.400 343.000 1.000
30.500 357.000 1.000
30.600 331.000 1.000
30.700 331.000 1.000
30.800 318.000 1.000
30.900 321.000 1.000
31.000 319.000 1.000
31.100 340.000 1.000
31.200 326.000 1.000
31.300 336.000 1.000
31.400 315.000 1.000
31.500 323.000 1.000
31.600 337.000 1.000
31.700 328.000 1.000
31.800 302.000 1.000
31.900 324.000 1.000
32.000 334.000 1.000
32.100 313.000 1.000
32.200 315.000 1.000
32.300 310.000 1.000
32.400 328.000 1.000
32.500 306.000 1.000
32.600 308.000 1.000
32.700 300.000 1.000
32.800 314.000 1.000
32.900 310.000 1.000
33.000 327.000 1.000
33.100 302.000 1.000
33.200 312.000 1.000
33.300 315.000 1.000
33.400 339.000 1.000
33.500 344.000 1.000
33.600 314.000 1.000
33.700 310.000 1.000
33.800 316.000 1.000
33.900 307.000 1.000
34.000 303.000 1.000
34.100 306.000 1.000
34.200 317.000 1.000
34.300 311.000 1.000
34.400 324.000 1.000
34.500 298.000 1.000
34.600 302.000 1.000
34.700 310.000 1.000
34.800 291.000 1.000
34.900 311.000 1.000
35.000 321.000 1.000
35.100 300.000 1.000
35.200 324.000 1.000
35.300 316.000 1.000
35.400 310.000 1.000
35.500 315.000 1.000
35.600 316.000 1.000
35.700 318.000 1.000
35.800 321.000 1.000
35.900 324.000 1.000
36.000 340.000 1.000
36.100 365.000 1.000
36.200 357.000 1.000
36.300 341.000 1.000
36.400 292.000 1.000
36.500 329.000 1.000
36.600 317.000 1.000
36.700 323.000 1.000
36.800 306.000 1.000
36.900 310.000 1.000
37.000 330.000 1.000
37.100 303.000 1.000
37.200 322.000 1.000
37.300 305.000 1.000
37.400 325.000 1.000
37.500 322.000 1.000
37.600 307.000 1.000
37.700 313.000 1.000
37.800 312.000 1.000
37.900 305.000 1.000
38.000 315.000 1.000
38.100 329.000 1.000
38.200 320.000 1.000
38.300 330.000 1.000
38.400 320.000 1.000
38.500 322.000 1.000
38.600 323.000 1.000
38.700 326.000 1.000
38.800 309.000 1.000
38.900 318.000 1.000
39.000 351.000 1.000
39.100 333.000 1.000
39.200 330.000 1.000
39.300 325.000 1.000
39.400 352.000 1.000
39.500 334.000 1.000
39.600 387.000 1.000
39.700 384.000 1.000
39.800 375.000 1.000
39.900 385.000 1.000
40.000 386.000 1.000
40.100 359.000 1.000
40.200 377.000 1.000
40.300 373.000 1.000
40.400 384.000 1.000
40.500 405.000 1.000
40.600 358.000 1.000
40.700 341.000 1.000
40.800 325.000 1.000
40.900 350.000 1.000
41.000 306.000 1.000
41.100 305.000 1.000
41.200 326.000 1.000
41.300 301.000 1.000
41.400 327.000 1.000
41.500 303.000 1.000
41.600 311.000 1.000
41.700 330.000 1.000
41.800 316.000 1.000
41.900 310.000 1.000
42.000 299.000 1.000
42.100 298.000 1.000
42.200 306.000 1.000
42.300 281.000 1.000
42.400 301.000 1.000
42.500 317.000 1.000
42.600 300.000 1.000
42.700 296.000 1.000
42.800 326.000 1.000
42.900 322.000 1.000
43.000 311.000 1.000
43.100 306.000 1.000
43.200 293.000 1.000
43.300 280.000 1.000
43.400 284.000 1.000
43.500 298.000 1.000
43.600 273.000 1.000
43.700 267.000 1.000
43.800 256.000 1.000
43.900 255.000 1.000
44.000 235.000 1.000
44.100 239.000 1.000
44.200 231.000 1.000
44.300 221.000 1.000
44.400 238.000 1.000
44.500 245.000 1.000
44.600 217.000 1.000
44.700 234.000 1.000
44.800 217.000 1.000
44.900 225.000 1.000
45.000 219.000 1.000
45.100 206.000 1.000
45.200 220.000 1.000
45.300 221.000 1.000
45.400 197.000 1.000
45.500 212.000 1.000
45.600 217.000 1.000
45.700 217.000 1.000
45.800 213.000 1.000
45.900 225.000 1.000
46.000 208.000 1.000
46.100 204.000 1.000
46.200 213.000 1.000
46.300 210.000 1.000
46.400 227.000 1.000
46.500 211.000 1.000
46.600 202.000 1.000
46.700 203.000 1.000
46.800 198.000 1.000
46.900 210.000 1.000
47.000 201.000 1.000
47.100 208.000 1.000
47.200 215.000 1.000
47.300 194.000 1.000
47.400 182.000 1.000
47.500 203.000 1.000
47.600 202.000 1.000
47.700 194.000 1.000
47.800 192.000 1.000
47.900 183.000 1.000
48.000 199.000 1.000
48.100 178.000 1.000
48.200 207.000 1.000
48.300 204.000 1.000
48.400 177.000 1.000
48.500 178.000 1.000
48.600 189.000 1.000
48.700 201.000 1.000
48.800 173.000 1.000
48.900 186.000 1.000
49.000 197.000 1.000
49.100 183.000 1.000
49.200 172.000 1.000
49.300 178.000 1.000
49.400 169.000 1.000
49.500 166.000 1.000
49.600 154.000 1.000
49.700 166.000 1.000
49.800 152.000 1.000
49.900 169.000 1.000
50.000 195.000 1.000
50.100 165.000 1.000
50.200 167.000 1.000
50.300 152.000 1.000
50.400 170.000 1.000
50.500 171.000 1.000
50.600 145.000 1.000
50.700 155.000 1.000
50.800 156.000 1.000
50.900 161.000 1.000
51.000 155.000 1.000
51.100 154.000 1.000
51.200 172.000 1.000
51.300 166.000 1.000
51.400 170.000 1.000
51.500 153.000 1.000
51.600 160.000 1.000
51.700 157.000 1.000
51.800 164.000 1.000
51.900 158.000 1.000
52.000 153.000 1.000
52.100 156.000 1.000
52.200 158.000 1.000
52.300 167.000 1.000
52.400 169.000 1.000
52.500 155.000 1.000
52.600 165.000 1.000
52.700 160.000 1.000
52.800 158.000 1.000
52.900 171.000 1.000
53.000 169.000 1.000
53.100 153.000 1.000
53.200 158.000 1.000
53.300 154.000 1.000
53.400 151.000 1.000
53.500 149.000 1.000
53.600 151.000 1.000
53.700 163.000 1.000
53.800 147.000 1.000
53.900 159.000 1.000
54.000 148.000 1.000
54.100 134.000 1.000
54.200 142.000 1.000
54.300 154.000 1.000
54.400 149.000 1.000
54.500 162.000 1.000
54.600 154.000 1.000
54.700 159.000 1.000
54.800 156.000 1.000
54.900 158.000 1.000
55.000 155.000 1.000
55.100 146.000 1.000
55.200 149.000 1.000
55.300 152.000 1.000
55.400 147.000 1.000
55.500 144.000 1.000
55.600 154.000 1.000
55.700 155.000 1.000
55.800 144.000 1.000
55.900 151.000 1.000
56.000 146.000 1.000
56.100 167.000 1.000
56.200 152.000 1.000
56.300 149.000 1.000
56.400 138.000 1.000
56.500 152.000 1.000
56.600 146.000 1.000
56.700 149.000 1.000
56.800 142.000 1.000
56.900 148.000 1.000
57.000 153.000 1.000
57.100 144.000 1.000
57.200 151.000 1.000
57.300 151.000 1.000
57.400 150.000 1.000
57.500 150.000 1.000
57.600 142.000 1.000
57.700 144.000 1.000
57.800 145.000 1.000
57.900 142.000 1.000
58.000 154.000 1.000
58.100 152.000 1.000
58.200 147.000 1.000
58.300 141.000 1.000
58.400 154.000 1.000
58.500 150.000 1.000
58.600 139.000 1.000
58.700 144.000 1.000
58.800 145.000 1.000
58.900 140.000 1.000
59.000 164.000 1.000
59.100 145.000 1.000
59.200 149.000 1.000
59.300 144.000 1.000
59.400 144.000 1.000
59.500 143.000 1.000
59.600 146.000 1.000
59.700 137.000 1.000
59.800 131.000 1.000
59.900 130.000 1.000
60.000 143.000 1.000
60.100 139.000 1.000
60.200 132.000 1.000
60.300 142.000 1.000
60.400 138.000 1.000
60.500 141.000 1.000
60.600 151.000 1.000
60.700 127.000 1.000
60.800 151.000 1.000
60.900 127.000 1.000
61.000 132.000 1.000
61.100 137.000 1.000
61.200 152.000 1.000
61.300 151.000 1.000
61.400 136.000 1.000
61.500 140.000 1.000
61.600 152.000 1.000
61.700 134.000 1.000
61.800 138.000 1.000
61.900 125.000 1.000
62.000 129.000 1.000
62.100 137.000 1.000
62.200 137.000 1.000
62.300 148.000 1.000
62.400 135.000 1.000
62.500 133.000 1.000
62.600 130.000 1.000
62.700 131.000 1.000
62.800 134.000 1.000
62.900 135.000 1.000
63.000 134.000 1.000
63.100 119.000 1.000
63.200 135.000 1.000
63.300 134.000 1.000
63.400 134.000 1.000
63.500 144.000 1.000
63.600 129.000 1.000
63.700 126.000 1.000
63.800 129.000 1.000
63.900 127.000 1.000
64.000 146.000 1.000
64.100 126.000 1.000
64.200 134.000 1.000
64.300 120.000 1.000
64.400 137.000 1.000
64.500 133.000 1.000
64.600 130.000 1.000
64.700 136.000 1.000
64.800 144.000 1.000
64.900 146.000 1.000
65.000 132.000 1.000
65.100 129.000 1.000
65.200 132.000 1.000
65.300 135.000 1.000
65.400 131.000 1.000
65.500 126.000 1.000
65.600 138.000 1.000
65.700 128.000 1.000
65.800 124.000 1.000
65.900 131.000 1.000
66.000 125.000 1.000
66.100 126.000 1.000
66.200 130.000 1.000
66.300 127.000 1.000
66.400 119.000 1.000
66.500 140.000 1.000
66.600 119.000 1.000
66.700 129.000 1.000
66.800 122.000 1.000
66.900 119.000 1.000
67.000 139.000 1.000
67.100 118.000 1.000
67.200 129.000 1.000
67.300 135.000 1.000
67.400 121.000 1.000
67.500 126.000 1.000
67.600 139.000 1.000
67.700 109.000 1.000
67.800 131.000 1.000
67.900 143.000 1.000
68.000 126.000 1.000
68.100 117.000 1.000
68.200 129.000 1.000
68.300 118.000 1.000
68.400 122.000 1.000
68.500 125.000 1.000
68.600 118.000 1.000
68.700 134.000 1.000
68.800 141.000 1.000
68.900 134.000 1.000
69.000 131.000 1.000
69.100 126.000 1.000
69.200 129.000 1.000
69.300 130.000 1.000
69.400 128.000 1.000
69.500 130.000 1.000
69.600 122.000 1.000
69.700 132.000 1.000
69.800 118.000 1.000
69.900 126.000 1.000
70.000 119.000 1.000
70.100 133.000 1.000
70.200 120.000 1.000
70.300 138.000 1.000
70.400 134.000 1.000
70.500 125.000 1.000
70.600 131.000 1.000
70.700 124.000 1.000
70.800 116.000 1.000
70.900 129.000 1.000
71.000 130.000 1.000
71.100 133.000 1.000
71.200 122.000 1.000
71.300 144.000 1.000
71.400 122.000 1.000
71.500 125.000 1.000
71.600 123.000 1.000
71.700 123.000 1.000
71.800 128.000 1.000
71.900 142.000 1.000
72.000 123.000 1.000
72.100 135.000 1.000
72.200 128.000 1.000
72.300 117.000 1.000
72.400 140.000 1.000
72.500 142.000 1.000
72.600 134.000 1.000
72.700 133.000 1.000
72.800 140.000 1.000
72.900 147.000 1.000
73.000 152.000 1.000
73.100 148.000 1.000
73.200 166.000 1.000
73.300 156.000 1.000
73.400 167.000 1.000
73.500 172.000 1.000
73.600 163.000 1.000
73.700 165.000 1.000
73.800 189.000 1.000
73.900 169.000 1.000
74.000 180.000 1.000
74.100 189.000 1.000
74.200 194.000 1.000
74.300 207.000 1.000
74.400 238.000 1.000
74.500 216.000 1.000
74.600 218.000 1.000
74.700 253.000 1.000
74.800 239.000 1.000
74.900 218.000 1.000
75.000 206.000 1.000
75.100 215.000 1.000
75.200 198.000 1.000
75.300 210.000 1.000
75.400 200.000 1.000
75.500 193.000 1.000
75.600 195.000 1.000
75.700 182.000 1.000
75.800 182.000 1.000
75.900 182.000 1.000
76.000 180.000 1.000
76.100 175.000 1.000
76.200 175.000 1.000
76.300 171.000 1.000
76.400 172.000 1.000
76.500 160.000 1.000
76.600 163.000 1.000
76.700 173.000 1.000
76.800 169.000 1.000
76.900 160.000 1.000
77.000 156.000 1.000
77.100 164.000 1.000
77.200 162.000 1.000
77.300 141.000 1.000
77.400 164.000 1.000
77.500 151.000 1.000
77.600 159.000 1.000
77.700 142.000 1.000
77.800 147.000 1.000
77.900 161.000 1.000
78.000 152.000 1.000
78.100 137.000 1.000
78.200 161.000 1.000
78.300 156.000 1.000
78.400 146.000 1.000
78.500 159.000 1.000
78.600 164.000 1.000
78.700 155.000 1.000
78.800 160.000 1.000
78.900 143.000 1.000
79.000 152.000 1.000
79.100 150.000 1.000
79.200 161.000 1.000
79.300 143.000 1.000
79.400 128.000 1.000
79.500 126.000 1.000
79.600 127.000 1.000
79.700 150.000 1.000
79.800 143.000 1.000
79.900 140.000 1.000
80.000 120.000 1.000
80.100 127.000 1.000
80.200 119.000 1.000
80.300 146.000 1.000
80.400 121.000 1.000
80.500 109.000 1.000
80.600 108.000 1.000
80.700 107.000 1.000
80.800 107.000 1.000
80.900 105.000 1.000
81.000 119.000 1.000
81.100 106.000 1.000
81.200 116.000 1.000
81.300 105.000 1.000
81.400 110.000 1.000
81.500 111.000 1.000
81.600 104.000 1.000
81.700 111.000 1.000
81.800 104.000 1.000
81.900 99.000 1.000
82.000 90.000 1.000
82.100 110.000 1.000
82.200 101.000 1.000
82.300 103.000 1.000
82.400 108.000 1.000
82.500 94.000 1.000
82.600 97.000 1.000
82.700 105.000 1.000
82.800 90.000 1.000
82.900 101.000 1.000
83.000 100.000 1.000
83.100 96.000 1.000
83.200 104.000 1.000
83.300 89.000 1.000
83.400 97.000 1.000
83.500 97.000 1.000
83.600 103.000 1.000
83.700 95.000 1.000
83.800 91.000 1.000
83.900 92.000 1.000
84.000 104.000 1.000
84.100 100.000 1.000
84.200 88.000 1.000
84.300 84.000 1.000
84.400 98.000 1.000
84.500 93.000 1.000
84.600 89.000 1.000
84.700 92.000 1.000
84.800 99.000 1.000
84.900 99.000 1.000
85.000 95.000 1.000
85.100 100.000 1.000
85.200 89.000 1.000
85.300 89.000 1.000
85.400 98.000 1.000
85.500 89.000 1.000
85.600 90.000 1.000
85.700 96.000 1.000
85.800 91.000 1.000
85.900 101.000 1.000
86.000 86.000 1.000
86.100 92.000 1.000
86.200 78.000 1.000
86.300 90.000 1.000
86.400 89.000 1.000
86.500 89.000 1.000
86.600 90.000 1.000
86.700 104.000 1.000
86.800 94.000 1.000
86.900 90.000 1.000
87.000 88.000 1.000
87.100 96.000 1.000
87.200 87.000 1.000
87.300 98.000 1.000
87.400 90.000 1.000
87.500 93.000 1.000
87.600 97.000 1.000
87.700 98.000 1.000
87.800 90.000 1.000
87.900 85.000 1.000
88.000 91.000 1.000
88.100 95.000 1.000
88.200 91.000 1.000
88.300 83.000 1.000
88.400 89.000 1.000
88.500 75.000 1.000
88.600 84.000 1.000
88.700 106.000 1.000
88.800 92.000 1.000
88.900 81.000 1.000
89.000 85.000 1.000
89.100 104.000 1.000
89.200 87.000 1.000
89.300 93.000 1.000
89.400 84.000 1.000
89.500 85.000 1.000
89.600 81.000 1.000
89.700 85.000 1.000
89.800 87.000 1.000
89.900 89.000 1.000
90.000 88.000 1.000
90.100 99.000 1.000
90.200 90.000 1.000
90.300 81.000 1.000
90.400 89.000 1.000
90.500 87.000 1.000
90.600 87.000 1.000
90.700 83.000 1.000
90.800 91.000 1.000
90.900 85.000 1.000
91.000 79.000 1.000
91.100 87.000 1.000
91.200 84.000 1.000
91.300 94.000 1.000
91.400 90.000 1.000
91.500 82.000 1.000
91.600 85.000 1.000
91.700 81.000 1.000
91.800 78.000 1.000
91.900 81.000 1.000
92.000 83.000 1.000
92.100 93.000 1.000
92.200 92.000 1.000
92.300 84.000 1.000
92.400 77.000 1.000
92.500 71.000 1.000
92.600 79.000 1.000
92.700 97.000 1.000
92.800 92.000 1.000
92.900 78.000 1.000
93.000 79.000 1.000
93.100 88.000 1.000
93.200 79.000 1.000
93.300 79.000 1.000
93.400 76.000 1.000
93.500 89.000 1.000
93.600 87.000 1.000
93.700 76.000 1.000
93.800 69.000 1.000
93.900 78.000 1.000
94.000 77.000 1.000
94.100 83.000 1.000
94.200 84.000 1.000
94.300 98.000 1.000
94.400 84.000 1.000
94.500 67.000 1.000
94.600 81.000 1.000
94.700 79.000 1.000
94.800 91.000 1.000
94.900 78.000 1.000
95.000 80.000 1.000
95.100 70.000 1.000
95.200 86.000 1.000
95.300 79.000 1.000
95.400 97.000 1.000
95.500 81.000 1.000
95.600 70.000 1.000
95.700 85.000 1.000
95.800 81.000 1.000
95.900 65.000 1.000
96.000 82.000 1.000
96.100 73.000 1.000
96.200 86.000 1.000
96.300 71.000 1.000
96.400 82.000 1.000
96.500 87.000 1.000
96.600 77.000 1.000
96.700 83.000 1.000
96.800 79.000 1.000
96.900 67.000 1.000
97.000 80.000 1.000
97.100 93.000 1.000
97.200 83.000 1.000
97.300 85.000 1.000
97.400 76.000 1.000
97.500 79.000 1.000
97.600 73.000 1.000
97.700 88.000 1.000
97.800 94.000 1.000
97.900 75.000 1.000
98.000 82.000 1.000
98.100 78.000 1.000
98.200 70.000 1.000
98.300 62.000 1.000
98.400 77.000 1.000
98.500 66.000 1.000
98.600 84.000 1.000
98.700 87.000 1.000
98.800 67.000 1.000
98.900 78.000 1.000
99.000 69.000 1.000
99.100 79.000 1.000
99.200 77.000 1.000
99.300 75.000 1.000
99.400 79.000 1.000
99.500 86.000 1.000
99.600 79.000 1.000
99.700 75.000 1.000
99.800 90.000 1.000
99.900 77.000 1.000
100.000 78.000 1.000
100.100 83.000 1.000
100.200 70.000 1.000
100.300 81.000 1.000
100.400 73.000 1.000
100.500 79.000 1.000
100.600 73.000 1.000
100.700 77.000 1.000
100.800 86.000 1.000
100.900 74.000 1.000
101.000 72.000 1.000
101.100 86.000 1.000
101.200 79.000 1.000
101.300 75.000 1.000
101.400 91.000 1.000
101.500 90.000 1.000
101.600 67.000 1.000
101.700 68.000 1.000
101.800 74.000 1.000
101.900 74.000 1.000
102.000 79.000 1.000
102.100 79.000 1.000
102.200 82.000 1.000
102.300 72.000 1.000
102.400 75.000 1.000
102.500 78.000 1.000
102.600 81.000 1.000
102.700 71.000 1.000
102.800 80.000 1.000
102.900 79.000 1.000
103.000 77.000 1.000
103.100 72.000 1.000
103.200 77.000 1.000
103.300 73.000 1.000
103.400 68.000 1.000
103.500 78.000 1.000
103.600 84.000 1.000
103.700 77.000 1.000
103.800 88.000 1.000
103.900 81.000 1.000
104.000 71.000 1.000
104.100 74.000 1.000
104.200 63.000 1.000
104.300 77.000 1.000
104.400 67.000 1.000
104.500 75.000 1.000
104.600 68.000 1.000
104.700 74.000 1.000
104.800 66.000 1.000
104.900 71.000 1.000
105.000 73.000 1.000
105.100 65.000 1.000
105.200 75.000 1.000
105.300 78.000 1.000
105.400 70.000 1.000
105.500 78.000 1.000
105.600 80.000 1.000
105.700 76.000 1.000
105.800 79.000 1.000
105.900 82.000 1.000
106.000 79.000 1.000
106.100 79.000 1.000
106.200 74.000 1.000
106.300 83.000 1.000
106.400 73.000 1.000
106.500 71.000 1.000
106.600 86.000 1.000
106.700 80.000 1.000
106.800 77.000 1.000
106.900 78.000 1.000
107.000 80.000 1.000
107.100 76.000 1.000
107.200 84.000 1.000
107.300 87.000 1.000
107.400 76.000 1.000
107.500 85.000 1.000
107.600 80.000 1.000
107.700 81.000 1.000
107.800 79.000 1.000
107.900 73.000 1.000
108.000 78.000 1.000
108.100 72.000 1.000
108.200 88.000 1.000
108.300 67.000 1.000
108.400 87.000 1.000
108.500 67.000 1.000
108.600 78.000 1.000
108.700 82.000 1.000
108.800 85.000 1.000
108.900 79.000 1.000
109.000 85.000 1.000
109.100 84.000 1.000
109.200 79.000 1.000
109.300 75.000 1.000
109.400 70.000 1.000
109.500 85.000 1.000
109.600 74.000 1.000
109.700 81.000 1.000
109.800 81.000 1.000
109.900 79.000 1.000
110.000 83.000 1.000
110.100 76.000 1.000
110.200 76.000 1.000
110.300 91.000 1.000
110.400 79.000 1.000
110.500 80.000 1.000
110.600 80.000 1.000
110.700 84.000 1.000
110.800 84.000 1.000
110.900 93.000 1.000
111.000 87.000 1.000
111.100 81.000 1.000
111.200 83.000 1.000
111.300 84.000 1.000
111.400 88.000 1.000
111.500 82.000 1.000
111.600 78.000 1.000
111.700 78.000 1.000
111.800 87.000 1.000
111.900 79.000 1.000
112.000 93.000 1.000
112.100 75.000 1.000
112.200 81.000 1.000
112.300 80.000 1.000
112.400 88.000 1.000
112.500 92.000 1.000
112.600 88.000 1.000
112.700 85.000 1.000
112.800 84.000 1.000
112.900 89.000 1.000
113.000 78.000 1.000
113.100 87.000 1.000
113.200 78.000 1.000
113.300 82.000 1.000
113.400 85.000 1.000
113.500 88.000 1.000
113.600 77.000 1.000
113.700 94.000 1.000
113.800 94.000 1.000
113.900 88.000 1.000
114.000 76.000 1.000
114.100 89.000 1.000
114.200 81.000 1.000
114.300 81.000 1.000
114.400 86.000 1.000
114.500 90.000 1.000
114.600 87.000 1.000
114.700 90.000 1.000
114.800 98.000 1.000
114.900 94.000 1.000
115.000 91.000 1.000
115.100 95.000 1.000
115.200 91.000 1.000
115.300 89.000 1.000
115.400 100.000 1.000
115.500 95.000 1.000
115.600 96.000 1.000
115.700 101.000 1.000
115.800 84.000 1.000
115.900 91.000 1.000
116.000 86.000 1.000
116.100 87.000 1.000
116.200 89.000 1.000
116.300 96.000 1.000
116.400 84.000 1.000
116.500 96.000 1.000
116.600 90.000 1.000
116.700 102.000 1.000
116.800 102.000 1.000
116.900 87.000 1.000
117.000 100.000 1.000
117.100 91.000 1.000
117.200 92.000 1.000
117.300 102.000 1.000
117.400 89.000 1.000
117.500 85.000 1.000
117.600 94.000 1.000
117.700 85.000 1.000
117.800 81.000 1.000
117.900 98.000 1.000
118.000 93.000 1.000
118.100 94.000 1.000
118.200 95.000 1.000
118.300 89.000 1.000
118.400 97.000 1.000
118.500 90.000 1.000
118.600 96.000 1.000
118.700 101.000 1.000
118.800 94.000 1.000
118.900 93.000 1.000
119.000 99.000 1.000
119.100 106.000 1.000
119.200 108.000 1.000
119.300 95.000 1.000
119.400 95.000 1.000
119.500 108.000 1.000
119.600 110.000 1.000
119.700 91.000 1.000
119.800 94.000 1.000
119.900 99.000 1.000
120.000 97.000 1.000
120.100 105.000 1.000
120.200 93.000 1.000
120.300 95.000 1.000
120.400 94.000 1.000
120.500 96.000 1.000
120.600 93.000 1.000
120.700 105.000 1.000
120.800 99.000 1.000
120.900 86.000 1.000
121.000 102.000 1.000
121.100 97.000 1.000
121.200 110.000 1.000
121.300 93.000 1.000
121.400 94.000 1.000
121.500 99.000 1.000
121.600 100.000 1.000
121.700 94.000 1.000
121.800 105.000 1.000
121.900 101.000 1.000
122.000 106.000 1.000
122.100 103.000 1.000
122.200 106.000 1.000
122.300 96.000 1.000
122.400 96.000 1.000
122.500 108.000 1.000
122.600 87.000 1.000
122.700 104.000 1.000
122.800 97.000 1.000
122.900 101.000 1.000
123.000 113.000 1.000
123.100 99.000 1.000
123.200 98.000 1.000
123.300 106.000 1.000
123.400 104.000 1.000
123.500 91.000 1.000
123.600 97.000 1.000
123.700 93.000 1.000
123.800 110.000 1.000
123.900 106.000 1.000
124.000 87.000 1.000
124.100 87.000 1.000
124.200 93.000 1.000
124.300 109.000 1.000
124.400 107.000 1.000
124.500 107.000 1.000
124.600 96.000 1.000
124.700 97.000 1.000
124.800 108.000 1.000
124.900 108.000 1.000
125.000 107.000 1.000
125.100 111.000 1.000
125.200 111.000 1.000
125.300 111.000 1.000
125.400 98.000 1.000
125.500 101.000 1.000
125.600 106.000 1.000
125.700 95.000 1.000
125.800 102.000 1.000
125.900 101.000 1.000
126.000 108.000 1.000
126.100 109.000 1.000
126.200 88.000 1.000
126.300 97.000 1.000
126.400 100.000 1.000
126.500 108.000 1.000
126.600 105.000 1.000
126.700 98.000 1.000
126.800 100.000 1.000
126.900 107.000 1.000
127.000 106.000 1.000
127.100 95.000 1.000
127.200 113.000 1.000
127.300 95.000 1.000
127.400 111.000 1.000
127.500 90.000 1.000
127.600 116.000 1.000
127.700 100.000 1.000
127.800 97.000 1.000
127.900 102.000 1.000
128.000 99.000 1.000
128.100 94.000 1.000
128.200 113.000 1.000
128.300 92.000 1.000
128.400 107.000 1.000
128.500 104.000 1.000
128.600 104.000 1.000
128.700 92.000 1.000
128.800 97.000 1.000
128.900 101.000 1.000
129.000 107.000 1.000
129.100 101.000 1.000
129.200 106.000 1.000
129.300 96.000 1.000
129.400 107.000 1.000
129.500 112.000 1.000
129.600 97.000 1.000
129.700 99.000 1.000
129.800 118.000 1.000
129.900 104.000 1.000
130.000 100.000 1.000
130.100 105.000 1.000
130.200 120.000 1.000
130.300 103.000 1.000
130.400 115.000 1.000
130.500 100.000 1.000
130.600 117.000 1.000
130.700 96.000 1.000
130.800 109.000 1.000
130.900 94.000 1.000
131.000 98.000 1.000
131.100 108.000 1.000
131.200 120.000 1.000
131.300 108.000 1.000
131.400 119.000 1.000
131.500 113.000 1.000
131.600 120.000 1.000
131.700 119.000 1.000
131.800 106.000 1.000
131.900 109.000 1.000
132.000 105.000 1.000
132.100 99.000 1.000
132.200 98.000 1.000
132.300 120.000 1.000
132.400 107.000 1.000
132.500 116.000 1.000
132.600 105.000 1.000
132.700 107.000 1.000
132.800 118.000 1.000
132.900 118.000 1.000
133.000 119.000 1.000
133.100 129.000 1.000
133.200 109.000 1.000
133.300 107.000 1.000
133.400 106.000 1.000
133.500 109.000 1.000
133.600 105.000 1.000
133.700 121.000 1.000
133.800 99.000 1.000
133.900 121.000 1.000
134.000 110.000 1.000
134.100 106.000 1.000
134.200 108.000 1.000
134.300 107.000 1.000
134.400 105.000 1.000
134.500 107.000 1.000
134.600 109.000 1.000
134.700 114.000 1.000
134.800 110.000 1.000
134.900 105.000 1.000
135.000 121.000 1.000
135.100 104.000 1.000
135.200 105.000 1.000
135.300 122.000 1.000
135.400 116.000 1.000
135.500 109.000 1.000
135.600 120.000 1.000
135.700 121.000 1.000
135.800 130.000 1.000
135.900 106.000 1.000
136.000 124.000 1.000
136.100 110.000 1.000
136.200 116.000 1.000
136.300 117.000 1.000
136.400 113.000 1.000
136.500 105.000 1.000
136.600 118.000 1.000
136.700 116.000 1.000
136.800 128.000 1.000
136.900 119.000 1.000
137.000 126.000 1.000
137.100 107.000 1.000
137.200 116.000 1.000
137.300 113.000 1.000
137.400 122.000 1.000
137.500 127.000 1.000
137.600 117.000 1.000
137.700 118.000 1.000
137.800 120.000 1.000
137.900 122.000 1.000
138.000 104.000 1.000
138.100 109.000 1.000
138.200 126.000 1.000
138.300 121.000 1.000
138.400 120.000 1.000
138.500 122.000 1.000
138.600 125.000 1.000
138.700 142.000 1.000
138.800 131.000 1.000
138.900 125.000 1.000
139.000 118.000 1.000
139.100 126.000 1.000
139.200 127.000 1.000
139.300 120.000 1.000
139.400 127.000 1.000
139.500 141.000 1.000
139.600 128.000 1.000
139.700 124.000 1.000
139.800 127.000 1.000
139.900 111.000 1.000
140.000 126.000 1.000
*RAS_INT_END
*RAS_DATA_END