File: Parafilm_Alu_flach.ras
*RAS_DATA_START
*RAS_HEADER_START
*CORR_POS_DB_NAME "AngleCorr_NIST640d_DteX_2022.02.28"
*CORR_POS_GONIO_RADIUS ""
*CORR_POS_NODE_INDEX01 ""
*CORR_POS_NODE_INDEX02 ""
*CORR_POS_NODE_INDEX03 ""
*CORR_POS_NODE_INDEX04 ""
*CORR_POS_NODE_INDEX05 ""
*CORR_POS_NODE_INDEX06 ""
*CORR_POS_NODE_INDEX07 ""
*CORR_POS_NODE_INDEX08 ""
*CORR_POS_NODE_INDEX09 ""
*CORR_POS_NODE_INDEX10 ""
*CORR_POS_NODE_INDEX11 ""
*CORR_POS_NODE_LABEL01 "Si(111)"
*CORR_POS_NODE_LABEL02 "Si(220)"
*CORR_POS_NODE_LABEL03 "Si(311)"
*CORR_POS_NODE_LABEL04 "Si(400)"
*CORR_POS_NODE_LABEL05 "Si(331)"
*CORR_POS_NODE_LABEL06 "Si(422)"
*CORR_POS_NODE_LABEL07 "Si(511)"
*CORR_POS_NODE_LABEL08 "Si(440)"
*CORR_POS_NODE_LABEL09 "Si(531)"
*CORR_POS_NODE_LABEL10 "Si(620)"
*CORR_POS_NODE_LABEL11 "Si(533)"
*CORR_POS_NODE_POS_CALC01 "28.4137"
*CORR_POS_NODE_POS_CALC02 "47.2707"
*CORR_POS_NODE_POS_CALC03 "56.0883"
*CORR_POS_NODE_POS_CALC04 "69.0934"
*CORR_POS_NODE_POS_CALC05 "76.3385"
*CORR_POS_NODE_POS_CALC06 "87.9915"
*CORR_POS_NODE_POS_CALC07 "94.9137"
*CORR_POS_NODE_POS_CALC08 "106.67"
*CORR_POS_NODE_POS_CALC09 "114.054"
*CORR_POS_NODE_POS_CALC10 "127.508"
*CORR_POS_NODE_POS_CALC11 "136.858"
*CORR_POS_NODE_POS_MEAS01 "28.3905"
*CORR_POS_NODE_POS_MEAS02 "47.2504"
*CORR_POS_NODE_POS_MEAS03 "56.0712"
*CORR_POS_NODE_POS_MEAS04 "69.0788"
*CORR_POS_NODE_POS_MEAS05 "76.3323"
*CORR_POS_NODE_POS_MEAS06 "87.9869"
*CORR_POS_NODE_POS_MEAS07 "94.9135"
*CORR_POS_NODE_POS_MEAS08 "106.672"
*CORR_POS_NODE_POS_MEAS09 "114.061"
*CORR_POS_NODE_POS_MEAS10 "127.517"
*CORR_POS_NODE_POS_MEAS11 "136.874"
*CORR_POS_OPT_ATTR "集中法"
*CORR_POS_PARAM_MU ""
*CORR_POS_PARAM_PL ""
*CORR_POS_SEMODEL_TYPE "0"
*CORR_POS_STANDARD_TYPE ""
*CORR_POS_VALUE_ANALYZER "None"
*CORR_POS_VALUE_CMONO "None"
*CORR_POS_VALUE_IMONO "None"
*CORR_POS_VALUE_IS "0.625deg"
*CORR_POS_VALUE_ISL "10.0mm"
*CORR_POS_VALUE_ISOLLER "2.5deg"
*CORR_POS_VALUE_RS1 "13.0mm"
*CORR_POS_VALUE_RS2 "13.0mm"
*CORR_POS_VALUE_RSOLLER "2.5deg"
*CORR_POS_XG_FOCUS_L ""
*CORR_POS_XG_WAVE_TYPE ""
*CORR_POS_XG_WAVE_VALUE ""
*DISP_FMT_X "%.2f"
*DISP_FMT_Y "%.0f"
*DISP_FULLSCALE "197624.0000000000"
*DISP_LINE_COLOR "255.0000000000"
*DISP_LINE_STYLE "0.0000000000"
*DISP_LINE_WIDTH "0.2500000000"
*DISP_NOTE "Collected Data-5"
*DISP_OFFSET_Y "0.0000000000"
*DISP_PEAKSEARCH_UNIT_Y "cps"
*DISP_RANGE_BOTTOM "0.0000000000"
*DISP_RANGE_LEFT "2.0000000000"
*DISP_RANGE_LOGCUTOFF "0.0100000000"
*DISP_RANGE_RIGHT "140.0000000000"
*DISP_RANGE_TOP "197624.0000000000"
*DISP_SCALE_MODE_Y "0.0000000000"
*DISP_TAB_NAME "Theta/2-Theta"
*DISP_TITLE_Y "Intensity"
*DISP_UNIT_Y "cps"
*DISP_WINDOW_NAME "MSG_MACROENGINE"
*FILE_COMMENT " "
*FILE_MD5 ""
*FILE_MEMO " "
*FILE_OPERATOR "Administrator"
*FILE_SAMPLE "Parafilm_Alu_flach"
*FILE_TYPE "RAS_RAW"
*FILE_USERGROUP "System Manager"
*FILE_VERSION "1.0000000000"
*HW_ATTACHMENT_ID "ATT1031"
*HW_ATTACHMENT_NAME "6サンプルチェンジャ|ASC-6"
*HW_COUNTER_ID-0 "CUT0025"
*HW_COUNTER_ID-1 "CUT0020"
*HW_COUNTER_ID-2 "CUT0020"
*HW_COUNTER_ID-3 "CMC0021"
*HW_COUNTER_NAME-0 "D/teX Ultra|D/teX Ultra"
*HW_COUNTER_NAME-1 "None|None"
*HW_COUNTER_NAME-2 "None|None"
*HW_COUNTER_NAME-3 "検出器モノクロメータ|Detector monochromator"
*HW_COUNTER_SELECT_NAME "D/teX Ultra|D/teX Ultra"
*HW_GONIOMETER_ID "GON0070"
*HW_GONIOMETER_NAME "MiniFlex 300/600|MiniFlex 300/600"
*HW_GONIOMETER_RADIUS-0 "79.0"
*HW_GONIOMETER_RADIUS-1 "91.5"
*HW_GONIOMETER_RADIUS-2 "150.0"
*HW_GONIOMETER_RADIUS-3 "0"
*HW_GONIOMETER_RADIUS-4 "103.4"
*HW_GONIOMETER_RADIUS-5 "150.0"
*HW_GONIOMETER_RADIUS-6 "46.6"
*HW_GONIOMETER_RADIUS-7 "160.0"
*HW_I_OPT_ID-0 "ISL0021"
*HW_I_OPT_ID-1 "ISO0021"
*HW_I_OPT_NAME-0 "発散スリット|Divergence slit"
*HW_I_OPT_NAME-1 "入射平行スリット|Incident parallel slit"
*HW_R_ATTENUATER_AUTOMODE "0"
*HW_R_OPT_ID-0 "RSS0021"
*HW_R_OPT_ID-1 "RSO0021"
*HW_R_OPT_ID-2 "RRS0021"
*HW_R_OPT_NAME-0 "散乱スリット|Scattering slit"
*HW_R_OPT_NAME-1 "受光平行スリット|Receiving soller slit"
*HW_R_OPT_NAME-2 "受光スリット|Receiving slit"
*HW_SAMPLE_HOLDER_ID "SMP0000"
*HW_SAMPLE_HOLDER_NAME "無し|None"
*HW_XG_CURRENT_MAX "15"
*HW_XG_CURRENT_MIN "2"
*HW_XG_CURRENT_RESOLUTION "1"
*HW_XG_CURRENT_UNIT "mA"
*HW_XG_FOCUS "1mm x 10mm"
*HW_XG_FOCUS_TYPE "Normal"
*HW_XG_ID ""
*HW_XG_NAME "300W/600W 封入管-B|300W/600W Sealed tube-B"
*HW_XG_TARGET_ATOMIC_NUMBER "29.0000000000"
*HW_XG_TARGET_NAME "Cu"
*HW_XG_TYPE "Hermetic"
*HW_XG_VOLTAGE_MAX "40"
*HW_XG_VOLTAGE_MIN "20"
*HW_XG_VOLTAGE_RESOLUTION "1"
*HW_XG_VOLTAGE_UNIT "kV"
*HW_XG_WATT_MAX "1"
*HW_XG_WATT_UNIT "kW"
*HW_XG_WAVE_LENGTH_ALPHA1 "1.540593"
*HW_XG_WAVE_LENGTH_ALPHA2 "1.544414"
*HW_XG_WAVE_LENGTH_BETA "1.392250"
*MEAS_COND_AXIS_NAME-0 "Theta/2-Theta"
*MEAS_COND_AXIS_NAME-1 "Spin"
*MEAS_COND_AXIS_NAME-2 "Change"
*MEAS_COND_AXIS_NAME-3 "Soller(inc.)"
*MEAS_COND_AXIS_NAME-4 "IHS"
*MEAS_COND_AXIS_NAME-5 "DS"
*MEAS_COND_AXIS_NAME-6 "SS"
*MEAS_COND_AXIS_NAME-7 "Soller(rec.)"
*MEAS_COND_AXIS_NAME-8 "RS"
*MEAS_COND_AXIS_NAME-9 "Filter"
*MEAS_COND_AXIS_NAME-10 "Monochromator"
*MEAS_COND_AXIS_NAME-11 "PHA"
*MEAS_COND_AXIS_NAME_INTERNAL-0 "TwoThetaTheta"
*MEAS_COND_AXIS_NAME_INTERNAL-1 "Spin"
*MEAS_COND_AXIS_NAME_INTERNAL-2 "Change"
*MEAS_COND_AXIS_NAME_INTERNAL-3 "IncidentSollerSlit"
*MEAS_COND_AXIS_NAME_INTERNAL-4 "IncidentAxdSlit"
*MEAS_COND_AXIS_NAME_INTERNAL-5 "IncidentSlitBox"
*MEAS_COND_AXIS_NAME_INTERNAL-6 "ReceivingSlitBox1"
*MEAS_COND_AXIS_NAME_INTERNAL-7 "ReceivingSollerSlit"
*MEAS_COND_AXIS_NAME_INTERNAL-8 "ReceivingSlitBox2"
*MEAS_COND_AXIS_NAME_INTERNAL-9 "Filter"
*MEAS_COND_AXIS_NAME_INTERNAL-10 "CounterMonochromator"
*MEAS_COND_AXIS_NAME_INTERNAL-11 "PHA"
*MEAS_COND_AXIS_NAME_MAGICNO-0 "268632064.0000000000"
*MEAS_COND_AXIS_NAME_MAGICNO-1 "16842752.0000000000"
*MEAS_COND_AXIS_NAME_MAGICNO-2 "16842752.0000000000"
*MEAS_COND_AXIS_NAME_MAGICNO-3 "20971521.0000000000"
*MEAS_COND_AXIS_NAME_MAGICNO-4 "22020097.0000000000"
*MEAS_COND_AXIS_NAME_MAGICNO-5 "22020097.0000000000"
*MEAS_COND_AXIS_NAME_MAGICNO-6 "23068673.0000000000"
*MEAS_COND_AXIS_NAME_MAGICNO-7 "20971521.0000000000"
*MEAS_COND_AXIS_NAME_MAGICNO-8 "23068673.0000000000"
*MEAS_COND_AXIS_NAME_MAGICNO-9 "20971521.0000000000"
*MEAS_COND_AXIS_NAME_MAGICNO-10 "20971521.0000000000"
*MEAS_COND_AXIS_NAME_MAGICNO-11 "0.0000000000"
*MEAS_COND_AXIS_OFFSET-0 "0.0000000000"
*MEAS_COND_AXIS_OFFSET-1 "-"
*MEAS_COND_AXIS_OFFSET-2 "-"
*MEAS_COND_AXIS_OFFSET-3 "-"
*MEAS_COND_AXIS_OFFSET-4 "-"
*MEAS_COND_AXIS_OFFSET-5 "-"
*MEAS_COND_AXIS_OFFSET-6 "-"
*MEAS_COND_AXIS_OFFSET-7 "-"
*MEAS_COND_AXIS_OFFSET-8 "-"
*MEAS_COND_AXIS_OFFSET-9 "-"
*MEAS_COND_AXIS_OFFSET-10 "-"
*MEAS_COND_AXIS_OFFSET-11 "-"
*MEAS_COND_AXIS_POSITION-0 "142.5900000000"
*MEAS_COND_AXIS_POSITION-1 "0.0000000000"
*MEAS_COND_AXIS_POSITION-2 "5.0000000000"
*MEAS_COND_AXIS_POSITION-3 "2.5deg"
*MEAS_COND_AXIS_POSITION-4 "10.0mm"
*MEAS_COND_AXIS_POSITION-5 "0.625deg"
*MEAS_COND_AXIS_POSITION-6 "8.0mm"
*MEAS_COND_AXIS_POSITION-7 "2.5deg"
*MEAS_COND_AXIS_POSITION-8 "13.0mm"
*MEAS_COND_AXIS_POSITION-9 "K-beta(x2)"
*MEAS_COND_AXIS_POSITION-10 "None"
*MEAS_COND_AXIS_POSITION-11 "49.0000000000"
*MEAS_COND_AXIS_UNIT-0 "deg"
*MEAS_COND_AXIS_UNIT-1 ""
*MEAS_COND_AXIS_UNIT-2 ""
*MEAS_COND_AXIS_UNIT-3 ""
*MEAS_COND_AXIS_UNIT-4 ""
*MEAS_COND_AXIS_UNIT-5 ""
*MEAS_COND_AXIS_UNIT-6 ""
*MEAS_COND_AXIS_UNIT-7 ""
*MEAS_COND_AXIS_UNIT-8 ""
*MEAS_COND_AXIS_UNIT-9 ""
*MEAS_COND_AXIS_UNIT-10 ""
*MEAS_COND_AXIS_UNIT-11 "div"
*MEAS_COND_CORRECTION_SLIT_COUNTERMONO "None"
*MEAS_COND_CORRECTION_SLIT_DS "0.625deg"
*MEAS_COND_CORRECTION_SLIT_FILTER "None"
*MEAS_COND_CORRECTION_SLIT_IHS "10.0mm"
*MEAS_COND_CORRECTION_SLIT_RS "13.0mm"
*MEAS_COND_CORRECTION_SLIT_SOLLER_INC "2.5deg"
*MEAS_COND_CORRECTION_SLIT_SOLLER_REC "2.5deg"
*MEAS_COND_CORRECTION_SLIT_SS "8.0mm"
*MEAS_COND_COUNTER_CNTLOSS_CORR "0.0000000000"
*MEAS_COND_COUNTER_PHABASE "49.0000000000"
*MEAS_COND_COUNTER_PHAWINDOW "8.0000000000"
*MEAS_COND_COUNTER_PHA_UNIT "div"
*MEAS_COND_COUNTER_TAUDIFF "0.2500000000"
*MEAS_COND_COUNTER_TAUINT "0.7500000000"
*MEAS_COND_IRRADIATION_MODE "OFF"
*MEAS_COND_IRRADIATION_WIDTH ""
*MEAS_COND_OPT_ATTR " "
*MEAS_COND_OPT_NAME ""
*MEAS_COND_UNSYMMETRIC_MODE "OFF"
*MEAS_COND_XG_CURRENT "15.0000000000"
*MEAS_COND_XG_VOLTAGE "40.0000000000"
*MEAS_COND_XG_WAVE_TYPE "Ka"
*MEAS_DATA_COUNT "13801.0000000000"
*MEAS_SCAN_AXIS_X "Theta/2-Theta"
*MEAS_SCAN_AXIS_X_INTERNAL "TwoThetaTheta"
*MEAS_SCAN_END_TIME "06/23/22 00:34:42"
*MEAS_SCAN_MODE "CONTINUOUS"
*MEAS_SCAN_MONITOR "0"
*MEAS_SCAN_RESOLUTION_X "0.005"
*MEAS_SCAN_SPEED "1.000"
*MEAS_SCAN_SPEED_UNIT "deg/min"
*MEAS_SCAN_START "2.0000000000"
*MEAS_SCAN_START_TIME "06/22/22 22:11:13"
*MEAS_SCAN_STEP "0.0100000000"
*MEAS_SCAN_STOP "140.0000000000"
*MEAS_SCAN_UNIT_X "deg"
*MEAS_SCAN_UNIT_Y "counts"
*SLIT_SYSTEM "0"
*RAS_HEADER_END
*RAS_INT_START
2.000 966.000 1.000
2.100 884.000 1.000
2.200 874.000 1.000
2.300 828.000 1.000
2.400 774.000 1.000
2.500 799.000 1.000
2.600 736.000 1.000
2.700 681.000 1.000
2.800 697.000 1.000
2.900 673.000 1.000
3.000 653.000 1.000
3.100 656.000 1.000
3.200 656.000 1.000
3.300 625.000 1.000
3.400 566.000 1.000
3.500 632.000 1.000
3.600 555.000 1.000
3.700 631.000 1.000
3.800 587.000 1.000
3.900 630.000 1.000
4.000 875.000 1.000
4.100 1387.000 1.000
4.200 1018.000 1.000
4.300 823.000 1.000
4.400 734.000 1.000
4.500 699.000 1.000
4.600 696.000 1.000
4.700 675.000 1.000
4.800 652.000 1.000
4.900 669.000 1.000
5.000 674.000 1.000
5.100 708.000 1.000
5.200 666.000 1.000
5.300 668.000 1.000
5.400 707.000 1.000
5.500 701.000 1.000
5.600 737.000 1.000
5.700 747.000 1.000
5.800 733.000 1.000
5.900 875.000 1.000
6.000 1021.000 1.000
6.100 1704.000 1.000
6.200 2941.000 1.000
6.300 2689.000 1.000
6.400 1634.000 1.000
6.500 1214.000 1.000
6.600 1105.000 1.000
6.700 1020.000 1.000
6.800 992.000 1.000
6.900 952.000 1.000
7.000 974.000 1.000
7.100 896.000 1.000
7.200 925.000 1.000
7.300 990.000 1.000
7.400 931.000 1.000
7.500 944.000 1.000
7.600 999.000 1.000
7.700 1024.000 1.000
7.800 987.000 1.000
7.900 1000.000 1.000
8.000 997.000 1.000
8.100 970.000 1.000
8.200 1006.000 1.000
8.300 1092.000 1.000
8.400 1184.000 1.000
8.500 1201.000 1.000
8.600 1173.000 1.000
8.700 1171.000 1.000
8.800 1215.000 1.000
8.900 1176.000 1.000
9.000 1237.000 1.000
9.100 1278.000 1.000
9.200 1218.000 1.000
9.300 1269.000 1.000
9.400 1293.000 1.000
9.500 1320.000 1.000
9.600 1348.000 1.000
9.700 1368.000 1.000
9.800 1335.000 1.000
9.900 1424.000 1.000
10.000 1428.000 1.000
10.100 1478.000 1.000
10.200 1543.000 1.000
10.300 1538.000 1.000
10.400 1580.000 1.000
10.500 1595.000 1.000
10.600 1603.000 1.000
10.700 1643.000 1.000
10.800 1643.000 1.000
10.900 1741.000 1.000
11.000 1758.000 1.000
11.100 1842.000 1.000
11.200 1875.000 1.000
11.300 1907.000 1.000
11.400 1995.000 1.000
11.500 1968.000 1.000
11.600 2097.000 1.000
11.700 2070.000 1.000
11.800 2146.000 1.000
11.900 2242.000 1.000
12.000 2303.000 1.000
12.100 2318.000 1.000
12.200 2306.000 1.000
12.300 2368.000 1.000
12.400 2481.000 1.000
12.500 2519.000 1.000
12.600 2612.000 1.000
12.700 2652.000 1.000
12.800 2727.000 1.000
12.900 2716.000 1.000
13.000 2787.000 1.000
13.100 2876.000 1.000
13.200 2933.000 1.000
13.300 2947.000 1.000
13.400 3009.000 1.000
13.500 3040.000 1.000
13.600 3103.000 1.000
13.700 3099.000 1.000
13.800 3177.000 1.000
13.900 3186.000 1.000
14.000 3171.000 1.000
14.100 3239.000 1.000
14.200 3164.000 1.000
14.300 3286.000 1.000
14.400 3223.000 1.000
14.500 3236.000 1.000
14.600 3212.000 1.000
14.700 3208.000 1.000
14.800 3166.000 1.000
14.900 3159.000 1.000
15.000 3164.000 1.000
15.100 3005.000 1.000
15.200 3106.000 1.000
15.300 2989.000 1.000
15.400 2970.000 1.000
15.500 2967.000 1.000
15.600 2875.000 1.000
15.700 2898.000 1.000
15.800 2810.000 1.000
15.900 2822.000 1.000
16.000 2757.000 1.000
16.100 2707.000 1.000
16.200 2672.000 1.000
16.300 2611.000 1.000
16.400 2616.000 1.000
16.500 2513.000 1.000
16.600 2514.000 1.000
16.700 2442.000 1.000
16.800 2380.000 1.000
16.900 2433.000 1.000
17.000 2399.000 1.000
17.100 2323.000 1.000
17.200 2253.000 1.000
17.300 2282.000 1.000
17.400 2243.000 1.000
17.500 2208.000 1.000
17.600 2127.000 1.000
17.700 2107.000 1.000
17.800 2135.000 1.000
17.900 1989.000 1.000
18.000 2006.000 1.000
18.100 2040.000 1.000
18.200 1975.000 1.000
18.300 1944.000 1.000
18.400 1958.000 1.000
18.500 1916.000 1.000
18.600 1917.000 1.000
18.700 1894.000 1.000
18.800 1824.000 1.000
18.900 1811.000 1.000
19.000 1808.000 1.000
19.100 1770.000 1.000
19.200 1738.000 1.000
19.300 1749.000 1.000
19.400 1711.000 1.000
19.500 1740.000 1.000
19.600 1622.000 1.000
19.700 1704.000 1.000
19.800 1628.000 1.000
19.900 1683.000 1.000
20.000 1636.000 1.000
20.100 1584.000 1.000
20.200 1665.000 1.000
20.300 1691.000 1.000
20.400 1666.000 1.000
20.500 1832.000 1.000
20.600 1882.000 1.000
20.700 2020.000 1.000
20.800 2445.000 1.000
20.900 3538.000 1.000
21.000 5523.000 1.000
21.100 6952.000 1.000
21.200 5215.000 1.000
21.300 2991.000 1.000
21.400 2143.000 1.000
21.500 1795.000 1.000
21.600 1557.000 1.000
21.700 1462.000 1.000
21.800 1430.000 1.000
21.900 1384.000 1.000
22.000 1346.000 1.000
22.100 1342.000 1.000
22.200 1285.000 1.000
22.300 1282.000 1.000
22.400 1250.000 1.000
22.500 1292.000 1.000
22.600 1319.000 1.000
22.700 1304.000 1.000
22.800 1353.000 1.000
22.900 1430.000 1.000
23.000 1571.000 1.000
23.100 1835.000 1.000
23.200 2376.000 1.000
23.300 3697.000 1.000
23.400 4880.000 1.000
23.500 4257.000 1.000
23.600 2747.000 1.000
23.700 1790.000 1.000
23.800 1366.000 1.000
23.900 1194.000 1.000
24.000 1053.000 1.000
24.100 1033.000 1.000
24.200 956.000 1.000
24.300 905.000 1.000
24.400 914.000 1.000
24.500 883.000 1.000
24.600 875.000 1.000
24.700 874.000 1.000
24.800 857.000 1.000
24.900 825.000 1.000
25.000 790.000 1.000
25.100 794.000 1.000
25.200 775.000 1.000
25.300 802.000 1.000
25.400 766.000 1.000
25.500 744.000 1.000
25.600 747.000 1.000
25.700 696.000 1.000
25.800 773.000 1.000
25.900 698.000 1.000
26.000 679.000 1.000
26.100 715.000 1.000
26.200 709.000 1.000
26.300 709.000 1.000
26.400 671.000 1.000
26.500 701.000 1.000
26.600 676.000 1.000
26.700 665.000 1.000
26.800 676.000 1.000
26.900 672.000 1.000
27.000 670.000 1.000
27.100 638.000 1.000
27.200 666.000 1.000
27.300 657.000 1.000
27.400 652.000 1.000
27.500 633.000 1.000
27.600 646.000 1.000
27.700 657.000 1.000
27.800 615.000 1.000
27.900 624.000 1.000
28.000 608.000 1.000
28.100 617.000 1.000
28.200 644.000 1.000
28.300 664.000 1.000
28.400 613.000 1.000
28.500 598.000 1.000
28.600 599.000 1.000
28.700 612.000 1.000
28.800 619.000 1.000
28.900 595.000 1.000
29.000 577.000 1.000
29.100 611.000 1.000
29.200 607.000 1.000
29.300 604.000 1.000
29.400 636.000 1.000
29.500 635.000 1.000
29.600 610.000 1.000
29.700 603.000 1.000
29.800 561.000 1.000
29.900 591.000 1.000
30.000 582.000 1.000
30.100 562.000 1.000
30.200 550.000 1.000
30.300 564.000 1.000
30.400 574.000 1.000
30.500 572.000 1.000
30.600 560.000 1.000
30.700 545.000 1.000
30.800 551.000 1.000
30.900 582.000 1.000
31.000 575.000 1.000
31.100 558.000 1.000
31.200 543.000 1.000
31.300 566.000 1.000
31.400 545.000 1.000
31.500 547.000 1.000
31.600 538.000 1.000
31.700 536.000 1.000
31.800 520.000 1.000
31.900 519.000 1.000
32.000 537.000 1.000
32.100 498.000 1.000
32.200 547.000 1.000
32.300 498.000 1.000
32.400 540.000 1.000
32.500 537.000 1.000
32.600 516.000 1.000
32.700 530.000 1.000
32.800 537.000 1.000
32.900 504.000 1.000
33.000 500.000 1.000
33.100 515.000 1.000
33.200 529.000 1.000
33.300 511.000 1.000
33.400 523.000 1.000
33.500 511.000 1.000
33.600 491.000 1.000
33.700 515.000 1.000
33.800 541.000 1.000
33.900 537.000 1.000
34.000 551.000 1.000
34.100 572.000 1.000
34.200 539.000 1.000
34.300 551.000 1.000
34.400 545.000 1.000
34.500 508.000 1.000
34.600 523.000 1.000
34.700 553.000 1.000
34.800 531.000 1.000
34.900 536.000 1.000
35.000 537.000 1.000
35.100 522.000 1.000
35.200 552.000 1.000
35.300 558.000 1.000
35.400 546.000 1.000
35.500 535.000 1.000
35.600 584.000 1.000
35.700 589.000 1.000
35.800 632.000 1.000
35.900 591.000 1.000
36.000 588.000 1.000
36.100 573.000 1.000
36.200 559.000 1.000
36.300 624.000 1.000
36.400 609.000 1.000
36.500 773.000 1.000
36.600 927.000 1.000
36.700 967.000 1.000
36.800 942.000 1.000
36.900 900.000 1.000
37.000 924.000 1.000
37.100 969.000 1.000
37.200 994.000 1.000
37.300 1330.000 1.000
37.400 1673.000 1.000
37.500 1996.000 1.000
37.600 2735.000 1.000
37.700 7149.000 1.000
37.800 48940.000 1.000
37.900 62286.000 1.000
38.000 22720.000 1.000
38.100 3778.000 1.000
38.200 2213.000 1.000
38.300 1396.000 1.000
38.400 1105.000 1.000
38.500 971.000 1.000
38.600 873.000 1.000
38.700 857.000 1.000
38.800 831.000 1.000
38.900 795.000 1.000
39.000 801.000 1.000
39.100 744.000 1.000
39.200 760.000 1.000
39.300 769.000 1.000
39.400 782.000 1.000
39.500 740.000 1.000
39.600 816.000 1.000
39.700 783.000 1.000
39.800 790.000 1.000
39.900 714.000 1.000
40.000 712.000 1.000
40.100 736.000 1.000
40.200 688.000 1.000
40.300 652.000 1.000
40.400 639.000 1.000
40.500 603.000 1.000
40.600 608.000 1.000
40.700 590.000 1.000
40.800 580.000 1.000
40.900 595.000 1.000
41.000 590.000 1.000
41.100 595.000 1.000
41.200 600.000 1.000
41.300 606.000 1.000
41.400 575.000 1.000
41.500 608.000 1.000
41.600 542.000 1.000
41.700 538.000 1.000
41.800 524.000 1.000
41.900 534.000 1.000
42.000 516.000 1.000
42.100 519.000 1.000
42.200 525.000 1.000
42.300 532.000 1.000
42.400 562.000 1.000
42.500 657.000 1.000
42.600 660.000 1.000
42.700 644.000 1.000
42.800 639.000 1.000
42.900 638.000 1.000
43.000 668.000 1.000
43.100 605.000 1.000
43.200 641.000 1.000
43.300 633.000 1.000
43.400 650.000 1.000
43.500 726.000 1.000
43.600 885.000 1.000
43.700 984.000 1.000
43.800 1469.000 1.000
43.900 2818.000 1.000
44.000 16205.000 1.000
44.100 21482.000 1.000
44.200 13638.000 1.000
44.300 2161.000 1.000
44.400 1165.000 1.000
44.500 869.000 1.000
44.600 682.000 1.000
44.700 580.000 1.000
44.800 500.000 1.000
44.900 474.000 1.000
45.000 464.000 1.000
45.100 435.000 1.000
45.200 456.000 1.000
45.300 431.000 1.000
45.400 406.000 1.000
45.500 392.000 1.000
45.600 413.000 1.000
45.700 371.000 1.000
45.800 386.000 1.000
45.900 345.000 1.000
46.000 379.000 1.000
46.100 406.000 1.000
46.200 366.000 1.000
46.300 374.000 1.000
46.400 378.000 1.000
46.500 365.000 1.000
46.600 368.000 1.000
46.700 349.000 1.000
46.800 368.000 1.000
46.900 346.000 1.000
47.000 333.000 1.000
47.100 346.000 1.000
47.200 346.000 1.000
47.300 331.000 1.000
47.400 327.000 1.000
47.500 314.000 1.000
47.600 328.000 1.000
47.700 307.000 1.000
47.800 331.000 1.000
47.900 298.000 1.000
48.000 326.000 1.000
48.100 311.000 1.000
48.200 320.000 1.000
48.300 323.000 1.000
48.400 315.000 1.000
48.500 306.000 1.000
48.600 291.000 1.000
48.700 288.000 1.000
48.800 311.000 1.000
48.900 268.000 1.000
49.000 260.000 1.000
49.100 274.000 1.000
49.200 262.000 1.000
49.300 277.000 1.000
49.400 266.000 1.000
49.500 267.000 1.000
49.600 273.000 1.000
49.700 247.000 1.000
49.800 260.000 1.000
49.900 283.000 1.000
50.000 240.000 1.000
50.100 270.000 1.000
50.200 259.000 1.000
50.300 249.000 1.000
50.400 252.000 1.000
50.500 245.000 1.000
50.600 254.000 1.000
50.700 239.000 1.000
50.800 256.000 1.000
50.900 246.000 1.000
51.000 239.000 1.000
51.100 236.000 1.000
51.200 251.000 1.000
51.300 246.000 1.000
51.400 238.000 1.000
51.500 243.000 1.000
51.600 233.000 1.000
51.700 236.000 1.000
51.800 256.000 1.000
51.900 245.000 1.000
52.000 250.000 1.000
52.100 254.000 1.000
52.200 218.000 1.000
52.300 245.000 1.000
52.400 251.000 1.000
52.500 250.000 1.000
52.600 267.000 1.000
52.700 250.000 1.000
52.800 219.000 1.000
52.900 237.000 1.000
53.000 220.000 1.000
53.100 224.000 1.000
53.200 217.000 1.000
53.300 226.000 1.000
53.400 232.000 1.000
53.500 234.000 1.000
53.600 224.000 1.000
53.700 236.000 1.000
53.800 215.000 1.000
53.900 228.000 1.000
54.000 207.000 1.000
54.100 204.000 1.000
54.200 217.000 1.000
54.300 224.000 1.000
54.400 216.000 1.000
54.500 222.000 1.000
54.600 206.000 1.000
54.700 231.000 1.000
54.800 225.000 1.000
54.900 211.000 1.000
55.000 208.000 1.000
55.100 209.000 1.000
55.200 192.000 1.000
55.300 191.000 1.000
55.400 208.000 1.000
55.500 213.000 1.000
55.600 213.000 1.000
55.700 211.000 1.000
55.800 206.000 1.000
55.900 195.000 1.000
56.000 190.000 1.000
56.100 209.000 1.000
56.200 217.000 1.000
56.300 213.000 1.000
56.400 190.000 1.000
56.500 181.000 1.000
56.600 189.000 1.000
56.700 186.000 1.000
56.800 203.000 1.000
56.900 198.000 1.000
57.000 216.000 1.000
57.100 191.000 1.000
57.200 195.000 1.000
57.300 198.000 1.000
57.400 204.000 1.000
57.500 180.000 1.000
57.600 211.000 1.000
57.700 199.000 1.000
57.800 197.000 1.000
57.900 214.000 1.000
58.000 188.000 1.000
58.100 198.000 1.000
58.200 197.000 1.000
58.300 200.000 1.000
58.400 189.000 1.000
58.500 192.000 1.000
58.600 188.000 1.000
58.700 193.000 1.000
58.800 192.000 1.000
58.900 203.000 1.000
59.000 183.000 1.000
59.100 193.000 1.000
59.200 203.000 1.000
59.300 184.000 1.000
59.400 195.000 1.000
59.500 180.000 1.000
59.600 181.000 1.000
59.700 176.000 1.000
59.800 177.000 1.000
59.900 190.000 1.000
60.000 186.000 1.000
60.100 190.000 1.000
60.200 173.000 1.000
60.300 174.000 1.000
60.400 186.000 1.000
60.500 182.000 1.000
60.600 203.000 1.000
60.700 208.000 1.000
60.800 185.000 1.000
60.900 191.000 1.000
61.000 197.000 1.000
61.100 177.000 1.000
61.200 192.000 1.000
61.300 191.000 1.000
61.400 194.000 1.000
61.500 192.000 1.000
61.600 179.000 1.000
61.700 204.000 1.000
61.800 197.000 1.000
61.900 204.000 1.000
62.000 191.000 1.000
62.100 199.000 1.000
62.200 192.000 1.000
62.300 175.000 1.000
62.400 186.000 1.000
62.500 194.000 1.000
62.600 188.000 1.000
62.700 197.000 1.000
62.800 177.000 1.000
62.900 199.000 1.000
63.000 203.000 1.000
63.100 189.000 1.000
63.200 189.000 1.000
63.300 192.000 1.000
63.400 197.000 1.000
63.500 197.000 1.000
63.600 212.000 1.000
63.700 207.000 1.000
63.800 235.000 1.000
63.900 261.000 1.000
64.000 305.000 1.000
64.100 354.000 1.000
64.200 829.000 1.000
64.300 3352.000 1.000
64.400 1194.000 1.000
64.500 1715.000 1.000
64.600 446.000 1.000
64.700 287.000 1.000
64.800 251.000 1.000
64.900 198.000 1.000
65.000 205.000 1.000
65.100 201.000 1.000
65.200 195.000 1.000
65.300 188.000 1.000
65.400 187.000 1.000
65.500 179.000 1.000
65.600 190.000 1.000
65.700 175.000 1.000
65.800 192.000 1.000
65.900 189.000 1.000
66.000 193.000 1.000
66.100 169.000 1.000
66.200 187.000 1.000
66.300 194.000 1.000
66.400 179.000 1.000
66.500 189.000 1.000
66.600 188.000 1.000
66.700 182.000 1.000
66.800 167.000 1.000
66.900 189.000 1.000
67.000 183.000 1.000
67.100 189.000 1.000
67.200 187.000 1.000
67.300 180.000 1.000
67.400 177.000 1.000
67.500 195.000 1.000
67.600 172.000 1.000
67.700 183.000 1.000
67.800 182.000 1.000
67.900 178.000 1.000
68.000 174.000 1.000
68.100 179.000 1.000
68.200 179.000 1.000
68.300 180.000 1.000
68.400 170.000 1.000
68.500 180.000 1.000
68.600 176.000 1.000
68.700 193.000 1.000
68.800 186.000 1.000
68.900 183.000 1.000
69.000 178.000 1.000
69.100 166.000 1.000
69.200 172.000 1.000
69.300 178.000 1.000
69.400 162.000 1.000
69.500 173.000 1.000
69.600 200.000 1.000
69.700 176.000 1.000
69.800 178.000 1.000
69.900 160.000 1.000
70.000 191.000 1.000
70.100 159.000 1.000
70.200 192.000 1.000
70.300 180.000 1.000
70.400 175.000 1.000
70.500 174.000 1.000
70.600 182.000 1.000
70.700 187.000 1.000
70.800 189.000 1.000
70.900 165.000 1.000
71.000 180.000 1.000
71.100 185.000 1.000
71.200 186.000 1.000
71.300 180.000 1.000
71.400 183.000 1.000
71.500 177.000 1.000
71.600 182.000 1.000
71.700 212.000 1.000
71.800 190.000 1.000
71.900 180.000 1.000
72.000 182.000 1.000
72.100 190.000 1.000
72.200 212.000 1.000
72.300 222.000 1.000
72.400 195.000 1.000
72.500 206.000 1.000
72.600 215.000 1.000
72.700 219.000 1.000
72.800 216.000 1.000
72.900 209.000 1.000
73.000 219.000 1.000
73.100 230.000 1.000
73.200 239.000 1.000
73.300 240.000 1.000
73.400 254.000 1.000
73.500 271.000 1.000
73.600 273.000 1.000
73.700 286.000 1.000
73.800 289.000 1.000
73.900 276.000 1.000
74.000 307.000 1.000
74.100 348.000 1.000
74.200 372.000 1.000
74.300 369.000 1.000
74.400 387.000 1.000
74.500 362.000 1.000
74.600 337.000 1.000
74.700 316.000 1.000
74.800 323.000 1.000
74.900 322.000 1.000
75.000 314.000 1.000
75.100 308.000 1.000
75.200 308.000 1.000
75.300 331.000 1.000
75.400 292.000 1.000
75.500 310.000 1.000
75.600 300.000 1.000
75.700 297.000 1.000
75.800 324.000 1.000
75.900 314.000 1.000
76.000 289.000 1.000
76.100 313.000 1.000
76.200 305.000 1.000
76.300 281.000 1.000
76.400 311.000 1.000
76.500 309.000 1.000
76.600 305.000 1.000
76.700 341.000 1.000
76.800 373.000 1.000
76.900 489.000 1.000
77.000 586.000 1.000
77.100 765.000 1.000
77.200 1759.000 1.000
77.300 6029.000 1.000
77.400 3670.000 1.000
77.500 2713.000 1.000
77.600 3188.000 1.000
77.700 851.000 1.000
77.800 512.000 1.000
77.900 425.000 1.000
78.000 359.000 1.000
78.100 323.000 1.000
78.200 322.000 1.000
78.300 309.000 1.000
78.400 327.000 1.000
78.500 321.000 1.000
78.600 285.000 1.000
78.700 299.000 1.000
78.800 286.000 1.000
78.900 276.000 1.000
79.000 277.000 1.000
79.100 288.000 1.000
79.200 260.000 1.000
79.300 266.000 1.000
79.400 263.000 1.000
79.500 258.000 1.000
79.600 247.000 1.000
79.700 243.000 1.000
79.800 235.000 1.000
79.900 262.000 1.000
80.000 245.000 1.000
80.100 243.000 1.000
80.200 236.000 1.000
80.300 238.000 1.000
80.400 239.000 1.000
80.500 238.000 1.000
80.600 228.000 1.000
80.700 242.000 1.000
80.800 239.000 1.000
80.900 268.000 1.000
81.000 322.000 1.000
81.100 372.000 1.000
81.200 437.000 1.000
81.300 616.000 1.000
81.400 1778.000 1.000
81.500 5691.000 1.000
81.600 1975.000 1.000
81.700 2091.000 1.000
81.800 2246.000 1.000
81.900 565.000 1.000
82.000 366.000 1.000
82.100 289.000 1.000
82.200 241.000 1.000
82.300 210.000 1.000
82.400 206.000 1.000
82.500 215.000 1.000
82.600 195.000 1.000
82.700 196.000 1.000
82.800 200.000 1.000
82.900 184.000 1.000
83.000 180.000 1.000
83.100 195.000 1.000
83.200 186.000 1.000
83.300 194.000 1.000
83.400 177.000 1.000
83.500 188.000 1.000
83.600 174.000 1.000
83.700 179.000 1.000
83.800 177.000 1.000
83.900 179.000 1.000
84.000 175.000 1.000
84.100 158.000 1.000
84.200 170.000 1.000
84.300 169.000 1.000
84.400 182.000 1.000
84.500 177.000 1.000
84.600 169.000 1.000
84.700 158.000 1.000
84.800 176.000 1.000
84.900 157.000 1.000
85.000 173.000 1.000
85.100 152.000 1.000
85.200 156.000 1.000
85.300 162.000 1.000
85.400 162.000 1.000
85.500 167.000 1.000
85.600 153.000 1.000
85.700 158.000 1.000
85.800 158.000 1.000
85.900 152.000 1.000
86.000 152.000 1.000
86.100 172.000 1.000
86.200 170.000 1.000
86.300 159.000 1.000
86.400 158.000 1.000
86.500 168.000 1.000
86.600 152.000 1.000
86.700 152.000 1.000
86.800 150.000 1.000
86.900 159.000 1.000
87.000 161.000 1.000
87.100 143.000 1.000
87.200 140.000 1.000
87.300 161.000 1.000
87.400 155.000 1.000
87.500 152.000 1.000
87.600 158.000 1.000
87.700 155.000 1.000
87.800 147.000 1.000
87.900 136.000 1.000
88.000 158.000 1.000
88.100 140.000 1.000
88.200 141.000 1.000
88.300 138.000 1.000
88.400 145.000 1.000
88.500 127.000 1.000
88.600 149.000 1.000
88.700 150.000 1.000
88.800 145.000 1.000
88.900 135.000 1.000
89.000 155.000 1.000
89.100 149.000 1.000
89.200 137.000 1.000
89.300 146.000 1.000
89.400 148.000 1.000
89.500 130.000 1.000
89.600 122.000 1.000
89.700 139.000 1.000
89.800 130.000 1.000
89.900 142.000 1.000
90.000 133.000 1.000
90.100 136.000 1.000
90.200 139.000 1.000
90.300 127.000 1.000
90.400 135.000 1.000
90.500 133.000 1.000
90.600 138.000 1.000
90.700 136.000 1.000
90.800 130.000 1.000
90.900 127.000 1.000
91.000 132.000 1.000
91.100 130.000 1.000
91.200 133.000 1.000
91.300 149.000 1.000
91.400 137.000 1.000
91.500 132.000 1.000
91.600 140.000 1.000
91.700 130.000 1.000
91.800 133.000 1.000
91.900 139.000 1.000
92.000 144.000 1.000
92.100 128.000 1.000
92.200 135.000 1.000
92.300 131.000 1.000
92.400 134.000 1.000
92.500 134.000 1.000
92.600 141.000 1.000
92.700 143.000 1.000
92.800 119.000 1.000
92.900 133.000 1.000
93.000 133.000 1.000
93.100 117.000 1.000
93.200 119.000 1.000
93.300 128.000 1.000
93.400 138.000 1.000
93.500 126.000 1.000
93.600 136.000 1.000
93.700 114.000 1.000
93.800 138.000 1.000
93.900 148.000 1.000
94.000 134.000 1.000
94.100 131.000 1.000
94.200 123.000 1.000
94.300 158.000 1.000
94.400 134.000 1.000
94.500 130.000 1.000
94.600 120.000 1.000
94.700 116.000 1.000
94.800 126.000 1.000
94.900 121.000 1.000
95.000 131.000 1.000
95.100 127.000 1.000
95.200 127.000 1.000
95.300 131.000 1.000
95.400 143.000 1.000
95.500 126.000 1.000
95.600 128.000 1.000
95.700 130.000 1.000
95.800 136.000 1.000
95.900 123.000 1.000
96.000 138.000 1.000
96.100 125.000 1.000
96.200 119.000 1.000
96.300 127.000 1.000
96.400 125.000 1.000
96.500 149.000 1.000
96.600 133.000 1.000
96.700 130.000 1.000
96.800 133.000 1.000
96.900 134.000 1.000
97.000 139.000 1.000
97.100 131.000 1.000
97.200 140.000 1.000
97.300 159.000 1.000
97.400 156.000 1.000
97.500 181.000 1.000
97.600 202.000 1.000
97.700 245.000 1.000
97.800 438.000 1.000
97.900 1012.000 1.000
98.000 1634.000 1.000
98.100 555.000 1.000
98.200 524.000 1.000
98.300 936.000 1.000
98.400 415.000 1.000
98.500 197.000 1.000
98.600 173.000 1.000
98.700 174.000 1.000
98.800 146.000 1.000
98.900 148.000 1.000
99.000 140.000 1.000
99.100 141.000 1.000
99.200 132.000 1.000
99.300 134.000 1.000
99.400 126.000 1.000
99.500 133.000 1.000
99.600 134.000 1.000
99.700 130.000 1.000
99.800 133.000 1.000
99.900 128.000 1.000
100.000 135.000 1.000
100.100 141.000 1.000
100.200 125.000 1.000
100.300 119.000 1.000
100.400 131.000 1.000
100.500 137.000 1.000
100.600 125.000 1.000
100.700 114.000 1.000
100.800 124.000 1.000
100.900 134.000 1.000
101.000 124.000 1.000
101.100 135.000 1.000
101.200 139.000 1.000
101.300 122.000 1.000
101.400 118.000 1.000
101.500 120.000 1.000
101.600 136.000 1.000
101.700 132.000 1.000
101.800 131.000 1.000
101.900 121.000 1.000
102.000 127.000 1.000
102.100 136.000 1.000
102.200 106.000 1.000
102.300 123.000 1.000
102.400 118.000 1.000
102.500 132.000 1.000
102.600 131.000 1.000
102.700 130.000 1.000
102.800 122.000 1.000
102.900 126.000 1.000
103.000 126.000 1.000
103.100 125.000 1.000
103.200 126.000 1.000
103.300 112.000 1.000
103.400 125.000 1.000
103.500 138.000 1.000
103.600 120.000 1.000
103.700 117.000 1.000
103.800 111.000 1.000
103.900 127.000 1.000
104.000 128.000 1.000
104.100 129.000 1.000
104.200 131.000 1.000
104.300 119.000 1.000
104.400 129.000 1.000
104.500 117.000 1.000
104.600 123.000 1.000
104.700 120.000 1.000
104.800 131.000 1.000
104.900 124.000 1.000
105.000 118.000 1.000
105.100 126.000 1.000
105.200 122.000 1.000
105.300 113.000 1.000
105.400 116.000 1.000
105.500 128.000 1.000
105.600 133.000 1.000
105.700 126.000 1.000
105.800 112.000 1.000
105.900 116.000 1.000
106.000 128.000 1.000
106.100 129.000 1.000
106.200 119.000 1.000
106.300 120.000 1.000
106.400 121.000 1.000
106.500 120.000 1.000
106.600 121.000 1.000
106.700 131.000 1.000
106.800 113.000 1.000
106.900 132.000 1.000
107.000 135.000 1.000
107.100 127.000 1.000
107.200 121.000 1.000
107.300 125.000 1.000
107.400 124.000 1.000
107.500 123.000 1.000
107.600 124.000 1.000
107.700 137.000 1.000
107.800 129.000 1.000
107.900 119.000 1.000
108.000 136.000 1.000
108.100 128.000 1.000
108.200 129.000 1.000
108.300 139.000 1.000
108.400 132.000 1.000
108.500 132.000 1.000
108.600 135.000 1.000
108.700 127.000 1.000
108.800 132.000 1.000
108.900 124.000 1.000
109.000 124.000 1.000
109.100 138.000 1.000
109.200 129.000 1.000
109.300 139.000 1.000
109.400 135.000 1.000
109.500 130.000 1.000
109.600 138.000 1.000
109.700 136.000 1.000
109.800 149.000 1.000
109.900 154.000 1.000
110.000 162.000 1.000
110.100 159.000 1.000
110.200 172.000 1.000
110.300 207.000 1.000
110.400 235.000 1.000
110.500 351.000 1.000
110.600 591.000 1.000
110.700 1098.000 1.000
110.800 1134.000 1.000
110.900 483.000 1.000
111.000 434.000 1.000
111.100 598.000 1.000
111.200 696.000 1.000
111.300 297.000 1.000
111.400 220.000 1.000
111.500 199.000 1.000
111.600 168.000 1.000
111.700 159.000 1.000
111.800 154.000 1.000
111.900 163.000 1.000
112.000 148.000 1.000
112.100 147.000 1.000
112.200 144.000 1.000
112.300 148.000 1.000
112.400 149.000 1.000
112.500 141.000 1.000
112.600 146.000 1.000
112.700 145.000 1.000
112.800 140.000 1.000
112.900 132.000 1.000
113.000 142.000 1.000
113.100 139.000 1.000
113.200 142.000 1.000
113.300 146.000 1.000
113.400 150.000 1.000
113.500 137.000 1.000
113.600 147.000 1.000
113.700 158.000 1.000
113.800 144.000 1.000
113.900 140.000 1.000
114.000 147.000 1.000
114.100 153.000 1.000
114.200 157.000 1.000
114.300 168.000 1.000
114.400 162.000 1.000
114.500 176.000 1.000
114.600 185.000 1.000
114.700 180.000 1.000
114.800 231.000 1.000
114.900 279.000 1.000
115.000 438.000 1.000
115.100 777.000 1.000
115.200 1133.000 1.000
115.300 758.000 1.000
115.400 396.000 1.000
115.500 413.000 1.000
115.600 557.000 1.000
115.700 636.000 1.000
115.800 302.000 1.000
115.900 221.000 1.000
116.000 205.000 1.000
116.100 181.000 1.000
116.200 166.000 1.000
116.300 172.000 1.000
116.400 150.000 1.000
116.500 157.000 1.000
116.600 149.000 1.000
116.700 143.000 1.000
116.800 146.000 1.000
116.900 151.000 1.000
117.000 145.000 1.000
117.100 144.000 1.000
117.200 139.000 1.000
117.300 148.000 1.000
117.400 124.000 1.000
117.500 134.000 1.000
117.600 142.000 1.000
117.700 138.000 1.000
117.800 142.000 1.000
117.900 149.000 1.000
118.000 140.000 1.000
118.100 145.000 1.000
118.200 150.000 1.000
118.300 142.000 1.000
118.400 128.000 1.000
118.500 146.000 1.000
118.600 132.000 1.000
118.700 152.000 1.000
118.800 142.000 1.000
118.900 139.000 1.000
119.000 137.000 1.000
119.100 148.000 1.000
119.200 160.000 1.000
119.300 141.000 1.000
119.400 136.000 1.000
119.500 139.000 1.000
119.600 142.000 1.000
119.700 137.000 1.000
119.800 145.000 1.000
119.900 138.000 1.000
120.000 142.000 1.000
120.100 131.000 1.000
120.200 136.000 1.000
120.300 143.000 1.000
120.400 145.000 1.000
120.500 147.000 1.000
120.600 154.000 1.000
120.700 129.000 1.000
120.800 143.000 1.000
120.900 142.000 1.000
121.000 144.000 1.000
121.100 141.000 1.000
121.200 134.000 1.000
121.300 147.000 1.000
121.400 145.000 1.000
121.500 148.000 1.000
121.600 144.000 1.000
121.700 137.000 1.000
121.800 145.000 1.000
121.900 146.000 1.000
122.000 150.000 1.000
122.100 139.000 1.000
122.200 128.000 1.000
122.300 149.000 1.000
122.400 148.000 1.000
122.500 150.000 1.000
122.600 139.000 1.000
122.700 148.000 1.000
122.800 150.000 1.000
122.900 145.000 1.000
123.000 143.000 1.000
123.100 140.000 1.000
123.200 149.000 1.000
123.300 129.000 1.000
123.400 143.000 1.000
123.500 139.000 1.000
123.600 143.000 1.000
123.700 148.000 1.000
123.800 136.000 1.000
123.900 142.000 1.000
124.000 163.000 1.000
124.100 141.000 1.000
124.200 160.000 1.000
124.300 145.000 1.000
124.400 151.000 1.000
124.500 155.000 1.000
124.600 153.000 1.000
124.700 144.000 1.000
124.800 134.000 1.000
124.900 146.000 1.000
125.000 149.000 1.000
125.100 149.000 1.000
125.200 170.000 1.000
125.300 162.000 1.000
125.400 132.000 1.000
125.500 135.000 1.000
125.600 144.000 1.000
125.700 147.000 1.000
125.800 147.000 1.000
125.900 138.000 1.000
126.000 125.000 1.000
126.100 146.000 1.000
126.200 149.000 1.000
126.300 148.000 1.000
126.400 146.000 1.000
126.500 146.000 1.000
126.600 150.000 1.000
126.700 155.000 1.000
126.800 145.000 1.000
126.900 140.000 1.000
127.000 146.000 1.000
127.100 149.000 1.000
127.200 158.000 1.000
127.300 152.000 1.000
127.400 148.000 1.000
127.500 151.000 1.000
127.600 152.000 1.000
127.700 161.000 1.000
127.800 169.000 1.000
127.900 166.000 1.000
128.000 170.000 1.000
128.100 151.000 1.000
128.200 167.000 1.000
128.300 165.000 1.000
128.400 172.000 1.000
128.500 163.000 1.000
128.600 147.000 1.000
128.700 153.000 1.000
128.800 172.000 1.000
128.900 170.000 1.000
129.000 155.000 1.000
129.100 170.000 1.000
129.200 153.000 1.000
129.300 157.000 1.000
129.400 161.000 1.000
129.500 143.000 1.000
129.600 178.000 1.000
129.700 175.000 1.000
129.800 158.000 1.000
129.900 168.000 1.000
130.000 160.000 1.000
130.100 168.000 1.000
130.200 170.000 1.000
130.300 153.000 1.000
130.400 174.000 1.000
130.500 165.000 1.000
130.600 152.000 1.000
130.700 173.000 1.000
130.800 162.000 1.000
130.900 165.000 1.000
131.000 175.000 1.000
131.100 177.000 1.000
131.200 161.000 1.000
131.300 170.000 1.000
131.400 178.000 1.000
131.500 161.000 1.000
131.600 191.000 1.000
131.700 168.000 1.000
131.800 172.000 1.000
131.900 165.000 1.000
132.000 168.000 1.000
132.100 186.000 1.000
132.200 181.000 1.000
132.300 197.000 1.000
132.400 176.000 1.000
132.500 181.000 1.000
132.600 184.000 1.000
132.700 180.000 1.000
132.800 183.000 1.000
132.900 196.000 1.000
133.000 184.000 1.000
133.100 192.000 1.000
133.200 199.000 1.000
133.300 182.000 1.000
133.400 186.000 1.000
133.500 167.000 1.000
133.600 180.000 1.000
133.700 206.000 1.000
133.800 191.000 1.000
133.900 203.000 1.000
134.000 197.000 1.000
134.100 216.000 1.000
134.200 234.000 1.000
134.300 230.000 1.000
134.400 225.000 1.000
134.500 250.000 1.000
134.600 245.000 1.000
134.700 272.000 1.000
134.800 278.000 1.000
134.900 331.000 1.000
135.000 406.000 1.000
135.100 515.000 1.000
135.200 724.000 1.000
135.300 1088.000 1.000
135.400 1595.000 1.000
135.500 2157.000 1.000
135.600 1972.000 1.000
135.700 950.000 1.000
135.800 702.000 1.000
135.900 642.000 1.000
136.000 730.000 1.000
136.100 968.000 1.000
136.200 1186.000 1.000
136.300 1097.000 1.000
136.400 606.000 1.000
136.500 402.000 1.000
136.600 293.000 1.000
136.700 281.000 1.000
136.800 250.000 1.000
136.900 233.000 1.000
137.000 219.000 1.000
137.100 213.000 1.000
137.200 212.000 1.000
137.300 231.000 1.000
137.400 202.000 1.000
137.500 212.000 1.000
137.600 211.000 1.000
137.700 202.000 1.000
137.800 200.000 1.000
137.900 211.000 1.000
138.000 220.000 1.000
138.100 212.000 1.000
138.200 196.000 1.000
138.300 211.000 1.000
138.400 181.000 1.000
138.500 210.000 1.000
138.600 187.000 1.000
138.700 192.000 1.000
138.800 197.000 1.000
138.900 193.000 1.000
139.000 205.000 1.000
139.100 170.000 1.000
139.200 179.000 1.000
139.300 176.000 1.000
139.400 195.000 1.000
139.500 203.000 1.000
139.600 193.000 1.000
139.700 194.000 1.000
139.800 205.000 1.000
139.900 189.000 1.000
140.000 186.000 1.000
*RAS_INT_END
*RAS_DATA_END