File: Si_Halter.ras
*RAS_DATA_START
*RAS_HEADER_START
*CORR_POS_DB_NAME "AngleCorr_NIST640d_DteX_2022.02.28"
*CORR_POS_GONIO_RADIUS ""
*CORR_POS_NODE_INDEX01 ""
*CORR_POS_NODE_INDEX02 ""
*CORR_POS_NODE_INDEX03 ""
*CORR_POS_NODE_INDEX04 ""
*CORR_POS_NODE_INDEX05 ""
*CORR_POS_NODE_INDEX06 ""
*CORR_POS_NODE_INDEX07 ""
*CORR_POS_NODE_INDEX08 ""
*CORR_POS_NODE_INDEX09 ""
*CORR_POS_NODE_INDEX10 ""
*CORR_POS_NODE_INDEX11 ""
*CORR_POS_NODE_LABEL01 "Si(111)"
*CORR_POS_NODE_LABEL02 "Si(220)"
*CORR_POS_NODE_LABEL03 "Si(311)"
*CORR_POS_NODE_LABEL04 "Si(400)"
*CORR_POS_NODE_LABEL05 "Si(331)"
*CORR_POS_NODE_LABEL06 "Si(422)"
*CORR_POS_NODE_LABEL07 "Si(511)"
*CORR_POS_NODE_LABEL08 "Si(440)"
*CORR_POS_NODE_LABEL09 "Si(531)"
*CORR_POS_NODE_LABEL10 "Si(620)"
*CORR_POS_NODE_LABEL11 "Si(533)"
*CORR_POS_NODE_POS_CALC01 "28.4137"
*CORR_POS_NODE_POS_CALC02 "47.2707"
*CORR_POS_NODE_POS_CALC03 "56.0883"
*CORR_POS_NODE_POS_CALC04 "69.0934"
*CORR_POS_NODE_POS_CALC05 "76.3385"
*CORR_POS_NODE_POS_CALC06 "87.9915"
*CORR_POS_NODE_POS_CALC07 "94.9137"
*CORR_POS_NODE_POS_CALC08 "106.67"
*CORR_POS_NODE_POS_CALC09 "114.054"
*CORR_POS_NODE_POS_CALC10 "127.508"
*CORR_POS_NODE_POS_CALC11 "136.858"
*CORR_POS_NODE_POS_MEAS01 "28.3905"
*CORR_POS_NODE_POS_MEAS02 "47.2504"
*CORR_POS_NODE_POS_MEAS03 "56.0712"
*CORR_POS_NODE_POS_MEAS04 "69.0788"
*CORR_POS_NODE_POS_MEAS05 "76.3323"
*CORR_POS_NODE_POS_MEAS06 "87.9869"
*CORR_POS_NODE_POS_MEAS07 "94.9135"
*CORR_POS_NODE_POS_MEAS08 "106.672"
*CORR_POS_NODE_POS_MEAS09 "114.061"
*CORR_POS_NODE_POS_MEAS10 "127.517"
*CORR_POS_NODE_POS_MEAS11 "136.874"
*CORR_POS_OPT_ATTR "集中法"
*CORR_POS_PARAM_MU ""
*CORR_POS_PARAM_PL ""
*CORR_POS_SEMODEL_TYPE "0"
*CORR_POS_STANDARD_TYPE ""
*CORR_POS_VALUE_ANALYZER "None"
*CORR_POS_VALUE_CMONO "None"
*CORR_POS_VALUE_IMONO "None"
*CORR_POS_VALUE_IS "0.625deg"
*CORR_POS_VALUE_ISL "10.0mm"
*CORR_POS_VALUE_ISOLLER "2.5deg"
*CORR_POS_VALUE_RS1 "13.0mm"
*CORR_POS_VALUE_RS2 "13.0mm"
*CORR_POS_VALUE_RSOLLER "2.5deg"
*CORR_POS_XG_FOCUS_L ""
*CORR_POS_XG_WAVE_TYPE ""
*CORR_POS_XG_WAVE_VALUE ""
*DISP_FMT_X "%.2f"
*DISP_FMT_Y "%.0f"
*DISP_FULLSCALE "2496.0000000000"
*DISP_LINE_COLOR "255.0000000000"
*DISP_LINE_STYLE "0.0000000000"
*DISP_LINE_WIDTH "0.2500000000"
*DISP_NOTE "Collected Data-4"
*DISP_OFFSET_Y "0.0000000000"
*DISP_PEAKSEARCH_UNIT_Y "cps"
*DISP_RANGE_BOTTOM "0.0000000000"
*DISP_RANGE_LEFT "2.0000000000"
*DISP_RANGE_LOGCUTOFF "0.0100000000"
*DISP_RANGE_RIGHT "140.0000000000"
*DISP_RANGE_TOP "2496.0000000000"
*DISP_SCALE_MODE_Y "0.0000000000"
*DISP_TAB_NAME "Theta/2-Theta"
*DISP_TITLE_Y "Intensity"
*DISP_UNIT_Y "cps"
*DISP_WINDOW_NAME "MSG_MACROENGINE"
*FILE_COMMENT " "
*FILE_MD5 ""
*FILE_MEMO " "
*FILE_OPERATOR "Administrator"
*FILE_SAMPLE "Si_Halter_alt"
*FILE_TYPE "RAS_RAW"
*FILE_USERGROUP "System Manager"
*FILE_VERSION "1.0000000000"
*HW_ATTACHMENT_ID "ATT1031"
*HW_ATTACHMENT_NAME "6サンプルチェンジャ|ASC-6"
*HW_COUNTER_ID-0 "CUT0025"
*HW_COUNTER_ID-1 "CUT0020"
*HW_COUNTER_ID-2 "CUT0020"
*HW_COUNTER_ID-3 "CMC0021"
*HW_COUNTER_NAME-0 "D/teX Ultra|D/teX Ultra"
*HW_COUNTER_NAME-1 "None|None"
*HW_COUNTER_NAME-2 "None|None"
*HW_COUNTER_NAME-3 "検出器モノクロメータ|Detector monochromator"
*HW_COUNTER_SELECT_NAME "D/teX Ultra|D/teX Ultra"
*HW_GONIOMETER_ID "GON0070"
*HW_GONIOMETER_NAME "MiniFlex 300/600|MiniFlex 300/600"
*HW_GONIOMETER_RADIUS-0 "79.0"
*HW_GONIOMETER_RADIUS-1 "91.5"
*HW_GONIOMETER_RADIUS-2 "150.0"
*HW_GONIOMETER_RADIUS-3 "0"
*HW_GONIOMETER_RADIUS-4 "103.4"
*HW_GONIOMETER_RADIUS-5 "150.0"
*HW_GONIOMETER_RADIUS-6 "46.6"
*HW_GONIOMETER_RADIUS-7 "160.0"
*HW_I_OPT_ID-0 "ISL0021"
*HW_I_OPT_ID-1 "ISO0021"
*HW_I_OPT_NAME-0 "発散スリット|Divergence slit"
*HW_I_OPT_NAME-1 "入射平行スリット|Incident parallel slit"
*HW_R_ATTENUATER_AUTOMODE "0"
*HW_R_OPT_ID-0 "RSS0021"
*HW_R_OPT_ID-1 "RSO0021"
*HW_R_OPT_ID-2 "RRS0021"
*HW_R_OPT_NAME-0 "散乱スリット|Scattering slit"
*HW_R_OPT_NAME-1 "受光平行スリット|Receiving soller slit"
*HW_R_OPT_NAME-2 "受光スリット|Receiving slit"
*HW_SAMPLE_HOLDER_ID "SMP0000"
*HW_SAMPLE_HOLDER_NAME "無し|None"
*HW_XG_CURRENT_MAX "15"
*HW_XG_CURRENT_MIN "2"
*HW_XG_CURRENT_RESOLUTION "1"
*HW_XG_CURRENT_UNIT "mA"
*HW_XG_FOCUS "1mm x 10mm"
*HW_XG_FOCUS_TYPE "Normal"
*HW_XG_ID ""
*HW_XG_NAME "300W/600W 封入管-B|300W/600W Sealed tube-B"
*HW_XG_TARGET_ATOMIC_NUMBER "29.0000000000"
*HW_XG_TARGET_NAME "Cu"
*HW_XG_TYPE "Hermetic"
*HW_XG_VOLTAGE_MAX "40"
*HW_XG_VOLTAGE_MIN "20"
*HW_XG_VOLTAGE_RESOLUTION "1"
*HW_XG_VOLTAGE_UNIT "kV"
*HW_XG_WATT_MAX "1"
*HW_XG_WATT_UNIT "kW"
*HW_XG_WAVE_LENGTH_ALPHA1 "1.540593"
*HW_XG_WAVE_LENGTH_ALPHA2 "1.544414"
*HW_XG_WAVE_LENGTH_BETA "1.392250"
*MEAS_COND_AXIS_NAME-0 "Theta/2-Theta"
*MEAS_COND_AXIS_NAME-1 "Spin"
*MEAS_COND_AXIS_NAME-2 "Change"
*MEAS_COND_AXIS_NAME-3 "Soller(inc.)"
*MEAS_COND_AXIS_NAME-4 "IHS"
*MEAS_COND_AXIS_NAME-5 "DS"
*MEAS_COND_AXIS_NAME-6 "SS"
*MEAS_COND_AXIS_NAME-7 "Soller(rec.)"
*MEAS_COND_AXIS_NAME-8 "RS"
*MEAS_COND_AXIS_NAME-9 "Filter"
*MEAS_COND_AXIS_NAME-10 "Monochromator"
*MEAS_COND_AXIS_NAME-11 "PHA"
*MEAS_COND_AXIS_NAME_INTERNAL-0 "TwoThetaTheta"
*MEAS_COND_AXIS_NAME_INTERNAL-1 "Spin"
*MEAS_COND_AXIS_NAME_INTERNAL-2 "Change"
*MEAS_COND_AXIS_NAME_INTERNAL-3 "IncidentSollerSlit"
*MEAS_COND_AXIS_NAME_INTERNAL-4 "IncidentAxdSlit"
*MEAS_COND_AXIS_NAME_INTERNAL-5 "IncidentSlitBox"
*MEAS_COND_AXIS_NAME_INTERNAL-6 "ReceivingSlitBox1"
*MEAS_COND_AXIS_NAME_INTERNAL-7 "ReceivingSollerSlit"
*MEAS_COND_AXIS_NAME_INTERNAL-8 "ReceivingSlitBox2"
*MEAS_COND_AXIS_NAME_INTERNAL-9 "Filter"
*MEAS_COND_AXIS_NAME_INTERNAL-10 "CounterMonochromator"
*MEAS_COND_AXIS_NAME_INTERNAL-11 "PHA"
*MEAS_COND_AXIS_NAME_MAGICNO-0 "268632064.0000000000"
*MEAS_COND_AXIS_NAME_MAGICNO-1 "16842752.0000000000"
*MEAS_COND_AXIS_NAME_MAGICNO-2 "16842752.0000000000"
*MEAS_COND_AXIS_NAME_MAGICNO-3 "20971521.0000000000"
*MEAS_COND_AXIS_NAME_MAGICNO-4 "22020097.0000000000"
*MEAS_COND_AXIS_NAME_MAGICNO-5 "22020097.0000000000"
*MEAS_COND_AXIS_NAME_MAGICNO-6 "23068673.0000000000"
*MEAS_COND_AXIS_NAME_MAGICNO-7 "20971521.0000000000"
*MEAS_COND_AXIS_NAME_MAGICNO-8 "23068673.0000000000"
*MEAS_COND_AXIS_NAME_MAGICNO-9 "20971521.0000000000"
*MEAS_COND_AXIS_NAME_MAGICNO-10 "20971521.0000000000"
*MEAS_COND_AXIS_NAME_MAGICNO-11 "0.0000000000"
*MEAS_COND_AXIS_OFFSET-0 "0.0000000000"
*MEAS_COND_AXIS_OFFSET-1 "-"
*MEAS_COND_AXIS_OFFSET-2 "-"
*MEAS_COND_AXIS_OFFSET-3 "-"
*MEAS_COND_AXIS_OFFSET-4 "-"
*MEAS_COND_AXIS_OFFSET-5 "-"
*MEAS_COND_AXIS_OFFSET-6 "-"
*MEAS_COND_AXIS_OFFSET-7 "-"
*MEAS_COND_AXIS_OFFSET-8 "-"
*MEAS_COND_AXIS_OFFSET-9 "-"
*MEAS_COND_AXIS_OFFSET-10 "-"
*MEAS_COND_AXIS_OFFSET-11 "-"
*MEAS_COND_AXIS_POSITION-0 "142.5900000000"
*MEAS_COND_AXIS_POSITION-1 "0.0000000000"
*MEAS_COND_AXIS_POSITION-2 "4.0000000000"
*MEAS_COND_AXIS_POSITION-3 "2.5deg"
*MEAS_COND_AXIS_POSITION-4 "10.0mm"
*MEAS_COND_AXIS_POSITION-5 "0.625deg"
*MEAS_COND_AXIS_POSITION-6 "8.0mm"
*MEAS_COND_AXIS_POSITION-7 "2.5deg"
*MEAS_COND_AXIS_POSITION-8 "13.0mm"
*MEAS_COND_AXIS_POSITION-9 "K-beta(x2)"
*MEAS_COND_AXIS_POSITION-10 "None"
*MEAS_COND_AXIS_POSITION-11 "49.0000000000"
*MEAS_COND_AXIS_UNIT-0 "deg"
*MEAS_COND_AXIS_UNIT-1 ""
*MEAS_COND_AXIS_UNIT-2 ""
*MEAS_COND_AXIS_UNIT-3 ""
*MEAS_COND_AXIS_UNIT-4 ""
*MEAS_COND_AXIS_UNIT-5 ""
*MEAS_COND_AXIS_UNIT-6 ""
*MEAS_COND_AXIS_UNIT-7 ""
*MEAS_COND_AXIS_UNIT-8 ""
*MEAS_COND_AXIS_UNIT-9 ""
*MEAS_COND_AXIS_UNIT-10 ""
*MEAS_COND_AXIS_UNIT-11 "div"
*MEAS_COND_CORRECTION_SLIT_COUNTERMONO "None"
*MEAS_COND_CORRECTION_SLIT_DS "0.625deg"
*MEAS_COND_CORRECTION_SLIT_FILTER "None"
*MEAS_COND_CORRECTION_SLIT_IHS "10.0mm"
*MEAS_COND_CORRECTION_SLIT_RS "13.0mm"
*MEAS_COND_CORRECTION_SLIT_SOLLER_INC "2.5deg"
*MEAS_COND_CORRECTION_SLIT_SOLLER_REC "2.5deg"
*MEAS_COND_CORRECTION_SLIT_SS "8.0mm"
*MEAS_COND_COUNTER_CNTLOSS_CORR "0.0000000000"
*MEAS_COND_COUNTER_PHABASE "49.0000000000"
*MEAS_COND_COUNTER_PHAWINDOW "8.0000000000"
*MEAS_COND_COUNTER_PHA_UNIT "div"
*MEAS_COND_COUNTER_TAUDIFF "0.2500000000"
*MEAS_COND_COUNTER_TAUINT "0.7500000000"
*MEAS_COND_IRRADIATION_MODE "OFF"
*MEAS_COND_IRRADIATION_WIDTH ""
*MEAS_COND_OPT_ATTR " "
*MEAS_COND_OPT_NAME ""
*MEAS_COND_UNSYMMETRIC_MODE "OFF"
*MEAS_COND_XG_CURRENT "15.0000000000"
*MEAS_COND_XG_VOLTAGE "40.0000000000"
*MEAS_COND_XG_WAVE_TYPE "Ka"
*MEAS_DATA_COUNT "13801.0000000000"
*MEAS_SCAN_AXIS_X "Theta/2-Theta"
*MEAS_SCAN_AXIS_X_INTERNAL "TwoThetaTheta"
*MEAS_SCAN_END_TIME "06/22/22 22:11:00"
*MEAS_SCAN_MODE "CONTINUOUS"
*MEAS_SCAN_MONITOR "0"
*MEAS_SCAN_RESOLUTION_X "0.005"
*MEAS_SCAN_SPEED "1.000"
*MEAS_SCAN_SPEED_UNIT "deg/min"
*MEAS_SCAN_START "2.0000000000"
*MEAS_SCAN_START_TIME "06/22/22 19:47:30"
*MEAS_SCAN_STEP "0.0100000000"
*MEAS_SCAN_STOP "140.0000000000"
*MEAS_SCAN_UNIT_X "deg"
*MEAS_SCAN_UNIT_Y "counts"
*SLIT_SYSTEM "0"
*RAS_HEADER_END
*RAS_INT_START
2.000 1083.000 1.000
2.100 1125.000 1.000
2.200 976.000 1.000
2.300 905.000 1.000
2.400 887.000 1.000
2.500 814.000 1.000
2.600 765.000 1.000
2.700 719.000 1.000
2.800 693.000 1.000
2.900 718.000 1.000
3.000 619.000 1.000
3.100 659.000 1.000
3.200 627.000 1.000
3.300 580.000 1.000
3.400 546.000 1.000
3.500 571.000 1.000
3.600 526.000 1.000
3.700 479.000 1.000
3.800 511.000 1.000
3.900 505.000 1.000
4.000 462.000 1.000
4.100 487.000 1.000
4.200 453.000 1.000
4.300 447.000 1.000
4.400 467.000 1.000
4.500 409.000 1.000
4.600 384.000 1.000
4.700 371.000 1.000
4.800 405.000 1.000
4.900 370.000 1.000
5.000 357.000 1.000
5.100 350.000 1.000
5.200 348.000 1.000
5.300 329.000 1.000
5.400 329.000 1.000
5.500 340.000 1.000
5.600 327.000 1.000
5.700 306.000 1.000
5.800 320.000 1.000
5.900 305.000 1.000
6.000 280.000 1.000
6.100 291.000 1.000
6.200 285.000 1.000
6.300 288.000 1.000
6.400 285.000 1.000
6.500 287.000 1.000
6.600 279.000 1.000
6.700 261.000 1.000
6.800 286.000 1.000
6.900 290.000 1.000
7.000 247.000 1.000
7.100 255.000 1.000
7.200 269.000 1.000
7.300 255.000 1.000
7.400 254.000 1.000
7.500 264.000 1.000
7.600 252.000 1.000
7.700 233.000 1.000
7.800 243.000 1.000
7.900 232.000 1.000
8.000 234.000 1.000
8.100 224.000 1.000
8.200 253.000 1.000
8.300 246.000 1.000
8.400 220.000 1.000
8.500 237.000 1.000
8.600 231.000 1.000
8.700 228.000 1.000
8.800 231.000 1.000
8.900 222.000 1.000
9.000 244.000 1.000
9.100 230.000 1.000
9.200 236.000 1.000
9.300 226.000 1.000
9.400 222.000 1.000
9.500 247.000 1.000
9.600 238.000 1.000
9.700 216.000 1.000
9.800 215.000 1.000
9.900 235.000 1.000
10.000 225.000 1.000
10.100 208.000 1.000
10.200 218.000 1.000
10.300 223.000 1.000
10.400 223.000 1.000
10.500 221.000 1.000
10.600 212.000 1.000
10.700 238.000 1.000
10.800 228.000 1.000
10.900 232.000 1.000
11.000 218.000 1.000
11.100 232.000 1.000
11.200 223.000 1.000
11.300 233.000 1.000
11.400 217.000 1.000
11.500 217.000 1.000
11.600 215.000 1.000
11.700 205.000 1.000
11.800 213.000 1.000
11.900 234.000 1.000
12.000 212.000 1.000
12.100 196.000 1.000
12.200 214.000 1.000
12.300 215.000 1.000
12.400 206.000 1.000
12.500 212.000 1.000
12.600 222.000 1.000
12.700 219.000 1.000
12.800 213.000 1.000
12.900 201.000 1.000
13.000 202.000 1.000
13.100 209.000 1.000
13.200 191.000 1.000
13.300 197.000 1.000
13.400 201.000 1.000
13.500 199.000 1.000
13.600 208.000 1.000
13.700 195.000 1.000
13.800 181.000 1.000
13.900 204.000 1.000
14.000 203.000 1.000
14.100 194.000 1.000
14.200 198.000 1.000
14.300 196.000 1.000
14.400 188.000 1.000
14.500 186.000 1.000
14.600 180.000 1.000
14.700 189.000 1.000
14.800 184.000 1.000
14.900 198.000 1.000
15.000 188.000 1.000
15.100 181.000 1.000
15.200 181.000 1.000
15.300 184.000 1.000
15.400 177.000 1.000
15.500 183.000 1.000
15.600 192.000 1.000
15.700 172.000 1.000
15.800 178.000 1.000
15.900 162.000 1.000
16.000 186.000 1.000
16.100 180.000 1.000
16.200 180.000 1.000
16.300 183.000 1.000
16.400 167.000 1.000
16.500 186.000 1.000
16.600 165.000 1.000
16.700 175.000 1.000
16.800 168.000 1.000
16.900 171.000 1.000
17.000 169.000 1.000
17.100 169.000 1.000
17.200 170.000 1.000
17.300 169.000 1.000
17.400 153.000 1.000
17.500 163.000 1.000
17.600 175.000 1.000
17.700 163.000 1.000
17.800 154.000 1.000
17.900 155.000 1.000
18.000 155.000 1.000
18.100 146.000 1.000
18.200 155.000 1.000
18.300 166.000 1.000
18.400 160.000 1.000
18.500 150.000 1.000
18.600 164.000 1.000
18.700 163.000 1.000
18.800 159.000 1.000
18.900 154.000 1.000
19.000 167.000 1.000
19.100 153.000 1.000
19.200 153.000 1.000
19.300 150.000 1.000
19.400 152.000 1.000
19.500 142.000 1.000
19.600 140.000 1.000
19.700 152.000 1.000
19.800 167.000 1.000
19.900 163.000 1.000
20.000 157.000 1.000
20.100 136.000 1.000
20.200 154.000 1.000
20.300 142.000 1.000
20.400 142.000 1.000
20.500 143.000 1.000
20.600 148.000 1.000
20.700 132.000 1.000
20.800 120.000 1.000
20.900 136.000 1.000
21.000 144.000 1.000
21.100 148.000 1.000
21.200 137.000 1.000
21.300 146.000 1.000
21.400 135.000 1.000
21.500 141.000 1.000
21.600 137.000 1.000
21.700 123.000 1.000
21.800 127.000 1.000
21.900 154.000 1.000
22.000 128.000 1.000
22.100 129.000 1.000
22.200 116.000 1.000
22.300 146.000 1.000
22.400 137.000 1.000
22.500 122.000 1.000
22.600 131.000 1.000
22.700 124.000 1.000
22.800 133.000 1.000
22.900 134.000 1.000
23.000 126.000 1.000
23.100 133.000 1.000
23.200 119.000 1.000
23.300 136.000 1.000
23.400 120.000 1.000
23.500 128.000 1.000
23.600 125.000 1.000
23.700 116.000 1.000
23.800 122.000 1.000
23.900 126.000 1.000
24.000 117.000 1.000
24.100 129.000 1.000
24.200 108.000 1.000
24.300 124.000 1.000
24.400 121.000 1.000
24.500 118.000 1.000
24.600 105.000 1.000
24.700 120.000 1.000
24.800 122.000 1.000
24.900 110.000 1.000
25.000 118.000 1.000
25.100 117.000 1.000
25.200 115.000 1.000
25.300 114.000 1.000
25.400 112.000 1.000
25.500 116.000 1.000
25.600 122.000 1.000
25.700 114.000 1.000
25.800 121.000 1.000
25.900 110.000 1.000
26.000 112.000 1.000
26.100 112.000 1.000
26.200 107.000 1.000
26.300 110.000 1.000
26.400 108.000 1.000
26.500 109.000 1.000
26.600 107.000 1.000
26.700 105.000 1.000
26.800 111.000 1.000
26.900 123.000 1.000
27.000 123.000 1.000
27.100 118.000 1.000
27.200 110.000 1.000
27.300 105.000 1.000
27.400 117.000 1.000
27.500 96.000 1.000
27.600 117.000 1.000
27.700 103.000 1.000
27.800 112.000 1.000
27.900 112.000 1.000
28.000 113.000 1.000
28.100 95.000 1.000
28.200 108.000 1.000
28.300 103.000 1.000
28.400 101.000 1.000
28.500 102.000 1.000
28.600 101.000 1.000
28.700 99.000 1.000
28.800 97.000 1.000
28.900 95.000 1.000
29.000 99.000 1.000
29.100 99.000 1.000
29.200 103.000 1.000
29.300 96.000 1.000
29.400 106.000 1.000
29.500 111.000 1.000
29.600 89.000 1.000
29.700 96.000 1.000
29.800 89.000 1.000
29.900 97.000 1.000
30.000 90.000 1.000
30.100 102.000 1.000
30.200 98.000 1.000
30.300 95.000 1.000
30.400 103.000 1.000
30.500 98.000 1.000
30.600 91.000 1.000
30.700 96.000 1.000
30.800 80.000 1.000
30.900 97.000 1.000
31.000 96.000 1.000
31.100 87.000 1.000
31.200 98.000 1.000
31.300 94.000 1.000
31.400 89.000 1.000
31.500 95.000 1.000
31.600 93.000 1.000
31.700 86.000 1.000
31.800 98.000 1.000
31.900 92.000 1.000
32.000 107.000 1.000
32.100 95.000 1.000
32.200 102.000 1.000
32.300 92.000 1.000
32.400 94.000 1.000
32.500 96.000 1.000
32.600 91.000 1.000
32.700 89.000 1.000
32.800 93.000 1.000
32.900 84.000 1.000
33.000 94.000 1.000
33.100 84.000 1.000
33.200 86.000 1.000
33.300 82.000 1.000
33.400 85.000 1.000
33.500 82.000 1.000
33.600 83.000 1.000
33.700 87.000 1.000
33.800 95.000 1.000
33.900 88.000 1.000
34.000 87.000 1.000
34.100 91.000 1.000
34.200 93.000 1.000
34.300 96.000 1.000
34.400 101.000 1.000
34.500 87.000 1.000
34.600 99.000 1.000
34.700 93.000 1.000
34.800 92.000 1.000
34.900 81.000 1.000
35.000 90.000 1.000
35.100 90.000 1.000
35.200 85.000 1.000
35.300 88.000 1.000
35.400 89.000 1.000
35.500 87.000 1.000
35.600 91.000 1.000
35.700 84.000 1.000
35.800 91.000 1.000
35.900 98.000 1.000
36.000 87.000 1.000
36.100 91.000 1.000
36.200 86.000 1.000
36.300 80.000 1.000
36.400 89.000 1.000
36.500 86.000 1.000
36.600 92.000 1.000
36.700 89.000 1.000
36.800 88.000 1.000
36.900 85.000 1.000
37.000 81.000 1.000
37.100 81.000 1.000
37.200 72.000 1.000
37.300 95.000 1.000
37.400 87.000 1.000
37.500 82.000 1.000
37.600 91.000 1.000
37.700 81.000 1.000
37.800 87.000 1.000
37.900 77.000 1.000
38.000 80.000 1.000
38.100 85.000 1.000
38.200 101.000 1.000
38.300 88.000 1.000
38.400 83.000 1.000
38.500 93.000 1.000
38.600 93.000 1.000
38.700 90.000 1.000
38.800 77.000 1.000
38.900 83.000 1.000
39.000 101.000 1.000
39.100 86.000 1.000
39.200 86.000 1.000
39.300 86.000 1.000
39.400 85.000 1.000
39.500 87.000 1.000
39.600 79.000 1.000
39.700 98.000 1.000
39.800 75.000 1.000
39.900 89.000 1.000
40.000 94.000 1.000
40.100 96.000 1.000
40.200 85.000 1.000
40.300 87.000 1.000
40.400 98.000 1.000
40.500 91.000 1.000
40.600 94.000 1.000
40.700 86.000 1.000
40.800 97.000 1.000
40.900 80.000 1.000
41.000 97.000 1.000
41.100 90.000 1.000
41.200 84.000 1.000
41.300 91.000 1.000
41.400 88.000 1.000
41.500 85.000 1.000
41.600 92.000 1.000
41.700 77.000 1.000
41.800 88.000 1.000
41.900 73.000 1.000
42.000 102.000 1.000
42.100 80.000 1.000
42.200 93.000 1.000
42.300 90.000 1.000
42.400 91.000 1.000
42.500 79.000 1.000
42.600 92.000 1.000
42.700 93.000 1.000
42.800 86.000 1.000
42.900 99.000 1.000
43.000 84.000 1.000
43.100 91.000 1.000
43.200 75.000 1.000
43.300 76.000 1.000
43.400 93.000 1.000
43.500 93.000 1.000
43.600 85.000 1.000
43.700 91.000 1.000
43.800 93.000 1.000
43.900 106.000 1.000
44.000 86.000 1.000
44.100 85.000 1.000
44.200 85.000 1.000
44.300 75.000 1.000
44.400 86.000 1.000
44.500 85.000 1.000
44.600 81.000 1.000
44.700 89.000 1.000
44.800 82.000 1.000
44.900 81.000 1.000
45.000 90.000 1.000
45.100 81.000 1.000
45.200 85.000 1.000
45.300 90.000 1.000
45.400 85.000 1.000
45.500 103.000 1.000
45.600 92.000 1.000
45.700 99.000 1.000
45.800 76.000 1.000
45.900 90.000 1.000
46.000 74.000 1.000
46.100 81.000 1.000
46.200 88.000 1.000
46.300 82.000 1.000
46.400 93.000 1.000
46.500 82.000 1.000
46.600 89.000 1.000
46.700 100.000 1.000
46.800 85.000 1.000
46.900 86.000 1.000
47.000 84.000 1.000
47.100 82.000 1.000
47.200 93.000 1.000
47.300 84.000 1.000
47.400 81.000 1.000
47.500 81.000 1.000
47.600 86.000 1.000
47.700 75.000 1.000
47.800 85.000 1.000
47.900 82.000 1.000
48.000 82.000 1.000
48.100 88.000 1.000
48.200 88.000 1.000
48.300 85.000 1.000
48.400 97.000 1.000
48.500 87.000 1.000
48.600 90.000 1.000
48.700 81.000 1.000
48.800 91.000 1.000
48.900 82.000 1.000
49.000 102.000 1.000
49.100 89.000 1.000
49.200 93.000 1.000
49.300 94.000 1.000
49.400 89.000 1.000
49.500 79.000 1.000
49.600 85.000 1.000
49.700 87.000 1.000
49.800 84.000 1.000
49.900 89.000 1.000
50.000 85.000 1.000
50.100 91.000 1.000
50.200 87.000 1.000
50.300 86.000 1.000
50.400 87.000 1.000
50.500 86.000 1.000
50.600 94.000 1.000
50.700 87.000 1.000
50.800 80.000 1.000
50.900 95.000 1.000
51.000 92.000 1.000
51.100 81.000 1.000
51.200 82.000 1.000
51.300 94.000 1.000
51.400 87.000 1.000
51.500 81.000 1.000
51.600 90.000 1.000
51.700 82.000 1.000
51.800 91.000 1.000
51.900 97.000 1.000
52.000 89.000 1.000
52.100 100.000 1.000
52.200 82.000 1.000
52.300 80.000 1.000
52.400 83.000 1.000
52.500 85.000 1.000
52.600 89.000 1.000
52.700 82.000 1.000
52.800 87.000 1.000
52.900 103.000 1.000
53.000 92.000 1.000
53.100 93.000 1.000
53.200 88.000 1.000
53.300 81.000 1.000
53.400 90.000 1.000
53.500 85.000 1.000
53.600 99.000 1.000
53.700 83.000 1.000
53.800 83.000 1.000
53.900 89.000 1.000
54.000 86.000 1.000
54.100 98.000 1.000
54.200 80.000 1.000
54.300 100.000 1.000
54.400 89.000 1.000
54.500 92.000 1.000
54.600 96.000 1.000
54.700 84.000 1.000
54.800 92.000 1.000
54.900 93.000 1.000
55.000 86.000 1.000
55.100 93.000 1.000
55.200 95.000 1.000
55.300 88.000 1.000
55.400 79.000 1.000
55.500 102.000 1.000
55.600 87.000 1.000
55.700 84.000 1.000
55.800 90.000 1.000
55.900 84.000 1.000
56.000 94.000 1.000
56.100 99.000 1.000
56.200 91.000 1.000
56.300 94.000 1.000
56.400 102.000 1.000
56.500 91.000 1.000
56.600 81.000 1.000
56.700 87.000 1.000
56.800 101.000 1.000
56.900 96.000 1.000
57.000 96.000 1.000
57.100 97.000 1.000
57.200 97.000 1.000
57.300 98.000 1.000
57.400 93.000 1.000
57.500 88.000 1.000
57.600 92.000 1.000
57.700 93.000 1.000
57.800 91.000 1.000
57.900 95.000 1.000
58.000 89.000 1.000
58.100 112.000 1.000
58.200 108.000 1.000
58.300 99.000 1.000
58.400 93.000 1.000
58.500 97.000 1.000
58.600 95.000 1.000
58.700 94.000 1.000
58.800 92.000 1.000
58.900 92.000 1.000
59.000 83.000 1.000
59.100 99.000 1.000
59.200 94.000 1.000
59.300 89.000 1.000
59.400 105.000 1.000
59.500 97.000 1.000
59.600 100.000 1.000
59.700 85.000 1.000
59.800 85.000 1.000
59.900 82.000 1.000
60.000 85.000 1.000
60.100 88.000 1.000
60.200 96.000 1.000
60.300 89.000 1.000
60.400 92.000 1.000
60.500 97.000 1.000
60.600 91.000 1.000
60.700 87.000 1.000
60.800 103.000 1.000
60.900 95.000 1.000
61.000 81.000 1.000
61.100 72.000 1.000
61.200 85.000 1.000
61.300 84.000 1.000
61.400 103.000 1.000
61.500 102.000 1.000
61.600 90.000 1.000
61.700 79.000 1.000
61.800 82.000 1.000
61.900 86.000 1.000
62.000 82.000 1.000
62.100 87.000 1.000
62.200 93.000 1.000
62.300 91.000 1.000
62.400 84.000 1.000
62.500 86.000 1.000
62.600 98.000 1.000
62.700 91.000 1.000
62.800 82.000 1.000
62.900 80.000 1.000
63.000 89.000 1.000
63.100 90.000 1.000
63.200 87.000 1.000
63.300 74.000 1.000
63.400 81.000 1.000
63.500 85.000 1.000
63.600 93.000 1.000
63.700 83.000 1.000
63.800 87.000 1.000
63.900 95.000 1.000
64.000 90.000 1.000
64.100 101.000 1.000
64.200 85.000 1.000
64.300 85.000 1.000
64.400 86.000 1.000
64.500 76.000 1.000
64.600 83.000 1.000
64.700 71.000 1.000
64.800 86.000 1.000
64.900 77.000 1.000
65.000 86.000 1.000
65.100 80.000 1.000
65.200 82.000 1.000
65.300 81.000 1.000
65.400 87.000 1.000
65.500 85.000 1.000
65.600 77.000 1.000
65.700 80.000 1.000
65.800 85.000 1.000
65.900 91.000 1.000
66.000 84.000 1.000
66.100 73.000 1.000
66.200 81.000 1.000
66.300 85.000 1.000
66.400 80.000 1.000
66.500 92.000 1.000
66.600 89.000 1.000
66.700 84.000 1.000
66.800 81.000 1.000
66.900 85.000 1.000
67.000 81.000 1.000
67.100 79.000 1.000
67.200 73.000 1.000
67.300 78.000 1.000
67.400 83.000 1.000
67.500 91.000 1.000
67.600 81.000 1.000
67.700 80.000 1.000
67.800 81.000 1.000
67.900 76.000 1.000
68.000 73.000 1.000
68.100 78.000 1.000
68.200 79.000 1.000
68.300 94.000 1.000
68.400 83.000 1.000
68.500 87.000 1.000
68.600 90.000 1.000
68.700 84.000 1.000
68.800 86.000 1.000
68.900 78.000 1.000
69.000 80.000 1.000
69.100 71.000 1.000
69.200 83.000 1.000
69.300 75.000 1.000
69.400 74.000 1.000
69.500 93.000 1.000
69.600 69.000 1.000
69.700 79.000 1.000
69.800 88.000 1.000
69.900 83.000 1.000
70.000 94.000 1.000
70.100 92.000 1.000
70.200 89.000 1.000
70.300 76.000 1.000
70.400 73.000 1.000
70.500 80.000 1.000
70.600 83.000 1.000
70.700 81.000 1.000
70.800 76.000 1.000
70.900 77.000 1.000
71.000 66.000 1.000
71.100 81.000 1.000
71.200 81.000 1.000
71.300 86.000 1.000
71.400 78.000 1.000
71.500 71.000 1.000
71.600 87.000 1.000
71.700 83.000 1.000
71.800 83.000 1.000
71.900 71.000 1.000
72.000 79.000 1.000
72.100 73.000 1.000
72.200 84.000 1.000
72.300 75.000 1.000
72.400 73.000 1.000
72.500 79.000 1.000
72.600 73.000 1.000
72.700 78.000 1.000
72.800 69.000 1.000
72.900 63.000 1.000
73.000 83.000 1.000
73.100 77.000 1.000
73.200 67.000 1.000
73.300 73.000 1.000
73.400 67.000 1.000
73.500 78.000 1.000
73.600 85.000 1.000
73.700 80.000 1.000
73.800 68.000 1.000
73.900 65.000 1.000
74.000 67.000 1.000
74.100 66.000 1.000
74.200 72.000 1.000
74.300 78.000 1.000
74.400 76.000 1.000
74.500 68.000 1.000
74.600 74.000 1.000
74.700 66.000 1.000
74.800 61.000 1.000
74.900 68.000 1.000
75.000 69.000 1.000
75.100 72.000 1.000
75.200 66.000 1.000
75.300 70.000 1.000
75.400 66.000 1.000
75.500 70.000 1.000
75.600 77.000 1.000
75.700 74.000 1.000
75.800 68.000 1.000
75.900 70.000 1.000
76.000 59.000 1.000
76.100 68.000 1.000
76.200 70.000 1.000
76.300 75.000 1.000
76.400 62.000 1.000
76.500 71.000 1.000
76.600 72.000 1.000
76.700 67.000 1.000
76.800 58.000 1.000
76.900 65.000 1.000
77.000 65.000 1.000
77.100 65.000 1.000
77.200 72.000 1.000
77.300 59.000 1.000
77.400 67.000 1.000
77.500 60.000 1.000
77.600 63.000 1.000
77.700 69.000 1.000
77.800 61.000 1.000
77.900 63.000 1.000
78.000 55.000 1.000
78.100 58.000 1.000
78.200 64.000 1.000
78.300 54.000 1.000
78.400 61.000 1.000
78.500 62.000 1.000
78.600 66.000 1.000
78.700 60.000 1.000
78.800 58.000 1.000
78.900 61.000 1.000
79.000 62.000 1.000
79.100 53.000 1.000
79.200 75.000 1.000
79.300 66.000 1.000
79.400 56.000 1.000
79.500 63.000 1.000
79.600 62.000 1.000
79.700 68.000 1.000
79.800 63.000 1.000
79.900 65.000 1.000
80.000 56.000 1.000
80.100 63.000 1.000
80.200 54.000 1.000
80.300 57.000 1.000
80.400 62.000 1.000
80.500 63.000 1.000
80.600 48.000 1.000
80.700 56.000 1.000
80.800 56.000 1.000
80.900 64.000 1.000
81.000 59.000 1.000
81.100 60.000 1.000
81.200 60.000 1.000
81.300 51.000 1.000
81.400 62.000 1.000
81.500 62.000 1.000
81.600 56.000 1.000
81.700 61.000 1.000
81.800 58.000 1.000
81.900 56.000 1.000
82.000 58.000 1.000
82.100 53.000 1.000
82.200 56.000 1.000
82.300 57.000 1.000
82.400 57.000 1.000
82.500 59.000 1.000
82.600 65.000 1.000
82.700 56.000 1.000
82.800 56.000 1.000
82.900 46.000 1.000
83.000 50.000 1.000
83.100 55.000 1.000
83.200 51.000 1.000
83.300 53.000 1.000
83.400 53.000 1.000
83.500 55.000 1.000
83.600 56.000 1.000
83.700 48.000 1.000
83.800 55.000 1.000
83.900 60.000 1.000
84.000 49.000 1.000
84.100 47.000 1.000
84.200 63.000 1.000
84.300 54.000 1.000
84.400 53.000 1.000
84.500 62.000 1.000
84.600 64.000 1.000
84.700 52.000 1.000
84.800 55.000 1.000
84.900 53.000 1.000
85.000 54.000 1.000
85.100 56.000 1.000
85.200 56.000 1.000
85.300 60.000 1.000
85.400 46.000 1.000
85.500 58.000 1.000
85.600 49.000 1.000
85.700 60.000 1.000
85.800 55.000 1.000
85.900 56.000 1.000
86.000 48.000 1.000
86.100 58.000 1.000
86.200 56.000 1.000
86.300 49.000 1.000
86.400 50.000 1.000
86.500 55.000 1.000
86.600 49.000 1.000
86.700 63.000 1.000
86.800 55.000 1.000
86.900 64.000 1.000
87.000 63.000 1.000
87.100 63.000 1.000
87.200 48.000 1.000
87.300 56.000 1.000
87.400 58.000 1.000
87.500 59.000 1.000
87.600 59.000 1.000
87.700 50.000 1.000
87.800 60.000 1.000
87.900 51.000 1.000
88.000 64.000 1.000
88.100 61.000 1.000
88.200 53.000 1.000
88.300 46.000 1.000
88.400 54.000 1.000
88.500 54.000 1.000
88.600 61.000 1.000
88.700 53.000 1.000
88.800 54.000 1.000
88.900 61.000 1.000
89.000 47.000 1.000
89.100 50.000 1.000
89.200 46.000 1.000
89.300 50.000 1.000
89.400 65.000 1.000
89.500 53.000 1.000
89.600 59.000 1.000
89.700 49.000 1.000
89.800 50.000 1.000
89.900 53.000 1.000
90.000 54.000 1.000
90.100 53.000 1.000
90.200 52.000 1.000
90.300 49.000 1.000
90.400 50.000 1.000
90.500 55.000 1.000
90.600 54.000 1.000
90.700 52.000 1.000
90.800 57.000 1.000
90.900 52.000 1.000
91.000 52.000 1.000
91.100 50.000 1.000
91.200 55.000 1.000
91.300 59.000 1.000
91.400 54.000 1.000
91.500 58.000 1.000
91.600 56.000 1.000
91.700 53.000 1.000
91.800 53.000 1.000
91.900 47.000 1.000
92.000 54.000 1.000
92.100 53.000 1.000
92.200 57.000 1.000
92.300 60.000 1.000
92.400 67.000 1.000
92.500 51.000 1.000
92.600 54.000 1.000
92.700 50.000 1.000
92.800 44.000 1.000
92.900 47.000 1.000
93.000 57.000 1.000
93.100 52.000 1.000
93.200 56.000 1.000
93.300 53.000 1.000
93.400 61.000 1.000
93.500 56.000 1.000
93.600 60.000 1.000
93.700 49.000 1.000
93.800 50.000 1.000
93.900 47.000 1.000
94.000 51.000 1.000
94.100 52.000 1.000
94.200 53.000 1.000
94.300 54.000 1.000
94.400 53.000 1.000
94.500 56.000 1.000
94.600 60.000 1.000
94.700 55.000 1.000
94.800 52.000 1.000
94.900 43.000 1.000
95.000 50.000 1.000
95.100 54.000 1.000
95.200 60.000 1.000
95.300 52.000 1.000
95.400 59.000 1.000
95.500 58.000 1.000
95.600 63.000 1.000
95.700 58.000 1.000
95.800 57.000 1.000
95.900 51.000 1.000
96.000 43.000 1.000
96.100 62.000 1.000
96.200 56.000 1.000
96.300 47.000 1.000
96.400 57.000 1.000
96.500 57.000 1.000
96.600 54.000 1.000
96.700 56.000 1.000
96.800 55.000 1.000
96.900 56.000 1.000
97.000 51.000 1.000
97.100 58.000 1.000
97.200 53.000 1.000
97.300 55.000 1.000
97.400 62.000 1.000
97.500 56.000 1.000
97.600 46.000 1.000
97.700 56.000 1.000
97.800 63.000 1.000
97.900 61.000 1.000
98.000 59.000 1.000
98.100 57.000 1.000
98.200 64.000 1.000
98.300 61.000 1.000
98.400 63.000 1.000
98.500 58.000 1.000
98.600 54.000 1.000
98.700 61.000 1.000
98.800 48.000 1.000
98.900 58.000 1.000
99.000 60.000 1.000
99.100 56.000 1.000
99.200 50.000 1.000
99.300 48.000 1.000
99.400 49.000 1.000
99.500 50.000 1.000
99.600 54.000 1.000
99.700 54.000 1.000
99.800 71.000 1.000
99.900 54.000 1.000
100.000 50.000 1.000
100.100 52.000 1.000
100.200 53.000 1.000
100.300 56.000 1.000
100.400 47.000 1.000
100.500 53.000 1.000
100.600 60.000 1.000
100.700 60.000 1.000
100.800 57.000 1.000
100.900 52.000 1.000
101.000 55.000 1.000
101.100 50.000 1.000
101.200 51.000 1.000
101.300 52.000 1.000
101.400 54.000 1.000
101.500 61.000 1.000
101.600 49.000 1.000
101.700 54.000 1.000
101.800 58.000 1.000
101.900 45.000 1.000
102.000 62.000 1.000
102.100 57.000 1.000
102.200 52.000 1.000
102.300 56.000 1.000
102.400 59.000 1.000
102.500 55.000 1.000
102.600 49.000 1.000
102.700 49.000 1.000
102.800 52.000 1.000
102.900 54.000 1.000
103.000 52.000 1.000
103.100 59.000 1.000
103.200 57.000 1.000
103.300 58.000 1.000
103.400 60.000 1.000
103.500 58.000 1.000
103.600 57.000 1.000
103.700 57.000 1.000
103.800 67.000 1.000
103.900 61.000 1.000
104.000 56.000 1.000
104.100 55.000 1.000
104.200 47.000 1.000
104.300 50.000 1.000
104.400 57.000 1.000
104.500 53.000 1.000
104.600 51.000 1.000
104.700 58.000 1.000
104.800 54.000 1.000
104.900 61.000 1.000
105.000 54.000 1.000
105.100 57.000 1.000
105.200 42.000 1.000
105.300 57.000 1.000
105.400 58.000 1.000
105.500 56.000 1.000
105.600 63.000 1.000
105.700 54.000 1.000
105.800 50.000 1.000
105.900 50.000 1.000
106.000 54.000 1.000
106.100 69.000 1.000
106.200 61.000 1.000
106.300 50.000 1.000
106.400 60.000 1.000
106.500 54.000 1.000
106.600 51.000 1.000
106.700 49.000 1.000
106.800 56.000 1.000
106.900 60.000 1.000
107.000 53.000 1.000
107.100 58.000 1.000
107.200 55.000 1.000
107.300 62.000 1.000
107.400 62.000 1.000
107.500 59.000 1.000
107.600 57.000 1.000
107.700 64.000 1.000
107.800 66.000 1.000
107.900 60.000 1.000
108.000 62.000 1.000
108.100 66.000 1.000
108.200 55.000 1.000
108.300 52.000 1.000
108.400 64.000 1.000
108.500 55.000 1.000
108.600 57.000 1.000
108.700 63.000 1.000
108.800 52.000 1.000
108.900 62.000 1.000
109.000 66.000 1.000
109.100 64.000 1.000
109.200 57.000 1.000
109.300 66.000 1.000
109.400 59.000 1.000
109.500 59.000 1.000
109.600 67.000 1.000
109.700 66.000 1.000
109.800 49.000 1.000
109.900 58.000 1.000
110.000 53.000 1.000
110.100 61.000 1.000
110.200 61.000 1.000
110.300 63.000 1.000
110.400 72.000 1.000
110.500 58.000 1.000
110.600 70.000 1.000
110.700 66.000 1.000
110.800 56.000 1.000
110.900 62.000 1.000
111.000 56.000 1.000
111.100 59.000 1.000
111.200 63.000 1.000
111.300 62.000 1.000
111.400 66.000 1.000
111.500 69.000 1.000
111.600 73.000 1.000
111.700 66.000 1.000
111.800 61.000 1.000
111.900 71.000 1.000
112.000 67.000 1.000
112.100 62.000 1.000
112.200 67.000 1.000
112.300 70.000 1.000
112.400 69.000 1.000
112.500 60.000 1.000
112.600 64.000 1.000
112.700 68.000 1.000
112.800 62.000 1.000
112.900 62.000 1.000
113.000 70.000 1.000
113.100 70.000 1.000
113.200 66.000 1.000
113.300 73.000 1.000
113.400 65.000 1.000
113.500 75.000 1.000
113.600 76.000 1.000
113.700 78.000 1.000
113.800 69.000 1.000
113.900 63.000 1.000
114.000 66.000 1.000
114.100 68.000 1.000
114.200 74.000 1.000
114.300 72.000 1.000
114.400 77.000 1.000
114.500 65.000 1.000
114.600 73.000 1.000
114.700 78.000 1.000
114.800 81.000 1.000
114.900 78.000 1.000
115.000 78.000 1.000
115.100 73.000 1.000
115.200 81.000 1.000
115.300 82.000 1.000
115.400 61.000 1.000
115.500 69.000 1.000
115.600 68.000 1.000
115.700 74.000 1.000
115.800 69.000 1.000
115.900 84.000 1.000
116.000 69.000 1.000
116.100 78.000 1.000
116.200 76.000 1.000
116.300 64.000 1.000
116.400 77.000 1.000
116.500 75.000 1.000
116.600 65.000 1.000
116.700 79.000 1.000
116.800 83.000 1.000
116.900 66.000 1.000
117.000 84.000 1.000
117.100 77.000 1.000
117.200 81.000 1.000
117.300 79.000 1.000
117.400 65.000 1.000
117.500 73.000 1.000
117.600 78.000 1.000
117.700 72.000 1.000
117.800 70.000 1.000
117.900 81.000 1.000
118.000 79.000 1.000
118.100 78.000 1.000
118.200 84.000 1.000
118.300 85.000 1.000
118.400 89.000 1.000
118.500 85.000 1.000
118.600 86.000 1.000
118.700 83.000 1.000
118.800 75.000 1.000
118.900 76.000 1.000
119.000 76.000 1.000
119.100 89.000 1.000
119.200 87.000 1.000
119.300 91.000 1.000
119.400 80.000 1.000
119.500 82.000 1.000
119.600 98.000 1.000
119.700 83.000 1.000
119.800 72.000 1.000
119.900 72.000 1.000
120.000 77.000 1.000
120.100 88.000 1.000
120.200 85.000 1.000
120.300 74.000 1.000
120.400 76.000 1.000
120.500 97.000 1.000
120.600 90.000 1.000
120.700 89.000 1.000
120.800 93.000 1.000
120.900 83.000 1.000
121.000 97.000 1.000
121.100 77.000 1.000
121.200 86.000 1.000
121.300 77.000 1.000
121.400 83.000 1.000
121.500 84.000 1.000
121.600 85.000 1.000
121.700 82.000 1.000
121.800 91.000 1.000
121.900 79.000 1.000
122.000 84.000 1.000
122.100 82.000 1.000
122.200 72.000 1.000
122.300 77.000 1.000
122.400 105.000 1.000
122.500 80.000 1.000
122.600 93.000 1.000
122.700 88.000 1.000
122.800 81.000 1.000
122.900 96.000 1.000
123.000 84.000 1.000
123.100 89.000 1.000
123.200 84.000 1.000
123.300 92.000 1.000
123.400 90.000 1.000
123.500 86.000 1.000
123.600 85.000 1.000
123.700 82.000 1.000
123.800 93.000 1.000
123.900 101.000 1.000
124.000 79.000 1.000
124.100 97.000 1.000
124.200 94.000 1.000
124.300 79.000 1.000
124.400 91.000 1.000
124.500 79.000 1.000
124.600 82.000 1.000
124.700 89.000 1.000
124.800 84.000 1.000
124.900 98.000 1.000
125.000 88.000 1.000
125.100 92.000 1.000
125.200 94.000 1.000
125.300 105.000 1.000
125.400 94.000 1.000
125.500 83.000 1.000
125.600 85.000 1.000
125.700 92.000 1.000
125.800 91.000 1.000
125.900 104.000 1.000
126.000 94.000 1.000
126.100 87.000 1.000
126.200 101.000 1.000
126.300 80.000 1.000
126.400 79.000 1.000
126.500 86.000 1.000
126.600 78.000 1.000
126.700 75.000 1.000
126.800 89.000 1.000
126.900 102.000 1.000
127.000 86.000 1.000
127.100 77.000 1.000
127.200 72.000 1.000
127.300 91.000 1.000
127.400 88.000 1.000
127.500 83.000 1.000
127.600 80.000 1.000
127.700 95.000 1.000
127.800 78.000 1.000
127.900 86.000 1.000
128.000 91.000 1.000
128.100 97.000 1.000
128.200 87.000 1.000
128.300 86.000 1.000
128.400 92.000 1.000
128.500 95.000 1.000
128.600 90.000 1.000
128.700 85.000 1.000
128.800 85.000 1.000
128.900 83.000 1.000
129.000 91.000 1.000
129.100 100.000 1.000
129.200 101.000 1.000
129.300 92.000 1.000
129.400 92.000 1.000
129.500 101.000 1.000
129.600 97.000 1.000
129.700 86.000 1.000
129.800 87.000 1.000
129.900 96.000 1.000
130.000 100.000 1.000
130.100 89.000 1.000
130.200 86.000 1.000
130.300 106.000 1.000
130.400 96.000 1.000
130.500 92.000 1.000
130.600 97.000 1.000
130.700 102.000 1.000
130.800 90.000 1.000
130.900 90.000 1.000
131.000 99.000 1.000
131.100 94.000 1.000
131.200 92.000 1.000
131.300 76.000 1.000
131.400 98.000 1.000
131.500 88.000 1.000
131.600 101.000 1.000
131.700 100.000 1.000
131.800 86.000 1.000
131.900 89.000 1.000
132.000 93.000 1.000
132.100 91.000 1.000
132.200 90.000 1.000
132.300 84.000 1.000
132.400 92.000 1.000
132.500 94.000 1.000
132.600 92.000 1.000
132.700 86.000 1.000
132.800 90.000 1.000
132.900 90.000 1.000
133.000 93.000 1.000
133.100 87.000 1.000
133.200 96.000 1.000
133.300 85.000 1.000
133.400 94.000 1.000
133.500 108.000 1.000
133.600 96.000 1.000
133.700 88.000 1.000
133.800 100.000 1.000
133.900 97.000 1.000
134.000 90.000 1.000
134.100 82.000 1.000
134.200 93.000 1.000
134.300 91.000 1.000
134.400 92.000 1.000
134.500 105.000 1.000
134.600 95.000 1.000
134.700 96.000 1.000
134.800 101.000 1.000
134.900 96.000 1.000
135.000 96.000 1.000
135.100 83.000 1.000
135.200 94.000 1.000
135.300 97.000 1.000
135.400 93.000 1.000
135.500 90.000 1.000
135.600 102.000 1.000
135.700 103.000 1.000
135.800 102.000 1.000
135.900 95.000 1.000
136.000 106.000 1.000
136.100 98.000 1.000
136.200 96.000 1.000
136.300 91.000 1.000
136.400 94.000 1.000
136.500 94.000 1.000
136.600 92.000 1.000
136.700 92.000 1.000
136.800 84.000 1.000
136.900 87.000 1.000
137.000 100.000 1.000
137.100 105.000 1.000
137.200 96.000 1.000
137.300 92.000 1.000
137.400 113.000 1.000
137.500 96.000 1.000
137.600 108.000 1.000
137.700 104.000 1.000
137.800 99.000 1.000
137.900 97.000 1.000
138.000 99.000 1.000
138.100 90.000 1.000
138.200 99.000 1.000
138.300 107.000 1.000
138.400 93.000 1.000
138.500 89.000 1.000
138.600 100.000 1.000
138.700 91.000 1.000
138.800 104.000 1.000
138.900 105.000 1.000
139.000 97.000 1.000
139.100 105.000 1.000
139.200 109.000 1.000
139.300 105.000 1.000
139.400 111.000 1.000
139.500 101.000 1.000
139.600 107.000 1.000
139.700 94.000 1.000
139.800 111.000 1.000
139.900 101.000 1.000
140.000 100.000 1.000
*RAS_INT_END
*RAS_DATA_END